<?xml version="1.0" encoding="utf-8"?>
<mujoco model="7374_pre">
  <compiler inertiafromgeom="auto" angle="radian" balanceinertia="true" boundmass="0.001" boundinertia="0.001">
    <lengthrange inttotal="10"></lengthrange>
  </compiler>
  <default>
    <joint limited="true" damping="0.5" armature="0.01" stiffness="0"></joint>
    <geom contype="1" conaffinity="1" condim="3" rgba="0.8 0.6 .4 1" margin="0.001" solref=".02 1" solimp=".8 .8 .01" material="geom"></geom>
    <site size="0.001"></site>
    <tendon width="0.001" rgba=".95 .3 .3 1" limited="false"></tendon>
    <default class="muscle">
      <muscle ctrllimited="true" ctrlrange="0 1" scale="400"></muscle>
    </default>
    <default class="motor">
      <motor gear="20"></motor>
    </default>
  </default>
  <option timestep="0.002" collision="predefined">
    <flag energy="enable"></flag>
  </option>
  <size njmax="1000" nconmax="400" nuser_jnt="1"></size>
  <visual>
    <map fogstart="3" fogend="5" force="0.1"></map>
    <quality shadowsize="2048"></quality>
  </visual>
  <worldbody>
    <geom name="floor" pos="0 0 0" size="10 10 0.125" type="plane" material="MatPlane" condim="3"></geom>
    <body name="pelvis" pos="       0        0        0" quat="0.7071067811865475 0.7071067811865475 0.0 0.0">
      <light mode="trackcom" directional="false" diffuse="1. 1. 1." specular="0.3 0.3 0.3" pos="0 0 4.0" dir="0 0 -1"></light>
      <geom name="sacrum" type="mesh" mesh="sacrum"></geom>
      <geom name="pelvis" type="mesh" mesh="pelvis"></geom>
      <geom name="l_pelvis" type="mesh" mesh="l_pelvis"></geom>
      <inertial pos="-0.051611        0        0" mass="4.45746074" fullinertia="0.0207344 0.0175678 0.0116782        0        0        0"></inertial>
      <site name="glut_med1_r-P1" pos="-0.029784 0.022192 0.088257"></site>
      <site name="glut_med2_r-P1" pos="-0.062415 0.032485 0.055918"></site>
      <site name="glut_med3_r-P1" pos="-0.089279 0.007665 0.047304"></site>
      <site name="glut_min1_r-P1" pos="-0.034091 -0.00584 0.077088"></site>
      <site name="glut_min2_r-P1" pos="-0.046209 -0.004745 0.072343"></site>
      <site name="glut_min3_r-P1" pos="-0.060882 -0.004599 0.062488"></site>
      <site name="semimem_r-P1" pos="-0.087016 -0.0711531 0.0522023"></site>
      <site name="semiten_r-P1" pos="-0.0922355 -0.0802124 0.0440847"></site>
      <site name="bifemlh_r-P1" pos="-0.0919508 -0.0748761 0.0506912"></site>
      <site name="sar_r-P1" pos="-0.011169 -0.000949 0.090666"></site>
      <site name="add_long_r-P1" pos="-0.023068 -0.061028 0.012337"></site>
      <site name="add_brev_r-P1" pos="-0.042851 -0.066795 0.011972"></site>
      <site name="add_mag1_r-P1" pos="-0.053436 -0.085702 0.018615"></site>
      <site name="add_mag2_r-P1" pos="-0.060663 -0.087016 0.022484"></site>
      <site name="add_mag3_r-P1" pos="-0.0810884 -0.0833149 0.0356386"></site>
      <site name="tfl_r-P1" pos="-0.022703 0.015622 0.090593"></site>
      <site name="pect_r-P1" pos="-0.031463 -0.056064 0.032923"></site>
      <site name="grac_r-P1" pos="-0.0540273 -0.086651 0.0203962"></site>
      <site name="glut_max1_r-P1" pos="-0.087235 0.044676 0.0511"></site>
      <site name="glut_max1_r-P2" pos="-0.094243 0.000876 0.064678"></site>
      <site name="glut_max2_r-P1" pos="-0.098477 0.012848 0.041099"></site>
      <site name="glut_max2_r-P2" pos="-0.100448 -0.03796 0.066722"></site>
      <site name="glut_max3_r-P1" pos="-0.113588 -0.022922 0.004234"></site>
      <site name="glut_max3_r-P2" pos="-0.111617 -0.076796 0.029419"></site>
      <site name="iliacus_r-P1" pos="-0.049202 0.026645 0.062342"></site>
      <site name="iliacus_r-P2" pos="-0.018834 -0.04015 0.059203"></site>
      <site name="psoas_r-P1" pos="-0.047231 0.064751 0.021097"></site>
      <site name="psoas_r-P2" pos="-0.017374 -0.04161 0.055407"></site>
      <site name="quad_fem_r-P1" pos="-0.083439 -0.084023 0.03796"></site>
      <site name="gem_r-P1" pos="-0.082709 -0.05986 0.052122"></site>
      <site name="peri_r-P1" pos="-0.101908 0.000219 0.017155"></site>
      <site name="peri_r-P2" pos="-0.087089 -0.020148 0.047961"></site>
      <site name="rect_fem_r-P1" pos="-0.021535 -0.022703 0.070664"></site>
      <site name="glut_med1_l-P1" pos="-0.029784 0.022192 -0.088257"></site>
      <site name="glut_med2_l-P1" pos="-0.062415 0.032485 -0.055918"></site>
      <site name="glut_med3_l-P1" pos="-0.089279 0.007665 -0.047304"></site>
      <site name="glut_min1_l-P1" pos="-0.034091 -0.00584 -0.077088"></site>
      <site name="glut_min2_l-P1" pos="-0.046209 -0.004745 -0.072343"></site>
      <site name="glut_min3_l-P1" pos="-0.060882 -0.004599 -0.062488"></site>
      <site name="semimem_l-P1" pos="-0.087016 -0.0711531 -0.0522023"></site>
      <site name="semiten_l-P1" pos="-0.0922355 -0.0802124 -0.0440847"></site>
      <site name="bifemlh_l-P1" pos="-0.0919508 -0.0748761 -0.0506912"></site>
      <site name="sar_l-P1" pos="-0.011169 -0.000949 -0.090666"></site>
      <site name="add_long_l-P1" pos="-0.023068 -0.061028 -0.012337"></site>
      <site name="add_brev_l-P1" pos="-0.042851 -0.066795 -0.011972"></site>
      <site name="add_mag1_l-P1" pos="-0.053436 -0.085702 -0.018615"></site>
      <site name="add_mag2_l-P1" pos="-0.060663 -0.087016 -0.022484"></site>
      <site name="add_mag3_l-P1" pos="-0.0810884 -0.0833149 -0.0356386"></site>
      <site name="tfl_l-P1" pos="-0.022703 0.015622 -0.090593"></site>
      <site name="pect_l-P1" pos="-0.031463 -0.056064 -0.032923"></site>
      <site name="grac_l-P1" pos="-0.0540273 -0.086651 -0.0203962"></site>
      <site name="glut_max1_l-P1" pos="-0.087235 0.044676 -0.0511"></site>
      <site name="glut_max1_l-P2" pos="-0.094243 0.000876 -0.064678"></site>
      <site name="glut_max2_l-P1" pos="-0.098477 0.012848 -0.041099"></site>
      <site name="glut_max2_l-P2" pos="-0.100448 -0.03796 -0.066722"></site>
      <site name="glut_max3_l-P1" pos="-0.113588 -0.022922 -0.004234"></site>
      <site name="glut_max3_l-P2" pos="-0.111617 -0.076796 -0.029419"></site>
      <site name="iliacus_l-P1" pos="-0.049202 0.026645 -0.062342"></site>
      <site name="iliacus_l-P2" pos="-0.018834 -0.04015 -0.059203"></site>
      <site name="psoas_l-P1" pos="-0.047231 0.064751 -0.021097"></site>
      <site name="psoas_l-P2" pos="-0.017374 -0.04161 -0.055407"></site>
      <site name="quad_fem_l-P1" pos="-0.083439 -0.084023 -0.03796"></site>
      <site name="gem_l-P1" pos="-0.082709 -0.05986 -0.052122"></site>
      <site name="peri_l-P1" pos="-0.101908 0.000219 -0.017155"></site>
      <site name="peri_l-P2" pos="-0.087089 -0.020148 -0.047961"></site>
      <site name="rect_fem_l-P1" pos="-0.021535 -0.022703 -0.070664"></site>
      <site name="ercspn_r-P1" pos="-0.1022 0.032047 0.031828"></site>
      <site name="ercspn_l-P1" pos="-0.1022 0.032047 -0.031828"></site>
      <site name="intobl_r-P1" pos="-0.0292 0.0511 0.084461"></site>
      <site name="intobl_l-P1" pos="-0.0292 0.0511 -0.084461"></site>
      <site name="extobl_r-P1" pos="-0.0219 -0.046428 0.0073"></site>
      <site name="extobl_l-P1" pos="-0.0219 -0.046428 -0.0073"></site>
      <joint name="pelvis_tz" type="slide" pos="0 0 0" axis="       0        0        1" limited="true" range="      -3        3" ref="0" armature="0" damping="0" stiffness="0"></joint>
      <joint name="pelvis_ty" type="slide" pos="0 0 0" axis="       0        1        0" limited="true" range="      -1        2" ref="0" armature="0" damping="0" stiffness="0"></joint>
      <joint name="pelvis_tx" type="slide" pos="0 0 0" axis="       1        0        0" limited="true" range="      -5        5" ref="0" armature="0" damping="0" stiffness="0"></joint>
      <joint name="pelvis_tilt" type="hinge" pos="0 0 0" axis="       0        0        1" limited="true" range=" -1.5708   1.5708" ref="0" armature="0" damping="0" stiffness="0"></joint>
      <joint name="pelvis_list" type="hinge" pos="0 0 0" axis="       1        0        0" limited="true" range=" -1.5708   1.5708" ref="0" armature="0" damping="0" stiffness="0"></joint>
      <joint name="pelvis_rotation" type="hinge" pos="0 0 0" axis="       0        1        0" limited="true" range=" -1.5708   1.5708" ref="0" armature="0" damping="0" stiffness="0"></joint>
      <body name="femur_r" pos="-0.051611 -0.048253 0.060955" quat="1.0 0.0 0.0 0.0">
        <geom name="femur" type="mesh" mesh="femur"></geom>
        <inertial pos="       0 -0.124666        0" mass="3.56887624" fullinertia="0.0276289 0.00724252 0.0291351        0        0        0"></inertial>
        <site name="glut_med1_r-P2" pos="-0.0159866 -0.00857996 0.0406998"></site>
        <site name="glut_med2_r-P2" pos="-0.0189199 -0.00425332 0.0386465"></site>
        <site name="glut_med3_r-P2" pos="-0.0226599 -0.00344665 0.0379865"></site>
        <site name="glut_min1_r-P2" pos="-0.00527998 -0.00762664 0.0410665"></site>
        <site name="glut_min2_r-P2" pos="-0.00703997 -0.00762664 0.0410665"></site>
        <site name="glut_min3_r-P2" pos="-0.00989996 -0.00608664 0.0403332"></site>
        <site name="bifemsh_r-P1" pos="0.00366665 -0.154806 0.0171599"></site>
        <site name="sar_r-P2" pos="-0.00219999 -0.261652 -0.0308732"></site>
        <site name="add_long_r-P2" pos="0.00366665 -0.154806 0.0171599"></site>
        <site name="add_brev_r-P2" pos="0.00066 -0.0877063 0.0215599"></site>
        <site name="add_mag1_r-P2" pos="-0.00329999 -0.0888063 0.0248599"></site>
        <site name="add_mag2_r-P2" pos="0.00395998 -0.167566 0.0166466"></site>
        <site name="add_mag3_r-P2" pos="0.00513331 -0.281379 -0.0195066"></site>
        <site name="tfl_r-P2" pos="0.0215599 -0.0729664 0.0437798"></site>
        <site name="tfl_r-P3" pos="0.00395998 -0.296925 0.0261799"></site>
        <site name="pect_r-P2" pos="-0.00894663 -0.0602798 0.0185533"></site>
        <site name="glut_max1_r-P3" pos="-0.0335132 -0.0181866 0.0287465"></site>
        <site name="glut_max1_r-P4" pos="-0.0203133 -0.0415065 0.0344665"></site>
        <site name="glut_max2_r-P3" pos="-0.0312399 -0.0388665 0.0214866"></site>
        <site name="glut_max2_r-P4" pos="-0.01144 -0.0745064 0.0307265"></site>
        <site name="glut_max3_r-P3" pos="-0.0219266 -0.0763397 0.00989996"></site>
        <site name="glut_max3_r-P4" pos="-0.00439998 -0.10406 0.0301399"></site>
        <site name="iliacus_r-P4" pos="0.00124666 -0.0398198 0.00417998"></site>
        <site name="iliacus_r-P5" pos="-0.0141533 -0.0455398 0.00945996"></site>
        <site name="psoas_r-P4" pos="0.00117333 -0.0371799 0.00278666"></site>
        <site name="psoas_r-P5" pos="-0.0137866 -0.0437798 0.00762664"></site>
        <site name="quad_fem_r-P2" pos="-0.0279399 -0.0263266 0.0268399"></site>
        <site name="gem_r-P2" pos="-0.0104133 -0.00241999 0.0324865"></site>
        <site name="peri_r-P3" pos="-0.0108533 -0.00263999 0.0320465"></site>
        <site name="vas_med_r-P1" pos="0.0102666 -0.153926 0.0137866"></site>
        <site name="vas_med_r-P2" pos="0.0261066 -0.203059 0.00066"></site>
        <site name="vas_int_r-P1" pos="0.0212666 -0.141093 0.0227332"></site>
        <site name="vas_int_r-P2" pos="0.0245666 -0.152826 0.0208999"></site>
        <site name="vas_lat_r-P1" pos="0.00351999 -0.135959 0.0255932"></site>
        <site name="vas_lat_r-P2" pos="0.0197266 -0.190006 0.0299932"></site>
        <site name="med_gas_r-P1" pos="-0.0139333 -0.288125 -0.0172333"></site>
        <site name="lat_gas_r-P1" pos="-0.0161333 -0.289372 0.0199466"></site>
        <joint name="hip_flexion_r" type="hinge" pos="0 0 0" axis="       0        0        1" limited="true" range=" -0.78   0.78" ref="0"></joint>
        <joint name="hip_adduction_r" type="hinge" pos="0 0 0" axis="       1        0        0" limited="true" range=" -0.52   0.15" ref="0"></joint>
        <joint name="hip_rotation_r" type="hinge" pos="0 0 0" axis="       0        1        0" limited="true" range=" -0.78   0.26" ref="0"></joint>
        <body name="tibia_r" pos="       0        0        0" quat="1.0 0.0 0.0 0.0">
          <geom name="tibia" type="mesh" mesh="tibia"></geom>
          <geom name="fibula" type="mesh" mesh="fibula"></geom>
          <inertial pos="       0 -0.132237        0" mass="1.28172134" fullinertia="0.00874101 0.00088451 0.00886242        0        0        0"></inertial>
          <site name="semimem_r-P3" pos="-0.0191237 -0.0337924 -0.0138612"></site>
          <site name="semiten_r-P3" pos="-0.0235293 -0.0374117 -0.0162056"></site>
          <site name="semiten_r-P4" pos="-0.00800365 -0.0528382 -0.017353"></site>
          <site name="semiten_r-P5" pos="0.00191238 -0.0677123 -0.0136699"></site>
          <site name="bifemlh_r-P2" pos="-0.0213194 -0.0254983 0.0208449"></site>
          <site name="bifemlh_r-P3" pos="-0.0165739 -0.0398766 0.0242943"></site>
          <site name="bifemsh_r-P2" pos="-0.0213194 -0.0254983 0.0208449"></site>
          <site name="bifemsh_r-P3" pos="-0.0165739 -0.0398766 0.0242943"></site>
          <site name="sar_r-P3" pos="-0.00396641 -0.0296772 -0.0282607"></site>
          <site name="sar_r-P4" pos="0.00424972 -0.0417181 -0.0271274"></site>
          <site name="sar_r-P5" pos="0.0172114 -0.0594961 -0.0178488"></site>
          <site name="tfl_r-P4" pos="0.00424972 -0.0344936 0.0210361"></site>
          <site name="grac_r-P3" pos="-0.013762 -0.036498 -0.0253567"></site>
          <site name="grac_r-P4" pos="0.00424972 -0.0592128 -0.0161489"></site>
          <site name="rect_fem_r-P3" pos="0.0552895 -0.00865128 0.0009916"></site>
          <site name="vas_med_r-P5" pos="0.0540332 -0.00566028 -0.010341"></site>
          <site name="vas_int_r-P4" pos="0.055469 -0.00460513 0.00127492"></site>
          <site name="vas_lat_r-P5" pos="0.0540689 -0.00841083 0.0116867"></site>
          <site name="soleus_r-P1" pos="-0.00169989 -0.10858 0.00502884"></site>
          <site name="tib_post_r-P1" pos="-0.0066579 -0.0954771 0.00134575"></site>
          <site name="tib_post_r-P2" pos="-0.0101993 -0.286927 -0.0162198"></site>
          <site name="flex_dig_r-P1" pos="-0.00587878 -0.144916 -0.00127492"></site>
          <site name="flex_dig_r-P2" pos="-0.0109076 -0.286927 -0.0138824"></site>
          <site name="flex_hal_r-P1" pos="-0.00559547 -0.165314 0.0172822"></site>
          <site name="flex_hal_r-P2" pos="-0.0131741 -0.28891 -0.0123242"></site>
          <site name="tib_ant_r-P1" pos="0.0126783 -0.115026 0.0081453"></site>
          <site name="tib_ant_r-P2" pos="0.0233027 -0.279844 -0.0125367"></site>
          <site name="per_brev_r-P1" pos="-0.00495801 -0.187413 0.0230193"></site>
          <site name="per_brev_r-P2" pos="-0.0140241 -0.296347 0.0200445"></site>
          <site name="per_brev_r-P3" pos="-0.0101993 -0.304209 0.0204695"></site>
          <site name="per_long_r-P1" pos="0.00035414 -0.111059 0.02564"></site>
          <site name="per_long_r-P2" pos="-0.0146616 -0.297835 0.020257"></site>
          <site name="per_long_r-P3" pos="-0.0114743 -0.305909 0.0204695"></site>
          <site name="per_tert_r-P1" pos="0.00070829 -0.198604 0.0163614"></site>
          <site name="per_tert_r-P2" pos="0.0162198 -0.288202 0.0112618"></site>
          <site name="ext_dig_r-P1" pos="0.00226652 -0.0978145 0.0195487"></site>
          <site name="ext_dig_r-P2" pos="0.0204695 -0.283811 0.00509967"></site>
          <site name="ext_hal_r-P1" pos="0.00084994 -0.125154 0.0161489"></site>
          <site name="ext_hal_r-P2" pos="0.0230902 -0.282252 -0.00602044"></site>
          <joint name="knee_angle_r_translation2" type="slide" pos="0 0 0" axis="       0        1        0" limited="true" range="-0.309907 -0.289892" ref="0"></joint>
          <joint name="knee_angle_r_translation1" type="slide" pos="0 0 0" axis="       1        0        0" limited="true" range="-0.00433978 0.0031965" ref="0"></joint>
          <joint name="knee_angle_r" type="hinge" pos="0 0 0" axis="       0        0        1" limited="true" range=" -2.0944 0.174533" ref="0"></joint>
          <body name="talus_r" pos="       0 -0.304563        0" quat="1.0 0.0 0.0 0.0">
            <geom name="talus" type="mesh" mesh="talus"></geom>
            <inertial pos="       0        0        0" mass="0.03457104" fullinertia="0.00017343 0.00017343 0.00017343        0        0        0"></inertial>
            <joint name="ankle_angle_r" type="hinge" pos="0 0 0" axis="-0.105014 -0.174022 0.979126" limited="true" range=" -0.78   0.78" ref="0"></joint>
            <body name="calcn_r" pos="-0.0345432 -0.0297127 0.00560963" quat="1.0 0.0 0.0 0.0">
              <geom name="foot" type="mesh" mesh="foot"></geom>
              <inertial pos="0.0708287 0.0212486        0" mass="0.43213801" fullinertia="0.00024281 0.00067639 0.00071107        0        0        0"></inertial>
              <site name="med_gas_r-P3" pos="0 0.0219569 -0.00375392"></site>
              <site name="lat_gas_r-P3" pos="0 0.0219569 -0.00375392"></site>
              <site name="soleus_r-P2" pos="0 0.0219569 -0.00375392"></site>
              <site name="tib_post_r-P3" pos="0.0295356 0.0236568 -0.020257"></site>
              <site name="tib_post_r-P4" pos="0.0546798 0.0112618 -0.0199029"></site>
              <site name="flex_dig_r-P3" pos="0.0308813 0.022311 -0.019832"></site>
              <site name="flex_dig_r-P4" pos="0.0501467 0.0124659 -0.018628"></site>
              <site name="flex_dig_r-P5" pos="0.117434 -0.00573713 0.00821613"></site>
              <site name="flex_hal_r-P3" pos="0.0264899 0.0195487 -0.0170697"></site>
              <site name="flex_hal_r-P4" pos="0.0735202 0.00481635 -0.0181322"></site>
              <site name="flex_hal_r-P5" pos="0.12225 -0.00375392 -0.0190529"></site>
              <site name="tib_ant_r-P3" pos="0.0825863 0.0126075 -0.0216028"></site>
              <site name="per_brev_r-P4" pos="0.0333603 0.0191237 0.0165031"></site>
              <site name="per_brev_r-P5" pos="0.047951 0.0155115 0.0242943"></site>
              <site name="per_long_r-P4" pos="0.031023 0.0162906 0.0156532"></site>
              <site name="per_long_r-P5" pos="0.0482344 0.00750784 0.0201154"></site>
              <site name="per_long_r-P6" pos="0.0603461 0.00488718 0.00835779"></site>
              <site name="per_long_r-P7" pos="0.085207 0.00602044 -0.0130325"></site>
              <site name="per_tert_r-P3" pos="0.0607002 0.0161489 0.0211778"></site>
              <site name="ext_dig_r-P3" pos="0.0653041 0.0274815 -7.083e-005"></site>
              <site name="ext_dig_r-P4" pos="0.114459 0.00389558 0.00920773"></site>
              <site name="ext_hal_r-P3" pos="0.0687039 0.0275524 -0.0149449"></site>
              <site name="ext_hal_r-P4" pos="0.0915815 0.0218861 -0.018203"></site>
              <site name="ext_hal_r-P5" pos="0.122817 0.00984519 -0.019832"></site>
              <joint name="subtalar_angle_r" type="hinge" pos="0 0 0" axis=" 0.78718 0.604747 -0.120949" limited="true" range=" -0.52   0.52" ref="0"></joint>
              <body name="toes_r" pos="0.126642 -0.00141657 0.00076495" quat="1.0 0.0 0.0 0.0">
                <geom name="bofoot" type="mesh" mesh="bofoot"></geom>
                <inertial pos="0.0245067 0.00424972 -0.012395" mass="0.07488087" fullinertia="1.734e-05 3.469e-05 0.00017343        0        0        0"></inertial>
                <site name="flex_dig_r-P6" pos="-0.00134575 -0.00552464 0.0104118"></site>
                <site name="flex_dig_r-P7" pos="0.0201862 -0.00502884 0.0152282"></site>
                <site name="flex_dig_r-P8" pos="0.0312355 -0.00424972 0.0171406"></site>
                <site name="flex_hal_r-P6" pos="0.0109785 -0.00453304 -0.0187696"></site>
                <site name="flex_hal_r-P7" pos="0.0398057 -0.00722453 -0.01282"></site>
                <site name="ext_dig_r-P5" pos="0.00021249 0.00332895 0.0108368"></site>
                <site name="ext_dig_r-P6" pos="0.0313771 -0.00028331 0.0177072"></site>
                <site name="ext_hal_r-P6" pos="0.021107 0.00290398 -0.017353"></site>
                <site name="ext_hal_r-P7" pos="0.0398766 0.00240818 -0.0131741"></site>
                <joint name="mtp_angle_r" type="hinge" pos="0 0 0" axis="-0.580954        0 0.813936" limited="true" range=" -0.52   0.52" ref="0"></joint>
              </body>
            </body>
          </body>
        </body>
      </body>
      <body name="femur_l" pos="-0.051611 -0.048253 -0.060955" quat="1.0 0.0 0.0 0.0">
        <geom name="l_femur" type="mesh" mesh="l_femur"></geom>
        <inertial pos="       0 -0.124666        0" mass="3.56887624" fullinertia="0.0276289 0.00724252 0.0291351        0        0        0"></inertial>
        <site name="glut_med1_l-P2" pos="-0.0159866 -0.00857996 -0.0406998"></site>
        <site name="glut_med2_l-P2" pos="-0.0189199 -0.00425332 -0.0386465"></site>
        <site name="glut_med3_l-P2" pos="-0.0226599 -0.00344665 -0.0379865"></site>
        <site name="glut_min1_l-P2" pos="-0.00527998 -0.00762664 -0.0410665"></site>
        <site name="glut_min2_l-P2" pos="-0.00703997 -0.00762664 -0.0410665"></site>
        <site name="glut_min3_l-P2" pos="-0.00989996 -0.00608664 -0.0403332"></site>
        <site name="bifemsh_l-P1" pos="0.00366665 -0.154806 -0.0171599"></site>
        <site name="sar_l-P2" pos="-0.00219999 -0.261652 0.0308732"></site>
        <site name="add_long_l-P2" pos="0.00366665 -0.154806 -0.0171599"></site>
        <site name="add_brev_l-P2" pos="0.00066 -0.0877063 -0.0215599"></site>
        <site name="add_mag1_l-P2" pos="-0.00329999 -0.0888063 -0.0248599"></site>
        <site name="add_mag2_l-P2" pos="0.00395998 -0.167566 -0.0166466"></site>
        <site name="add_mag3_l-P2" pos="0.00513331 -0.281379 0.0195066"></site>
        <site name="tfl_l-P2" pos="0.0215599 -0.0729664 -0.0437798"></site>
        <site name="tfl_l-P3" pos="0.00395998 -0.296925 -0.0261799"></site>
        <site name="pect_l-P2" pos="-0.00894663 -0.0602798 -0.0185533"></site>
        <site name="glut_max1_l-P3" pos="-0.0335132 -0.0181866 -0.0287465"></site>
        <site name="glut_max1_l-P4" pos="-0.0203133 -0.0415065 -0.0344665"></site>
        <site name="glut_max2_l-P3" pos="-0.0312399 -0.0388665 -0.0214866"></site>
        <site name="glut_max2_l-P4" pos="-0.01144 -0.0745064 -0.0307265"></site>
        <site name="glut_max3_l-P3" pos="-0.0219266 -0.0763397 -0.00989996"></site>
        <site name="glut_max3_l-P4" pos="-0.00439998 -0.10406 -0.0301399"></site>
        <site name="iliacus_l-P4" pos="0.00124666 -0.0398198 -0.00417998"></site>
        <site name="iliacus_l-P5" pos="-0.0141533 -0.0455398 -0.00945996"></site>
        <site name="psoas_l-P4" pos="0.00117333 -0.0371799 -0.00278666"></site>
        <site name="psoas_l-P5" pos="-0.0137866 -0.0437798 -0.00762664"></site>
        <site name="quad_fem_l-P2" pos="-0.0279399 -0.0263266 -0.0268399"></site>
        <site name="gem_l-P2" pos="-0.0104133 -0.00241999 -0.0324865"></site>
        <site name="peri_l-P3" pos="-0.0108533 -0.00263999 -0.0320465"></site>
        <site name="vas_med_l-P1" pos="0.0102666 -0.153926 -0.0137866"></site>
        <site name="vas_med_l-P2" pos="0.0261066 -0.203059 -0.00066"></site>
        <site name="vas_int_l-P1" pos="0.0212666 -0.141093 -0.0227332"></site>
        <site name="vas_int_l-P2" pos="0.0245666 -0.152826 -0.0208999"></site>
        <site name="vas_lat_l-P1" pos="0.00351999 -0.135959 -0.0255932"></site>
        <site name="vas_lat_l-P2" pos="0.0197266 -0.190006 -0.0299932"></site>
        <site name="med_gas_l-P1" pos="-0.0139333 -0.288125 0.0172333"></site>
        <site name="lat_gas_l-P1" pos="-0.0161333 -0.289372 -0.0199466"></site>
        <joint name="hip_flexion_l" type="hinge" pos="0 0 0" axis="       0        0        1" limited="true" range=" -0.78   0.78" ref="0"></joint>
        <joint name="hip_adduction_l" type="hinge" pos="0 0 0" axis="      -1        0        0" limited="true" range=" -0.52   0.15" ref="0"></joint>
        <joint name="hip_rotation_l" type="hinge" pos="0 0 0" axis="       0       -1        0" limited="true" range=" -0.78   0.26" ref="0"></joint>
        <body name="tibia_l" pos="       0        0        0" quat="1.0 0.0 0.0 0.0">
          <geom name="l_tibia" type="mesh" mesh="l_tibia"></geom>
          <geom name="l_fibula" type="mesh" mesh="l_fibula"></geom>
          <inertial pos="       0 -0.132237        0" mass="1.28172134" fullinertia="0.00874101 0.00088451 0.00886242        0        0        0"></inertial>
          <site name="semimem_l-P3" pos="-0.0191237 -0.0337924 0.0138612"></site>
          <site name="semiten_l-P3" pos="-0.0235293 -0.0374117 0.0162056"></site>
          <site name="semiten_l-P4" pos="-0.00800365 -0.0528382 0.017353"></site>
          <site name="semiten_l-P5" pos="0.00191238 -0.0677123 0.0136699"></site>
          <site name="bifemlh_l-P2" pos="-0.0213194 -0.0254983 -0.0208449"></site>
          <site name="bifemlh_l-P3" pos="-0.0165739 -0.0398766 -0.0242943"></site>
          <site name="bifemsh_l-P2" pos="-0.0213194 -0.0254983 -0.0208449"></site>
          <site name="bifemsh_l-P3" pos="-0.0165739 -0.0398766 -0.0242943"></site>
          <site name="sar_l-P3" pos="-0.00396641 -0.0296772 0.0282607"></site>
          <site name="sar_l-P4" pos="0.00424972 -0.0417181 0.0271274"></site>
          <site name="sar_l-P5" pos="0.0172114 -0.0594961 0.0178488"></site>
          <site name="tfl_l-P4" pos="0.00424972 -0.0344936 -0.0210361"></site>
          <site name="grac_l-P3" pos="-0.013762 -0.036498 0.0253567"></site>
          <site name="grac_l-P4" pos="0.00424972 -0.0592128 0.0161489"></site>
          <site name="rect_fem_l-P3" pos="0.0552895 -0.00865128 -0.0009916"></site>
          <site name="vas_med_l-P5" pos="0.0540332 -0.00566028 0.010341"></site>
          <site name="vas_int_l-P4" pos="0.0552895 -0.00865128 -0.0009916"></site>
          <site name="vas_lat_l-P5" pos="0.0540689 -0.00841083 -0.0116867"></site>
          <site name="soleus_l-P1" pos="-0.00169989 -0.10858 -0.00502884"></site>
          <site name="tib_post_l-P1" pos="-0.0066579 -0.0954771 -0.00134575"></site>
          <site name="tib_post_l-P2" pos="-0.0101993 -0.286927 0.0162198"></site>
          <site name="flex_dig_l-P1" pos="-0.00587878 -0.144916 0.00127492"></site>
          <site name="flex_dig_l-P2" pos="-0.0109076 -0.286927 0.0138824"></site>
          <site name="flex_hal_l-P1" pos="-0.00559547 -0.165314 -0.0172822"></site>
          <site name="flex_hal_l-P2" pos="-0.0131741 -0.28891 0.0123242"></site>
          <site name="tib_ant_l-P1" pos="0.0126783 -0.115026 -0.0081453"></site>
          <site name="tib_ant_l-P2" pos="0.0233027 -0.279844 0.0125367"></site>
          <site name="per_brev_l-P1" pos="-0.00495801 -0.187413 -0.0230193"></site>
          <site name="per_brev_l-P2" pos="-0.0140241 -0.296347 -0.0200445"></site>
          <site name="per_brev_l-P3" pos="-0.0101993 -0.304209 -0.0204695"></site>
          <site name="per_long_l-P1" pos="0.00035414 -0.111059 -0.02564"></site>
          <site name="per_long_l-P2" pos="-0.0146616 -0.297835 -0.020257"></site>
          <site name="per_long_l-P3" pos="-0.0114743 -0.305909 -0.0204695"></site>
          <site name="per_tert_l-P1" pos="0.00070829 -0.198604 -0.0163614"></site>
          <site name="per_tert_l-P2" pos="0.0162198 -0.288202 -0.0112618"></site>
          <site name="ext_dig_l-P1" pos="0.00226652 -0.0978145 -0.0195487"></site>
          <site name="ext_dig_l-P2" pos="0.0204695 -0.283811 -0.00509967"></site>
          <site name="ext_hal_l-P1" pos="0.00084994 -0.125154 -0.0161489"></site>
          <site name="ext_hal_l-P2" pos="0.0230902 -0.282252 0.00602044"></site>
          <joint name="knee_angle_l_translation2" type="slide" pos="0 0 0" axis="       0        1        0" limited="true" range="-0.309907 -0.289892" ref="0"></joint>
          <joint name="knee_angle_l_translation1" type="slide" pos="0 0 0" axis="       1        0        0" limited="true" range="-0.00433978 0.0031965" ref="0"></joint>
          <joint name="knee_angle_l" type="hinge" pos="0 0 0" axis="       0        0        1" limited="true" range=" -2.0944 0.174533" ref="0"></joint>
          <body name="talus_l" pos="       0 -0.304563        0" quat="1.0 0.0 0.0 0.0">
            <geom name="l_talus" type="mesh" mesh="l_talus"></geom>
            <inertial pos="       0        0        0" mass="0.03457104" fullinertia="0.00017343 0.00017343 0.00017343        0        0        0"></inertial>
            <joint name="ankle_angle_l" type="hinge" pos="0 0 0" axis="0.105014 -0.174022 0.979126" limited="true" range=" -0.78   0.78" ref="0"></joint>
            <body name="calcn_l" pos="-0.0345432 -0.0297127 -0.00560963" quat="1.0 0.0 0.0 0.0">
              <geom name="l_foot" type="mesh" mesh="l_foot"></geom>
              <inertial pos="0.0708287 0.0212486        0" mass="0.43213801" fullinertia="0.00024281 0.00067639 0.00071107        0        0        0"></inertial>
              <site name="med_gas_l-P3" pos="0 0.0219569 0.00375392"></site>
              <site name="lat_gas_l-P3" pos="0 0.0219569 0.00375392"></site>
              <site name="soleus_l-P2" pos="0 0.0219569 0.00375392"></site>
              <site name="tib_post_l-P3" pos="0.0295356 0.0236568 0.020257"></site>
              <site name="tib_post_l-P4" pos="0.0546798 0.0112618 0.0199029"></site>
              <site name="flex_dig_l-P3" pos="0.0308813 0.022311 0.019832"></site>
              <site name="flex_dig_l-P4" pos="0.0501467 0.0124659 0.018628"></site>
              <site name="flex_dig_l-P5" pos="0.117434 -0.00573713 -0.00821613"></site>
              <site name="flex_hal_l-P3" pos="0.0264899 0.0195487 0.0170697"></site>
              <site name="flex_hal_l-P4" pos="0.0735202 0.00481635 0.0181322"></site>
              <site name="flex_hal_l-P5" pos="0.12225 -0.00375392 0.0190529"></site>
              <site name="tib_ant_l-P3" pos="0.0825863 0.0126075 0.0216028"></site>
              <site name="per_brev_l-P4" pos="0.0333603 0.0191237 -0.0165031"></site>
              <site name="per_brev_l-P5" pos="0.047951 0.0155115 -0.0242943"></site>
              <site name="per_long_l-P4" pos="0.031023 0.0162906 -0.0156532"></site>
              <site name="per_long_l-P5" pos="0.0482344 0.00750784 -0.0201154"></site>
              <site name="per_long_l-P6" pos="0.0603461 0.00488718 -0.00835779"></site>
              <site name="per_long_l-P7" pos="0.085207 0.00602044 0.0130325"></site>
              <site name="per_tert_l-P3" pos="0.0607002 0.0161489 -0.0211778"></site>
              <site name="ext_dig_l-P3" pos="0.0653041 0.0274815 7.083e-005"></site>
              <site name="ext_dig_l-P4" pos="0.114459 0.00389558 -0.00920773"></site>
              <site name="ext_hal_l-P3" pos="0.0687039 0.0275524 0.0149449"></site>
              <site name="ext_hal_l-P4" pos="0.0915815 0.0218861 0.018203"></site>
              <site name="ext_hal_l-P5" pos="0.122817 0.00984519 0.019832"></site>
              <joint name="subtalar_angle_l" type="hinge" pos="0 0 0" axis="-0.78718 -0.604747 -0.120949" limited="true" range=" -0.52   0.52" ref="0"></joint>
              <body name="toes_l" pos="0.126642 -0.00141657 -0.00076495" quat="1.0 0.0 0.0 0.0">
                <geom name="l_bofoot" type="mesh" mesh="l_bofoot"></geom>
                <inertial pos="0.0245067 0.00424972 0.012395" mass="0.07488087" fullinertia="1.734e-05 3.469e-05 0.00017343        0        0        0"></inertial>
                <site name="flex_dig_l-P6" pos="-0.00134575 -0.00552464 -0.0104118"></site>
                <site name="flex_dig_l-P7" pos="0.0201862 -0.00502884 -0.0152282"></site>
                <site name="flex_dig_l-P8" pos="0.0312355 -0.00424972 -0.0171406"></site>
                <site name="flex_hal_l-P6" pos="0.0109785 -0.00453304 0.0187696"></site>
                <site name="flex_hal_l-P7" pos="0.0398057 -0.00722453 0.01282"></site>
                <site name="ext_dig_l-P5" pos="0.00021249 0.00332895 -0.0108368"></site>
                <site name="ext_dig_l-P6" pos="0.0313771 -0.00028331 -0.0177072"></site>
                <site name="ext_hal_l-P6" pos="0.021107 0.00290398 0.017353"></site>
                <site name="ext_hal_l-P7" pos="0.0398766 0.00240818 0.0131741"></site>
                <joint name="mtp_angle_l" type="hinge" pos="0 0 0" axis="0.580954        0 0.813936" limited="true" range=" -0.52   0.52" ref="0"></joint>
              </body>
            </body>
          </body>
        </body>
      </body>
      <body name="torso" pos="-0.073511 0.059495        0" quat="1.0 0.0 0.0 0.0">
        <geom name="hat_spine" type="mesh" mesh="hat_spine"></geom>
        <geom name="hat_jaw" type="mesh" mesh="hat_jaw"></geom>
        <geom name="hat_skull" type="mesh" mesh="hat_skull"></geom>
        <geom name="hat_ribs" type="mesh" mesh="hat_ribs"></geom>
        <inertial pos=" -0.0219   0.2336        0" mass="12.95816424" fullinertia="0.297402 0.152382 0.288709        0        0        0"></inertial>
        <site name="ercspn_r-P2" pos="-0.04015 0.0803 0.017593"></site>
        <site name="ercspn_l-P2" pos="-0.04015 0.0803 -0.017593"></site>
        <site name="intobl_r-P2" pos="0.0511 0.1168 0.01095"></site>
        <site name="intobl_l-P2" pos="0.0511 0.1168 -0.01095"></site>
        <site name="extobl_r-P2" pos="0.04745 0.0803 0.0803"></site>
        <site name="extobl_l-P2" pos="0.04745 0.0803 -0.0803"></site>
        <joint name="lumbar_extension" type="hinge" pos="0 0 0" axis="       0        0        1" limited="true" range=" -0.78   0.17" ref="0"></joint>
        <joint name="lumbar_bending" type="hinge" pos="0 0 0" axis="       1        0        0" limited="true" range=" -0.26   0.26" ref="0"></joint>
        <joint name="lumbar_rotation" type="hinge" pos="0 0 0" axis="       0        1        0" limited="true" range=" -0.26   0.26" ref="0"></joint>
      </body>
    </body>
    <camera name="for_testing" pos="0 0 0" euler="0 0 0"></camera>
  </worldbody>
  <asset>
    <mesh name="sacrum" file="Geometry/sacrum.stl" scale="    0.73     0.73     0.73"></mesh>
    <mesh name="pelvis" file="Geometry/pelvis.stl" scale="    0.73     0.73     0.73"></mesh>
    <mesh name="l_pelvis" file="Geometry/l_pelvis.stl" scale="    0.73     0.73     0.73"></mesh>
    <mesh name="femur" file="Geometry/femur.stl" scale=" 0.73333  0.73333  0.73333"></mesh>
    <mesh name="tibia" file="Geometry/tibia.stl" scale="0.708287 0.708287 0.708287"></mesh>
    <mesh name="fibula" file="Geometry/fibula.stl" scale="0.708287 0.708287 0.708287"></mesh>
    <mesh name="talus" file="Geometry/talus.stl" scale="0.708287 0.708287 0.708287"></mesh>
    <mesh name="foot" file="Geometry/foot.stl" scale="0.708287 0.708287 0.708287"></mesh>
    <mesh name="bofoot" file="Geometry/bofoot.stl" scale="0.708287 0.708287 0.708287"></mesh>
    <mesh name="l_femur" file="Geometry/l_femur.stl" scale=" 0.73333  0.73333  0.73333"></mesh>
    <mesh name="l_tibia" file="Geometry/l_tibia.stl" scale="0.708287 0.708287 0.708287"></mesh>
    <mesh name="l_fibula" file="Geometry/l_fibula.stl" scale="0.708287 0.708287 0.708287"></mesh>
    <mesh name="l_talus" file="Geometry/l_talus.stl" scale="0.708287 0.708287 0.708287"></mesh>
    <mesh name="l_foot" file="Geometry/l_foot.stl" scale="0.708287 0.708287 0.708287"></mesh>
    <mesh name="l_bofoot" file="Geometry/l_bofoot.stl" scale="0.708287 0.708287 0.708287"></mesh>
    <mesh name="hat_spine" file="Geometry/hat_spine.stl" scale="    0.73     0.73     0.73"></mesh>
    <mesh name="hat_jaw" file="Geometry/hat_jaw.stl" scale="    0.73     0.73     0.73"></mesh>
    <mesh name="hat_skull" file="Geometry/hat_skull.stl" scale="    0.73     0.73     0.73"></mesh>
    <mesh name="hat_ribs" file="Geometry/hat_ribs.stl" scale="    0.73     0.73     0.73"></mesh>
    <texture name="texplane" type="2d" builtin="checker" rgb1=".68 .93 .93" rgb2=".0 0.81 0.81" width="100" height="100"></texture>
    <texture name="texgeom" type="cube" builtin="flat" mark="cross" width="127" height="1278" rgb1="0.8 0.6 0.4" rgb2="0.8 0.6 0.4" markrgb="1 1 1" random="0.01"></texture>
    <material name="MatPlane" reflectance="0.1" texture="texplane" texrepeat="1 1" texuniform="true"></material>
    <material name="geom" texture="texgeom" texuniform="true"></material>
  </asset>
  <tendon>
    <spatial name="glut_med1_r_tendon" springlength="0.05700012">
      <site site="glut_med1_r-P1"></site>
      <site site="glut_med1_r-P2"></site>
    </spatial>
    <spatial name="glut_med2_r_tendon" springlength="0.03873208">
      <site site="glut_med2_r-P1"></site>
      <site site="glut_med2_r-P2"></site>
    </spatial>
    <spatial name="glut_med3_r_tendon" springlength="0.03873998">
      <site site="glut_med3_r-P1"></site>
      <site site="glut_med3_r-P2"></site>
    </spatial>
    <spatial name="glut_min1_r_tendon" springlength="0.01170221">
      <site site="glut_min1_r-P1"></site>
      <site site="glut_min1_r-P2"></site>
    </spatial>
    <spatial name="glut_min2_r_tendon" springlength="0.01902009">
      <site site="glut_min2_r-P1"></site>
      <site site="glut_min2_r-P2"></site>
    </spatial>
    <spatial name="glut_min3_r_tendon" springlength="0.03730969">
      <site site="glut_min3_r-P1"></site>
      <site site="glut_min3_r-P2"></site>
    </spatial>
    <spatial name="semimem_r_tendon" springlength="0.26228167">
      <site site="semimem_r-P1"></site>
      <site site="semimem_r-P3"></site>
    </spatial>
    <spatial name="semiten_r_tendon" springlength="0.18592474">
      <site site="semiten_r-P1"></site>
      <site site="semiten_r-P3"></site>
      <site site="semiten_r-P4"></site>
      <site site="semiten_r-P5"></site>
    </spatial>
    <spatial name="bifemlh_r_tendon" springlength="0.23799659">
      <site site="bifemlh_r-P1"></site>
      <site site="bifemlh_r-P2"></site>
      <site site="bifemlh_r-P3"></site>
    </spatial>
    <spatial name="bifemsh_r_tendon" springlength="0.06469303">
      <site site="bifemsh_r-P1"></site>
      <site site="bifemsh_r-P2"></site>
      <site site="bifemsh_r-P3"></site>
    </spatial>
    <spatial name="sar_r_tendon" springlength="0.07286875">
      <site site="sar_r-P1"></site>
      <site site="sar_r-P2"></site>
      <site site="sar_r-P3"></site>
      <site site="sar_r-P4"></site>
      <site site="sar_r-P5"></site>
    </spatial>
    <spatial name="add_long_r_tendon" springlength="0.08063557">
      <site site="add_long_r-P1"></site>
      <site site="add_long_r-P2"></site>
    </spatial>
    <spatial name="add_brev_r_tendon" springlength="0.01465131">
      <site site="add_brev_r-P1"></site>
      <site site="add_brev_r-P2"></site>
    </spatial>
    <spatial name="add_mag1_r_tendon" springlength="0.04397385">
      <site site="add_mag1_r-P1"></site>
      <site site="add_mag1_r-P2"></site>
    </spatial>
    <spatial name="add_mag2_r_tendon" springlength="0.08805541">
      <site site="add_mag2_r-P1"></site>
      <site site="add_mag2_r-P2"></site>
    </spatial>
    <spatial name="add_mag3_r_tendon" springlength="0.18269975">
      <site site="add_mag3_r-P1"></site>
      <site site="add_mag3_r-P2"></site>
    </spatial>
    <spatial name="tfl_r_tendon" springlength="0.31060121">
      <site site="tfl_r-P1"></site>
      <site site="tfl_r-P2"></site>
      <site site="tfl_r-P3"></site>
      <site site="tfl_r-P4"></site>
    </spatial>
    <spatial name="pect_r_tendon" springlength="0.02417153">
      <site site="pect_r-P1"></site>
      <site site="pect_r-P2"></site>
    </spatial>
    <spatial name="grac_r_tendon" springlength="0.091761">
      <site site="grac_r-P1"></site>
      <site site="grac_r-P3"></site>
      <site site="grac_r-P4"></site>
    </spatial>
    <spatial name="glut_max1_r_tendon" springlength="0.09139188">
      <site site="glut_max1_r-P1"></site>
      <site site="glut_max1_r-P2"></site>
      <site site="glut_max1_r-P3"></site>
      <site site="glut_max1_r-P4"></site>
    </spatial>
    <spatial name="glut_max2_r_tendon" springlength="0.09291061">
      <site site="glut_max2_r-P1"></site>
      <site site="glut_max2_r-P2"></site>
      <site site="glut_max2_r-P3"></site>
      <site site="glut_max2_r-P4"></site>
    </spatial>
    <spatial name="glut_max3_r_tendon" springlength="0.10608002">
      <site site="glut_max3_r-P1"></site>
      <site site="glut_max3_r-P2"></site>
      <site site="glut_max3_r-P3"></site>
      <site site="glut_max3_r-P4"></site>
    </spatial>
    <spatial name="iliacus_r_tendon" springlength="0.07309827">
      <site site="iliacus_r-P1"></site>
      <site site="iliacus_r-P2"></site>
      <site site="iliacus_r-P4"></site>
      <site site="iliacus_r-P5"></site>
    </spatial>
    <spatial name="psoas_r_tendon" springlength="0.11691492">
      <site site="psoas_r-P1"></site>
      <site site="psoas_r-P2"></site>
      <site site="psoas_r-P4"></site>
      <site site="psoas_r-P5"></site>
    </spatial>
    <spatial name="quad_fem_r_tendon" springlength="0.01755006">
      <site site="quad_fem_r-P1"></site>
      <site site="quad_fem_r-P2"></site>
    </spatial>
    <spatial name="gem_r_tendon" springlength="0.02853441">
      <site site="gem_r-P1"></site>
      <site site="gem_r-P2"></site>
    </spatial>
    <spatial name="peri_r_tendon" springlength="0.08403038">
      <site site="peri_r-P1"></site>
      <site site="peri_r-P2"></site>
      <site site="peri_r-P3"></site>
    </spatial>
    <spatial name="rect_fem_r_tendon" springlength="0.22760166">
      <site site="rect_fem_r-P1"></site>
      <site site="rect_fem_r-P3"></site>
    </spatial>
    <spatial name="vas_med_r_tendon" springlength="0.09259563">
      <site site="vas_med_r-P1"></site>
      <site site="vas_med_r-P2"></site>
      <site site="vas_med_r-P5"></site>
    </spatial>
    <spatial name="vas_int_r_tendon" springlength="0.10009943">
      <site site="vas_int_r-P1"></site>
      <site site="vas_int_r-P2"></site>
      <site site="vas_int_r-P4"></site>
    </spatial>
    <spatial name="vas_lat_r_tendon" springlength="0.11530148">
      <site site="vas_lat_r-P1"></site>
      <site site="vas_lat_r-P2"></site>
      <site site="vas_lat_r-P5"></site>
    </spatial>
    <spatial name="med_gas_r_tendon" springlength="0.27641847">
      <site site="med_gas_r-P1"></site>
      <site site="med_gas_r-P3"></site>
    </spatial>
    <spatial name="lat_gas_r_tendon" springlength="0.26925678">
      <site site="lat_gas_r-P1"></site>
      <site site="lat_gas_r-P3"></site>
    </spatial>
    <spatial name="soleus_r_tendon" springlength="0.1770718">
      <site site="soleus_r-P1"></site>
      <site site="soleus_r-P2"></site>
    </spatial>
    <spatial name="tib_post_r_tendon" springlength="0.21956903">
      <site site="tib_post_r-P1"></site>
      <site site="tib_post_r-P2"></site>
      <site site="tib_post_r-P3"></site>
      <site site="tib_post_r-P4"></site>
    </spatial>
    <spatial name="flex_dig_r_tendon" springlength="0.28331488">
      <site site="flex_dig_r-P1"></site>
      <site site="flex_dig_r-P2"></site>
      <site site="flex_dig_r-P3"></site>
      <site site="flex_dig_r-P4"></site>
      <site site="flex_dig_r-P5"></site>
      <site site="flex_dig_r-P6"></site>
      <site site="flex_dig_r-P7"></site>
      <site site="flex_dig_r-P8"></site>
    </spatial>
    <spatial name="flex_hal_r_tendon" springlength="0.26914914">
      <site site="flex_hal_r-P1"></site>
      <site site="flex_hal_r-P2"></site>
      <site site="flex_hal_r-P3"></site>
      <site site="flex_hal_r-P4"></site>
      <site site="flex_hal_r-P5"></site>
      <site site="flex_hal_r-P6"></site>
      <site site="flex_hal_r-P7"></site>
    </spatial>
    <spatial name="tib_ant_r_tendon" springlength="0.15794805">
      <site site="tib_ant_r-P1"></site>
      <site site="tib_ant_r-P2"></site>
      <site site="tib_ant_r-P3"></site>
    </spatial>
    <spatial name="per_brev_r_tendon" springlength="0.11403424">
      <site site="per_brev_r-P1"></site>
      <site site="per_brev_r-P2"></site>
      <site site="per_brev_r-P3"></site>
      <site site="per_brev_r-P4"></site>
      <site site="per_brev_r-P5"></site>
    </spatial>
    <spatial name="per_long_r_tendon" springlength="0.24435908">
      <site site="per_long_r-P1"></site>
      <site site="per_long_r-P2"></site>
      <site site="per_long_r-P3"></site>
      <site site="per_long_r-P4"></site>
      <site site="per_long_r-P5"></site>
      <site site="per_long_r-P6"></site>
      <site site="per_long_r-P7"></site>
    </spatial>
    <spatial name="per_tert_r_tendon" springlength="0.07082872">
      <site site="per_tert_r-P1"></site>
      <site site="per_tert_r-P2"></site>
      <site site="per_tert_r-P3"></site>
    </spatial>
    <spatial name="ext_dig_r_tendon" springlength="0.24435908">
      <site site="ext_dig_r-P1"></site>
      <site site="ext_dig_r-P2"></site>
      <site site="ext_dig_r-P3"></site>
      <site site="ext_dig_r-P4"></site>
      <site site="ext_dig_r-P5"></site>
      <site site="ext_dig_r-P6"></site>
    </spatial>
    <spatial name="ext_hal_r_tendon" springlength="0.2160276">
      <site site="ext_hal_r-P1"></site>
      <site site="ext_hal_r-P2"></site>
      <site site="ext_hal_r-P3"></site>
      <site site="ext_hal_r-P4"></site>
      <site site="ext_hal_r-P5"></site>
      <site site="ext_hal_r-P6"></site>
      <site site="ext_hal_r-P7"></site>
    </spatial>
    <spatial name="glut_med1_l_tendon" springlength="0.05700012">
      <site site="glut_med1_l-P1"></site>
      <site site="glut_med1_l-P2"></site>
    </spatial>
    <spatial name="glut_med2_l_tendon" springlength="0.03873208">
      <site site="glut_med2_l-P1"></site>
      <site site="glut_med2_l-P2"></site>
    </spatial>
    <spatial name="glut_med3_l_tendon" springlength="0.03873998">
      <site site="glut_med3_l-P1"></site>
      <site site="glut_med3_l-P2"></site>
    </spatial>
    <spatial name="glut_min1_l_tendon" springlength="0.01170221">
      <site site="glut_min1_l-P1"></site>
      <site site="glut_min1_l-P2"></site>
    </spatial>
    <spatial name="glut_min2_l_tendon" springlength="0.01902009">
      <site site="glut_min2_l-P1"></site>
      <site site="glut_min2_l-P2"></site>
    </spatial>
    <spatial name="glut_min3_l_tendon" springlength="0.03730969">
      <site site="glut_min3_l-P1"></site>
      <site site="glut_min3_l-P2"></site>
    </spatial>
    <spatial name="semimem_l_tendon" springlength="0.26228167">
      <site site="semimem_l-P1"></site>
      <site site="semimem_l-P3"></site>
    </spatial>
    <spatial name="semiten_l_tendon" springlength="0.18592474">
      <site site="semiten_l-P1"></site>
      <site site="semiten_l-P3"></site>
      <site site="semiten_l-P4"></site>
      <site site="semiten_l-P5"></site>
    </spatial>
    <spatial name="bifemlh_l_tendon" springlength="0.23799659">
      <site site="bifemlh_l-P1"></site>
      <site site="bifemlh_l-P2"></site>
      <site site="bifemlh_l-P3"></site>
    </spatial>
    <spatial name="bifemsh_l_tendon" springlength="0.06469303">
      <site site="bifemsh_l-P1"></site>
      <site site="bifemsh_l-P2"></site>
      <site site="bifemsh_l-P3"></site>
    </spatial>
    <spatial name="sar_l_tendon" springlength="0.07286875">
      <site site="sar_l-P1"></site>
      <site site="sar_l-P2"></site>
      <site site="sar_l-P3"></site>
      <site site="sar_l-P4"></site>
      <site site="sar_l-P5"></site>
    </spatial>
    <spatial name="add_long_l_tendon" springlength="0.08063557">
      <site site="add_long_l-P1"></site>
      <site site="add_long_l-P2"></site>
    </spatial>
    <spatial name="add_brev_l_tendon" springlength="0.01465131">
      <site site="add_brev_l-P1"></site>
      <site site="add_brev_l-P2"></site>
    </spatial>
    <spatial name="add_mag1_l_tendon" springlength="0.04397385">
      <site site="add_mag1_l-P1"></site>
      <site site="add_mag1_l-P2"></site>
    </spatial>
    <spatial name="add_mag2_l_tendon" springlength="0.08805541">
      <site site="add_mag2_l-P1"></site>
      <site site="add_mag2_l-P2"></site>
    </spatial>
    <spatial name="add_mag3_l_tendon" springlength="0.18269975">
      <site site="add_mag3_l-P1"></site>
      <site site="add_mag3_l-P2"></site>
    </spatial>
    <spatial name="tfl_l_tendon" springlength="0.31060121">
      <site site="tfl_l-P1"></site>
      <site site="tfl_l-P2"></site>
      <site site="tfl_l-P3"></site>
      <site site="tfl_l-P4"></site>
    </spatial>
    <spatial name="pect_l_tendon" springlength="0.02417153">
      <site site="pect_l-P1"></site>
      <site site="pect_l-P2"></site>
    </spatial>
    <spatial name="grac_l_tendon" springlength="0.091761">
      <site site="grac_l-P1"></site>
      <site site="grac_l-P3"></site>
      <site site="grac_l-P4"></site>
    </spatial>
    <spatial name="glut_max1_l_tendon" springlength="0.09139188">
      <site site="glut_max1_l-P1"></site>
      <site site="glut_max1_l-P2"></site>
      <site site="glut_max1_l-P3"></site>
      <site site="glut_max1_l-P4"></site>
    </spatial>
    <spatial name="glut_max2_l_tendon" springlength="0.09291061">
      <site site="glut_max2_l-P1"></site>
      <site site="glut_max2_l-P2"></site>
      <site site="glut_max2_l-P3"></site>
      <site site="glut_max2_l-P4"></site>
    </spatial>
    <spatial name="glut_max3_l_tendon" springlength="0.10608002">
      <site site="glut_max3_l-P1"></site>
      <site site="glut_max3_l-P2"></site>
      <site site="glut_max3_l-P3"></site>
      <site site="glut_max3_l-P4"></site>
    </spatial>
    <spatial name="iliacus_l_tendon" springlength="0.07309827">
      <site site="iliacus_l-P1"></site>
      <site site="iliacus_l-P2"></site>
      <site site="iliacus_l-P4"></site>
      <site site="iliacus_l-P5"></site>
    </spatial>
    <spatial name="psoas_l_tendon" springlength="0.11691492">
      <site site="psoas_l-P1"></site>
      <site site="psoas_l-P2"></site>
      <site site="psoas_l-P4"></site>
      <site site="psoas_l-P5"></site>
    </spatial>
    <spatial name="quad_fem_l_tendon" springlength="0.01755006">
      <site site="quad_fem_l-P1"></site>
      <site site="quad_fem_l-P2"></site>
    </spatial>
    <spatial name="gem_l_tendon" springlength="0.02853441">
      <site site="gem_l-P1"></site>
      <site site="gem_l-P2"></site>
    </spatial>
    <spatial name="peri_l_tendon" springlength="0.08403038">
      <site site="peri_l-P1"></site>
      <site site="peri_l-P2"></site>
      <site site="peri_l-P3"></site>
    </spatial>
    <spatial name="rect_fem_l_tendon" springlength="0.22760166">
      <site site="rect_fem_l-P1"></site>
      <site site="rect_fem_l-P3"></site>
    </spatial>
    <spatial name="vas_med_l_tendon" springlength="0.09259563">
      <site site="vas_med_l-P1"></site>
      <site site="vas_med_l-P2"></site>
      <site site="vas_med_l-P5"></site>
    </spatial>
    <spatial name="vas_int_l_tendon" springlength="0.09996095">
      <site site="vas_int_l-P1"></site>
      <site site="vas_int_l-P2"></site>
      <site site="vas_int_l-P4"></site>
    </spatial>
    <spatial name="vas_lat_l_tendon" springlength="0.11530148">
      <site site="vas_lat_l-P1"></site>
      <site site="vas_lat_l-P2"></site>
      <site site="vas_lat_l-P5"></site>
    </spatial>
    <spatial name="med_gas_l_tendon" springlength="0.27641847">
      <site site="med_gas_l-P1"></site>
      <site site="med_gas_l-P3"></site>
    </spatial>
    <spatial name="lat_gas_l_tendon" springlength="0.26925678">
      <site site="lat_gas_l-P1"></site>
      <site site="lat_gas_l-P3"></site>
    </spatial>
    <spatial name="soleus_l_tendon" springlength="0.1770718">
      <site site="soleus_l-P1"></site>
      <site site="soleus_l-P2"></site>
    </spatial>
    <spatial name="tib_post_l_tendon" springlength="0.21956903">
      <site site="tib_post_l-P1"></site>
      <site site="tib_post_l-P2"></site>
      <site site="tib_post_l-P3"></site>
      <site site="tib_post_l-P4"></site>
    </spatial>
    <spatial name="flex_dig_l_tendon" springlength="0.28331488">
      <site site="flex_dig_l-P1"></site>
      <site site="flex_dig_l-P2"></site>
      <site site="flex_dig_l-P3"></site>
      <site site="flex_dig_l-P4"></site>
      <site site="flex_dig_l-P5"></site>
      <site site="flex_dig_l-P6"></site>
      <site site="flex_dig_l-P7"></site>
      <site site="flex_dig_l-P8"></site>
    </spatial>
    <spatial name="flex_hal_l_tendon" springlength="0.26914914">
      <site site="flex_hal_l-P1"></site>
      <site site="flex_hal_l-P2"></site>
      <site site="flex_hal_l-P3"></site>
      <site site="flex_hal_l-P4"></site>
      <site site="flex_hal_l-P5"></site>
      <site site="flex_hal_l-P6"></site>
      <site site="flex_hal_l-P7"></site>
    </spatial>
    <spatial name="tib_ant_l_tendon" springlength="0.15794805">
      <site site="tib_ant_l-P1"></site>
      <site site="tib_ant_l-P2"></site>
      <site site="tib_ant_l-P3"></site>
    </spatial>
    <spatial name="per_brev_l_tendon" springlength="0.11403424">
      <site site="per_brev_l-P1"></site>
      <site site="per_brev_l-P2"></site>
      <site site="per_brev_l-P3"></site>
      <site site="per_brev_l-P4"></site>
      <site site="per_brev_l-P5"></site>
    </spatial>
    <spatial name="per_long_l_tendon" springlength="0.24435908">
      <site site="per_long_l-P1"></site>
      <site site="per_long_l-P2"></site>
      <site site="per_long_l-P3"></site>
      <site site="per_long_l-P4"></site>
      <site site="per_long_l-P5"></site>
      <site site="per_long_l-P6"></site>
      <site site="per_long_l-P7"></site>
    </spatial>
    <spatial name="per_tert_l_tendon" springlength="0.07082872">
      <site site="per_tert_l-P1"></site>
      <site site="per_tert_l-P2"></site>
      <site site="per_tert_l-P3"></site>
    </spatial>
    <spatial name="ext_dig_l_tendon" springlength="0.24435908">
      <site site="ext_dig_l-P1"></site>
      <site site="ext_dig_l-P2"></site>
      <site site="ext_dig_l-P3"></site>
      <site site="ext_dig_l-P4"></site>
      <site site="ext_dig_l-P5"></site>
      <site site="ext_dig_l-P6"></site>
    </spatial>
    <spatial name="ext_hal_l_tendon" springlength="0.2160276">
      <site site="ext_hal_l-P1"></site>
      <site site="ext_hal_l-P2"></site>
      <site site="ext_hal_l-P3"></site>
      <site site="ext_hal_l-P4"></site>
      <site site="ext_hal_l-P5"></site>
      <site site="ext_hal_l-P6"></site>
      <site site="ext_hal_l-P7"></site>
    </spatial>
    <spatial name="ercspn_r_tendon" springlength="0.0219">
      <site site="ercspn_r-P1"></site>
      <site site="ercspn_r-P2"></site>
    </spatial>
    <spatial name="ercspn_l_tendon" springlength="0.0219">
      <site site="ercspn_l-P1"></site>
      <site site="ercspn_l-P2"></site>
    </spatial>
    <spatial name="intobl_r_tendon" springlength="0.073">
      <site site="intobl_r-P1"></site>
      <site site="intobl_r-P2"></site>
    </spatial>
    <spatial name="intobl_l_tendon" springlength="0.073">
      <site site="intobl_l-P1"></site>
      <site site="intobl_l-P2"></site>
    </spatial>
    <spatial name="extobl_r_tendon" springlength="0.1022">
      <site site="extobl_r-P1"></site>
      <site site="extobl_r-P2"></site>
    </spatial>
    <spatial name="extobl_l_tendon" springlength="0.1022">
      <site site="extobl_l-P1"></site>
      <site site="extobl_l-P2"></site>
    </spatial>
  </tendon>
  <actuator>
    <muscle name="glut_med1_r" tendon="glut_med1_r_tendon" class="muscle" timeconst="    0.01     0.04"></muscle>
    <muscle name="glut_med2_r" tendon="glut_med2_r_tendon" class="muscle" timeconst="    0.01     0.04"></muscle>
    <muscle name="glut_med3_r" tendon="glut_med3_r_tendon" class="muscle" timeconst="    0.01     0.04"></muscle>
    <muscle name="glut_min1_r" tendon="glut_min1_r_tendon" class="muscle" timeconst="    0.01     0.04"></muscle>
    <muscle name="glut_min2_r" tendon="glut_min2_r_tendon" class="muscle" timeconst="    0.01     0.04"></muscle>
    <muscle name="glut_min3_r" tendon="glut_min3_r_tendon" class="muscle" timeconst="    0.01     0.04"></muscle>
    <muscle name="semimem_r" tendon="semimem_r_tendon" class="muscle" timeconst="    0.01     0.04"></muscle>
    <muscle name="semiten_r" tendon="semiten_r_tendon" class="muscle" timeconst="    0.01     0.04"></muscle>
    <muscle name="bifemlh_r" tendon="bifemlh_r_tendon" class="muscle" timeconst="    0.01     0.04"></muscle>
    <muscle name="bifemsh_r" tendon="bifemsh_r_tendon" class="muscle" timeconst="    0.01     0.04"></muscle>
    <muscle name="sar_r" tendon="sar_r_tendon" class="muscle" timeconst="    0.01     0.04"></muscle>
    <muscle name="add_long_r" tendon="add_long_r_tendon" class="muscle" timeconst="    0.01     0.04"></muscle>
    <muscle name="add_brev_r" tendon="add_brev_r_tendon" class="muscle" timeconst="    0.01     0.04"></muscle>
    <muscle name="add_mag1_r" tendon="add_mag1_r_tendon" class="muscle" timeconst="    0.01     0.04"></muscle>
    <muscle name="add_mag2_r" tendon="add_mag2_r_tendon" class="muscle" timeconst="    0.01     0.04"></muscle>
    <muscle name="add_mag3_r" tendon="add_mag3_r_tendon" class="muscle" timeconst="    0.01     0.04"></muscle>
    <muscle name="tfl_r" tendon="tfl_r_tendon" class="muscle" timeconst="    0.01     0.04"></muscle>
    <muscle name="pect_r" tendon="pect_r_tendon" class="muscle" timeconst="    0.01     0.04"></muscle>
    <muscle name="grac_r" tendon="grac_r_tendon" class="muscle" timeconst="    0.01     0.04"></muscle>
    <muscle name="glut_max1_r" tendon="glut_max1_r_tendon" class="muscle" timeconst="    0.01     0.04"></muscle>
    <muscle name="glut_max2_r" tendon="glut_max2_r_tendon" class="muscle" timeconst="    0.01     0.04"></muscle>
    <muscle name="glut_max3_r" tendon="glut_max3_r_tendon" class="muscle" timeconst="    0.01     0.04"></muscle>
    <muscle name="iliacus_r" tendon="iliacus_r_tendon" class="muscle" timeconst="    0.01     0.04"></muscle>
    <muscle name="psoas_r" tendon="psoas_r_tendon" class="muscle" timeconst="    0.01     0.04"></muscle>
    <muscle name="quad_fem_r" tendon="quad_fem_r_tendon" class="muscle" timeconst="    0.01     0.04"></muscle>
    <muscle name="gem_r" tendon="gem_r_tendon" class="muscle" timeconst="    0.01     0.04"></muscle>
    <muscle name="peri_r" tendon="peri_r_tendon" class="muscle" timeconst="    0.01     0.04"></muscle>
    <muscle name="rect_fem_r" tendon="rect_fem_r_tendon" class="muscle" timeconst="    0.01     0.04"></muscle>
    <muscle name="vas_med_r" tendon="vas_med_r_tendon" class="muscle" timeconst="    0.01     0.04"></muscle>
    <muscle name="vas_int_r" tendon="vas_int_r_tendon" class="muscle" timeconst="    0.01     0.04"></muscle>
    <muscle name="vas_lat_r" tendon="vas_lat_r_tendon" class="muscle" timeconst="    0.01     0.04"></muscle>
    <muscle name="med_gas_r" tendon="med_gas_r_tendon" class="muscle" timeconst="    0.01     0.04"></muscle>
    <muscle name="lat_gas_r" tendon="lat_gas_r_tendon" class="muscle" timeconst="    0.01     0.04"></muscle>
    <muscle name="soleus_r" tendon="soleus_r_tendon" class="muscle" timeconst="    0.01     0.04"></muscle>
    <muscle name="tib_post_r" tendon="tib_post_r_tendon" class="muscle" timeconst="    0.01     0.04"></muscle>
    <muscle name="flex_dig_r" tendon="flex_dig_r_tendon" class="muscle" timeconst="    0.01     0.04"></muscle>
    <muscle name="flex_hal_r" tendon="flex_hal_r_tendon" class="muscle" timeconst="    0.01     0.04"></muscle>
    <muscle name="tib_ant_r" tendon="tib_ant_r_tendon" class="muscle" timeconst="    0.01     0.04"></muscle>
    <muscle name="per_brev_r" tendon="per_brev_r_tendon" class="muscle" timeconst="    0.01     0.04"></muscle>
    <muscle name="per_long_r" tendon="per_long_r_tendon" class="muscle" timeconst="    0.01     0.04"></muscle>
    <muscle name="per_tert_r" tendon="per_tert_r_tendon" class="muscle" timeconst="    0.01     0.04"></muscle>
    <muscle name="ext_dig_r" tendon="ext_dig_r_tendon" class="muscle" timeconst="    0.01     0.04"></muscle>
    <muscle name="ext_hal_r" tendon="ext_hal_r_tendon" class="muscle" timeconst="    0.01     0.04"></muscle>
    <muscle name="glut_med1_l" tendon="glut_med1_l_tendon" class="muscle" timeconst="    0.01     0.04"></muscle>
    <muscle name="glut_med2_l" tendon="glut_med2_l_tendon" class="muscle" timeconst="    0.01     0.04"></muscle>
    <muscle name="glut_med3_l" tendon="glut_med3_l_tendon" class="muscle" timeconst="    0.01     0.04"></muscle>
    <muscle name="glut_min1_l" tendon="glut_min1_l_tendon" class="muscle" timeconst="    0.01     0.04"></muscle>
    <muscle name="glut_min2_l" tendon="glut_min2_l_tendon" class="muscle" timeconst="    0.01     0.04"></muscle>
    <muscle name="glut_min3_l" tendon="glut_min3_l_tendon" class="muscle" timeconst="    0.01     0.04"></muscle>
    <muscle name="semimem_l" tendon="semimem_l_tendon" class="muscle" timeconst="    0.01     0.04"></muscle>
    <muscle name="semiten_l" tendon="semiten_l_tendon" class="muscle" timeconst="    0.01     0.04"></muscle>
    <muscle name="bifemlh_l" tendon="bifemlh_l_tendon" class="muscle" timeconst="    0.01     0.04"></muscle>
    <muscle name="bifemsh_l" tendon="bifemsh_l_tendon" class="muscle" timeconst="    0.01     0.04"></muscle>
    <muscle name="sar_l" tendon="sar_l_tendon" class="muscle" timeconst="    0.01     0.04"></muscle>
    <muscle name="add_long_l" tendon="add_long_l_tendon" class="muscle" timeconst="    0.01     0.04"></muscle>
    <muscle name="add_brev_l" tendon="add_brev_l_tendon" class="muscle" timeconst="    0.01     0.04"></muscle>
    <muscle name="add_mag1_l" tendon="add_mag1_l_tendon" class="muscle" timeconst="    0.01     0.04"></muscle>
    <muscle name="add_mag2_l" tendon="add_mag2_l_tendon" class="muscle" timeconst="    0.01     0.04"></muscle>
    <muscle name="add_mag3_l" tendon="add_mag3_l_tendon" class="muscle" timeconst="    0.01     0.04"></muscle>
    <muscle name="tfl_l" tendon="tfl_l_tendon" class="muscle" timeconst="    0.01     0.04"></muscle>
    <muscle name="pect_l" tendon="pect_l_tendon" class="muscle" timeconst="    0.01     0.04"></muscle>
    <muscle name="grac_l" tendon="grac_l_tendon" class="muscle" timeconst="    0.01     0.04"></muscle>
    <muscle name="glut_max1_l" tendon="glut_max1_l_tendon" class="muscle" timeconst="    0.01     0.04"></muscle>
    <muscle name="glut_max2_l" tendon="glut_max2_l_tendon" class="muscle" timeconst="    0.01     0.04"></muscle>
    <muscle name="glut_max3_l" tendon="glut_max3_l_tendon" class="muscle" timeconst="    0.01     0.04"></muscle>
    <muscle name="iliacus_l" tendon="iliacus_l_tendon" class="muscle" timeconst="    0.01     0.04"></muscle>
    <muscle name="psoas_l" tendon="psoas_l_tendon" class="muscle" timeconst="    0.01     0.04"></muscle>
    <muscle name="quad_fem_l" tendon="quad_fem_l_tendon" class="muscle" timeconst="    0.01     0.04"></muscle>
    <muscle name="gem_l" tendon="gem_l_tendon" class="muscle" timeconst="    0.01     0.04"></muscle>
    <muscle name="peri_l" tendon="peri_l_tendon" class="muscle" timeconst="    0.01     0.04"></muscle>
    <muscle name="rect_fem_l" tendon="rect_fem_l_tendon" class="muscle" timeconst="    0.01     0.04"></muscle>
    <muscle name="vas_med_l" tendon="vas_med_l_tendon" class="muscle" timeconst="    0.01     0.04"></muscle>
    <muscle name="vas_int_l" tendon="vas_int_l_tendon" class="muscle" timeconst="    0.01     0.04"></muscle>
    <muscle name="vas_lat_l" tendon="vas_lat_l_tendon" class="muscle" timeconst="    0.01     0.04"></muscle>
    <muscle name="med_gas_l" tendon="med_gas_l_tendon" class="muscle" timeconst="    0.01     0.04"></muscle>
    <muscle name="lat_gas_l" tendon="lat_gas_l_tendon" class="muscle" timeconst="    0.01     0.04"></muscle>
    <muscle name="soleus_l" tendon="soleus_l_tendon" class="muscle" timeconst="    0.01     0.04"></muscle>
    <muscle name="tib_post_l" tendon="tib_post_l_tendon" class="muscle" timeconst="    0.01     0.04"></muscle>
    <muscle name="flex_dig_l" tendon="flex_dig_l_tendon" class="muscle" timeconst="    0.01     0.04"></muscle>
    <muscle name="flex_hal_l" tendon="flex_hal_l_tendon" class="muscle" timeconst="    0.01     0.04"></muscle>
    <muscle name="tib_ant_l" tendon="tib_ant_l_tendon" class="muscle" timeconst="    0.01     0.04"></muscle>
    <muscle name="per_brev_l" tendon="per_brev_l_tendon" class="muscle" timeconst="    0.01     0.04"></muscle>
    <muscle name="per_long_l" tendon="per_long_l_tendon" class="muscle" timeconst="    0.01     0.04"></muscle>
    <muscle name="per_tert_l" tendon="per_tert_l_tendon" class="muscle" timeconst="    0.01     0.04"></muscle>
    <muscle name="ext_dig_l" tendon="ext_dig_l_tendon" class="muscle" timeconst="    0.01     0.04"></muscle>
    <muscle name="ext_hal_l" tendon="ext_hal_l_tendon" class="muscle" timeconst="    0.01     0.04"></muscle>
    <muscle name="ercspn_r" tendon="ercspn_r_tendon" class="muscle" timeconst="    0.01     0.04"></muscle>
    <muscle name="ercspn_l" tendon="ercspn_l_tendon" class="muscle" timeconst="    0.01     0.04"></muscle>
    <muscle name="intobl_r" tendon="intobl_r_tendon" class="muscle" timeconst="    0.01     0.04"></muscle>
    <muscle name="intobl_l" tendon="intobl_l_tendon" class="muscle" timeconst="    0.01     0.04"></muscle>
    <muscle name="extobl_r" tendon="extobl_r_tendon" class="muscle" timeconst="    0.01     0.04"></muscle>
    <muscle name="extobl_l" tendon="extobl_l_tendon" class="muscle" timeconst="    0.01     0.04"></muscle>
  </actuator>
  <equality>
    <joint name="knee_angle_r_translation2_constraint" active="true" joint1="knee_angle_r_translation2" joint2="knee_angle_r" polycoef="-0.290189 0.00250368 -0.00409599 0.000490941 0.000415926" solimp="0.9999 0.9999 0.001 0.5 2"></joint>
    <joint name="knee_angle_r_translation1_constraint" active="true" joint1="knee_angle_r_translation1" joint2="knee_angle_r" polycoef="-0.00266877 -0.00459562 0.00205838 0.000982944 -0.000496922" solimp="0.9999 0.9999 0.001 0.5 2"></joint>
    <joint name="subtalar_angle_r_constraint" active="true" joint1="subtalar_angle_r" polycoef="       0        0        0        0        0"></joint>
    <joint name="mtp_angle_r_constraint" active="true" joint1="mtp_angle_r" polycoef="       0        0        0        0        0"></joint>
    <joint name="knee_angle_l_translation2_constraint" active="true" joint1="knee_angle_l_translation2" joint2="knee_angle_l" polycoef="-0.290189 0.00250368 -0.00409599 0.000490941 0.000415926" solimp="0.9999 0.9999 0.001 0.5 2"></joint>
    <joint name="knee_angle_l_translation1_constraint" active="true" joint1="knee_angle_l_translation1" joint2="knee_angle_l" polycoef="-0.00266877 -0.00459562 0.00205838 0.000982944 -0.000496922" solimp="0.9999 0.9999 0.001 0.5 2"></joint>
    <joint name="subtalar_angle_l_constraint" active="true" joint1="subtalar_angle_l" polycoef="       0        0        0        0        0"></joint>
    <joint name="mtp_angle_l_constraint" active="true" joint1="mtp_angle_l" polycoef="       0        0        0        0        0"></joint>
    <weld name="origin_to_worldbody" body1="pelvis" active="false"></weld>
  </equality>
  <contact>
    <pair geom1="floor" geom2="foot"/>
    <pair geom1="floor" geom2="bofoot"/>
    <pair geom1="floor" geom2="l_bofoot"/>
    <pair geom1="floor" geom2="l_foot"/>
  </contact>
</mujoco>
