<?xml version="1.0" encoding="utf-8"?>
<mujoco model="gait10dof18musc.osim">
  <compiler inertiafromgeom="auto" angle="radian" balanceinertia="true" boundmass="0.001" boundinertia="0.001">
    <lengthrange inttotal="50" useexisting="true"></lengthrange>
  </compiler>
  <default>
    <joint limited="true" damping="0.5" armature="0.1" stiffness="2"></joint>
    <geom rgba="0.8 0.6 .4 1" margin="0.001"></geom>
    <site size="0.001"></site>
    <tendon width="0.001" rgba=".95 .3 .3 1" limited="false"></tendon>
    <default class="muscle">
      <muscle ctrllimited="true" ctrlrange="0 1" scale="200"></muscle>
    </default>
    <default class="motor">
      <general gainprm="5 0 0 0 0 0 0 0 0 0"></general>
    </default>
  </default>
  <option timestep="0.002"></option>
  <size njmax="1000" nconmax="400" nuser_jnt="1"></size>
  <worldbody>
    <geom name="floor" pos="0 0 0" size="10 10 0.125" type="plane" material="MatPlane" condim="3"></geom>
    <body name="pelvis" pos="       0    -0.02        1" quat="0.7071067811865475 0.7071067811865475 0.0 0.0">
      <light mode="trackcom" directional="false" pos="0 0 4.0" dir="0 0 -1"></light>
      <geom name="sacrum" type="mesh" mesh="sacrum"></geom>
      <geom name="pelvis" type="mesh" mesh="pelvis"></geom>
      <geom name="l_pelvis" type="mesh" mesh="l_pelvis"></geom>
      <inertial pos=" -0.0707        0        0" mass="11.777" fullinertia="  0.1028   0.0871   0.0579        0        0        0"></inertial>
      <site name="bifemlh_r-P1" pos="-0.129056 -0.105091 0.0711468"></site>
      <site name="glut_max_r-P1" pos="-0.134937 0.00891385 0.0473356"></site>
      <site name="glut_max_r-P2" pos="-0.137704 -0.0623969 0.0832984"></site>
      <site name="psoas_r-P1" pos="-0.0662903 0.0908802 0.0296104"></site>
      <site name="psoas_r-P2" pos="-0.024385 -0.0584011 0.0777656"></site>
      <site name="psoas_r-P3" pos="-0.0295079 -0.0824787 0.0836057"></site>
      <site name="rect_fem_r-P1" pos="-0.0302251 -0.0318644 0.0991793"></site>
      <site name="bifemlh_l-P1" pos="-0.129056 -0.105091 -0.0711468"></site>
      <site name="glut_max_l-P1" pos="-0.134937 0.00891385 -0.0473356"></site>
      <site name="glut_max_l-P2" pos="-0.137704 -0.0623969 -0.0832984"></site>
      <site name="psoas_l-P1" pos="-0.0662903 0.0908802 -0.0296104"></site>
      <site name="psoas_l-P2" pos="-0.024385 -0.0584011 -0.0777656"></site>
      <site name="psoas_l-P3" pos="-0.0295079 -0.0824787 -0.0836057"></site>
      <site name="rect_fem_l-P1" pos="-0.0302251 -0.0318644 -0.0991793"></site>
      <joint name="pelvis_ty" type="slide" pos="0 0 0" axis="       0        1        0" limited="false" range="      -1        2" ref="0" armature="0" damping="0" stiffness="0"></joint>
      <joint name="pelvis_tx" type="slide" pos="0 0 0" axis="       1        0        0" limited="false" range="      -5        5" ref="0" armature="0" damping="0" stiffness="0"></joint>
      <joint name="pelvis_tilt" type="hinge" pos="0 0 0" axis="       0        0        1" limited="false" range=" -1.5708   1.5708" ref="0" armature="0" damping="0" stiffness="0"></joint>
      <body name="femur_r" pos=" -0.0707  -0.0661   0.0835" quat="1.0 0.0 0.0 0.0">
        <geom name="femur_r" type="mesh" mesh="femur_r"></geom>
        <inertial pos="       0    -0.17        0" mass="9.3014" fullinertia="  0.1339   0.0351   0.1412        0        0        0"></inertial>
        <site name="bifemsh_r-P1" pos="0.0057362 -0.242182 0.0268454"></site>
        <site name="glut_max_r-P3" pos="-0.0516258 -0.0669988 0.0289104"></site>
        <site name="glut_max_r-P4" pos="-0.0178969 -0.11656 0.0480694"></site>
        <site name="psoas_r-P4" pos="0.00183558 -0.0581651 0.00435951"></site>
        <site name="psoas_r-P5" pos="-0.0215681 -0.0684902 0.0119313"></site>
        <site name="rect_fem_r-P2" pos="0.0383178 -0.462338 0.00217976"></site>
        <site name="vas_int_r-P1" pos="0.03327 -0.220729 0.0355644"></site>
        <site name="vas_int_r-P2" pos="0.0384325 -0.239085 0.0326963"></site>
        <site name="vas_int_r-P3" pos="0.0393503 -0.462338 0.00630982"></site>
        <site name="med_gas_r-P1" pos="-0.0217976 -0.450751 -0.0269601"></site>
        <site name="med_gas_r-P2" pos="-0.0344172 -0.46142 -0.0295988"></site>
        <joint name="hip_flexion_r" type="hinge" pos="0 0 0" axis="       0        0        1" limited="false" range=" -2.0944   2.0944" ref="0"></joint>
        <body name="tibia_r" pos="       0        0        0" quat="1.0 0.0 0.0 0.0">
          <geom name="tibia_r" type="mesh" mesh="tibia_r"></geom>
          <geom name="fibula" type="mesh" mesh="fibula"></geom>
          <inertial pos="       0  -0.1867        0" mass="3.7075" fullinertia="  0.0504   0.0051   0.0511        0        0        0"></inertial>
          <site name="bifemlh_r-P2" pos="-0.0297545 -0.0355868 0.0290922"></site>
          <site name="bifemlh_r-P3" pos="-0.0231314 -0.0556538 0.0339063"></site>
          <site name="bifemsh_r-P2" pos="-0.0297545 -0.0355868 0.0290922"></site>
          <site name="bifemsh_r-P3" pos="-0.0231314 -0.0556538 0.0339063"></site>
          <site name="rect_fem_r-P3" pos="0.0780827 -0.0123631   0.0014"></site>
          <site name="vas_int_r-P4" pos="0.0785259 -0.00619903   0.0018"></site>
          <site name="soleus_r-P1" pos="-0.00237246 -0.151541 0.00701851"></site>
          <site name="tib_ant_r-P1" pos="0.0176946 -0.160536 0.011368"></site>
          <site name="tib_ant_r-P2" pos="0.0325224 -0.390565 -0.0174969"></site>
          <joint name="knee_angle_r_translation2" type="slide" pos="0 0 0" axis="       0        1        0" limited="true" range="-0.422602 -0.395309" ref="0"></joint>
          <joint name="knee_angle_r_translation1" type="slide" pos="0 0 0" axis="       1        0        0" limited="true" range="-0.00591791 0.00435888" ref="0"></joint>
          <joint name="knee_angle_r" type="hinge" pos="0 0 0" axis="       0        0        1" limited="false" range=" -2.0944 0.174533" ref="0"></joint>
          <body name="talus_r" pos="       0    -0.43        0" quat="1.0 0.0 0.0 0.0">
            <geom name="talus" type="mesh" mesh="talus"></geom>
            <inertial pos="       0        0        0" mass="0.1" fullinertia="   0.001    0.001    0.001        0        0        0"></inertial>
            <joint name="ankle_angle_r" type="hinge" pos="0 0 0" axis="       0        0        1" limited="false" range=" -1.5708   1.5708" ref="0"></joint>
            <body name="calcn_r" pos="-0.04877 -0.04195  0.00792" quat="1.0 0.0 0.0 0.0">
              <geom name="foot" type="mesh" mesh="foot"></geom>
              <inertial pos="     0.1     0.03        0" mass="1.25" fullinertia="  0.0014   0.0039   0.0041        0        0        0"></inertial>
              <site name="med_gas_r-P3" pos="0 0.0318395 -0.00544352"></site>
              <site name="soleus_r-P2" pos="0 0.0318395 -0.00544352"></site>
              <site name="tib_ant_r-P3" pos="0.119758 0.018282 -0.0313259"></site>
              <body name="toes_r" pos="  0.1788   -0.002  0.00108" quat="1.0 0.0 0.0 0.0">
                <geom name="bofoot" type="mesh" mesh="bofoot"></geom>
                <inertial pos="  0.0346    0.006  -0.0175" mass="0.2166" fullinertia="  0.0001   0.0002   0.0001        0        0        0"></inertial>
              </body>
            </body>
          </body>
        </body>
      </body>
      <body name="femur_l" pos=" -0.0707  -0.0661  -0.0835" quat="1.0 0.0 0.0 0.0">
        <geom name="femur_l" type="mesh" mesh="femur_l"></geom>
        <inertial pos="       0    -0.17        0" mass="9.3014" fullinertia="  0.1339   0.0351   0.1412        0        0        0"></inertial>
        <site name="bifemsh_l-P1" pos="0.0057362 -0.242182 -0.0268454"></site>
        <site name="glut_max_l-P3" pos="-0.0516258 -0.0669988 -0.0289104"></site>
        <site name="glut_max_l-P4" pos="-0.0178969 -0.11656 -0.0480694"></site>
        <site name="psoas_l-P4" pos="0.00183558 -0.0581651 -0.00435951"></site>
        <site name="psoas_l-P5" pos="-0.0215681 -0.0684902 -0.0119313"></site>
        <site name="rect_fem_l-P2" pos="0.0383178 -0.462338 -0.00217976"></site>
        <site name="vas_int_l-P1" pos="0.03327 -0.220729 -0.0355644"></site>
        <site name="vas_int_l-P2" pos="0.0384325 -0.239085 -0.0326963"></site>
        <site name="vas_int_l-P3" pos="0.0393503 -0.462338 -0.00630982"></site>
        <site name="med_gas_l-P1" pos="-0.0217976 -0.450751 0.0269601"></site>
        <site name="med_gas_l-P2" pos="-0.0344172 -0.46142 0.0295988"></site>
        <joint name="hip_flexion_l" type="hinge" pos="0 0 0" axis="       0        0        1" limited="false" range=" -2.0944   2.0944" ref="0"></joint>
        <body name="tibia_l" pos="       0        0        0" quat="1.0 0.0 0.0 0.0">
          <geom name="tibia_l" type="mesh" mesh="tibia_l"></geom>
          <geom name="l_fibula" type="mesh" mesh="l_fibula"></geom>
          <inertial pos="       0  -0.1867        0" mass="3.7075" fullinertia="  0.0504   0.0051   0.0511        0        0        0"></inertial>
          <site name="bifemlh_l-P2" pos="-0.0297545 -0.0355868 -0.0290922"></site>
          <site name="bifemlh_l-P3" pos="-0.0231314 -0.0556538 -0.0339063"></site>
          <site name="bifemsh_l-P2" pos="-0.0297545 -0.0355868 -0.0290922"></site>
          <site name="bifemsh_l-P3" pos="-0.0231314 -0.0556538 -0.0339063"></site>
          <site name="rect_fem_l-P3" pos="0.0780827 -0.0123631  -0.0014"></site>
          <site name="vas_int_l-P4" pos="0.0785259 -0.00619903  -0.0018"></site>
          <site name="soleus_l-P1" pos="-0.00237246 -0.151541 -0.00701851"></site>
          <site name="tib_ant_l-P1" pos="0.0176946 -0.160536 -0.011368"></site>
          <site name="tib_ant_l-P2" pos="0.0325224 -0.390565 0.0174969"></site>
          <joint name="knee_angle_l_translation2" type="slide" pos="0 0 0" axis="       0        1        0" limited="true" range="-0.422602 -0.395309" ref="0"></joint>
          <joint name="knee_angle_l_translation1" type="slide" pos="0 0 0" axis="       1        0        0" limited="true" range="-0.00591791 0.00435888" ref="0"></joint>
          <joint name="knee_angle_l" type="hinge" pos="0 0 0" axis="       0        0        1" limited="false" range=" -2.0944 0.174533" ref="0"></joint>
          <body name="talus_l" pos="       0    -0.43        0" quat="1.0 0.0 0.0 0.0">
            <geom name="l_talus" type="mesh" mesh="l_talus"></geom>
            <inertial pos="       0        0        0" mass="0.1" fullinertia="   0.001    0.001    0.001        0        0        0"></inertial>
            <joint name="ankle_angle_l" type="hinge" pos="0 0 0" axis="       0        0        1" limited="false" range=" -1.5708   1.5708" ref="0"></joint>
            <body name="calcn_l" pos="-0.04877 -0.04195 -0.00792" quat="1.0 0.0 0.0 0.0">
              <geom name="l_foot" type="mesh" mesh="l_foot"></geom>
              <inertial pos="     0.1     0.03        0" mass="1.25" fullinertia="  0.0014   0.0039   0.0041        0        0        0"></inertial>
              <site name="med_gas_l-P3" pos="0 0.0318395 0.00544352"></site>
              <site name="soleus_l-P2" pos="0 0.0318395 0.00544352"></site>
              <site name="tib_ant_l-P3" pos="0.119758 0.018282 0.0313259"></site>
              <body name="toes_l" pos="  0.1788   -0.002 -0.00108" quat="1.0 0.0 0.0 0.0">
                <geom name="l_bofoot" type="mesh" mesh="l_bofoot"></geom>
                <inertial pos="  0.0346    0.006   0.0175" mass="0.2166" fullinertia="  0.0001   0.0002   0.0001        0        0        0"></inertial>
              </body>
            </body>
          </body>
        </body>
      </body>
      <body name="torso" pos=" -0.1007   0.0815        0" quat="1.0 0.0 0.0 0.0">
        <geom name="hat_spine" type="mesh" mesh="hat_spine"></geom>
        <geom name="hat_jaw" type="mesh" mesh="hat_jaw"></geom>
        <geom name="hat_skull" type="mesh" mesh="hat_skull"></geom>
        <geom name="hat_ribs" type="mesh" mesh="hat_ribs"></geom>
        <inertial pos="   -0.03     0.32        0" mass="34.2366" fullinertia="  1.4745   0.7555   1.4314        0        0        0"></inertial>
        <joint name="lumbar_extension" type="hinge" pos="0 0 0" axis="       0        0        1" limited="false" range=" -1.5708   1.5708" ref="0"></joint>
      </body>
    </body>
    <camera name="for_testing" pos="0 0 0" euler="0 0 0"></camera>
  </worldbody>
  <asset>
    <mesh name="sacrum" file="Geometry/sacrum.stl" scale="       1        1        1"></mesh>
    <mesh name="pelvis" file="Geometry/pelvis.stl" scale="       1        1        1"></mesh>
    <mesh name="l_pelvis" file="Geometry/l_pelvis.stl" scale="       1        1        1"></mesh>
    <mesh name="femur_r" file="Geometry/femur_r.stl" scale="       1        1        1"></mesh>
    <mesh name="tibia_r" file="Geometry/tibia_r.stl" scale="       1        1        1"></mesh>
    <mesh name="fibula" file="Geometry/fibula.stl" scale="       1        1        1"></mesh>
    <mesh name="talus" file="Geometry/talus.stl" scale="       1        1        1"></mesh>
    <mesh name="foot" file="Geometry/foot.stl" scale="       1        1        1"></mesh>
    <mesh name="bofoot" file="Geometry/bofoot.stl" scale="       1        1        1"></mesh>
    <mesh name="femur_l" file="Geometry/femur_l.stl" scale="       1        1        1"></mesh>
    <mesh name="tibia_l" file="Geometry/tibia_l.stl" scale="       1        1        1"></mesh>
    <mesh name="l_fibula" file="Geometry/l_fibula.stl" scale="       1        1        1"></mesh>
    <mesh name="l_talus" file="Geometry/l_talus.stl" scale="       1        1        1"></mesh>
    <mesh name="l_foot" file="Geometry/l_foot.stl" scale="       1        1        1"></mesh>
    <mesh name="l_bofoot" file="Geometry/l_bofoot.stl" scale="       1        1        1"></mesh>
    <mesh name="hat_spine" file="Geometry/hat_spine.stl" scale="       1        1        1"></mesh>
    <mesh name="hat_jaw" file="Geometry/hat_jaw.stl" scale="       1        1        1"></mesh>
    <mesh name="hat_skull" file="Geometry/hat_skull.stl" scale="       1        1        1"></mesh>
    <mesh name="hat_ribs" file="Geometry/hat_ribs.stl" scale="       1        1        1"></mesh>
    <texture name="texplane" type="2d" builtin="checker" rgb1=".2 .3 .4" rgb2=".1 0.15 0.2" width="100" height="100"></texture>
    <material name="MatPlane" reflectance="0.0" texture="texplane" texrepeat="1 1" texuniform="true"></material>
  </asset>
  <tendon>
    <spatial name="hamstrings_r_tendon">
      <site site="bifemlh_r-P1"></site>
      <site site="bifemlh_r-P2"></site>
      <site site="bifemlh_r-P3"></site>
    </spatial>
    <spatial name="bifemsh_r_tendon">
      <site site="bifemsh_r-P1"></site>
      <site site="bifemsh_r-P2"></site>
      <site site="bifemsh_r-P3"></site>
    </spatial>
    <spatial name="glut_max_r_tendon">
      <site site="glut_max_r-P1"></site>
      <site site="glut_max_r-P2"></site>
      <site site="glut_max_r-P3"></site>
      <site site="glut_max_r-P4"></site>
    </spatial>
    <spatial name="iliopsoas_r_tendon">
      <site site="psoas_r-P1"></site>
      <site site="psoas_r-P2"></site>
      <site site="psoas_r-P3"></site>
      <site site="psoas_r-P4"></site>
      <site site="psoas_r-P5"></site>
    </spatial>
    <spatial name="rect_fem_r_tendon">
      <site site="rect_fem_r-P1"></site>
      <site site="rect_fem_r-P2"></site>
      <site site="rect_fem_r-P3"></site>
    </spatial>
    <spatial name="vasti_r_tendon">
      <site site="vas_int_r-P1"></site>
      <site site="vas_int_r-P2"></site>
      <site site="vas_int_r-P3"></site>
      <site site="vas_int_r-P4"></site>
    </spatial>
    <spatial name="gastroc_r_tendon">
      <site site="med_gas_r-P1"></site>
      <site site="med_gas_r-P2"></site>
      <site site="med_gas_r-P3"></site>
    </spatial>
    <spatial name="soleus_r_tendon">
      <site site="soleus_r-P1"></site>
      <site site="soleus_r-P2"></site>
    </spatial>
    <spatial name="tib_ant_r_tendon">
      <site site="tib_ant_r-P1"></site>
      <site site="tib_ant_r-P2"></site>
      <site site="tib_ant_r-P3"></site>
    </spatial>
    <spatial name="hamstrings_l_tendon">
      <site site="bifemlh_l-P1"></site>
      <site site="bifemlh_l-P2"></site>
      <site site="bifemlh_l-P3"></site>
    </spatial>
    <spatial name="bifemsh_l_tendon">
      <site site="bifemsh_l-P1"></site>
      <site site="bifemsh_l-P2"></site>
      <site site="bifemsh_l-P3"></site>
    </spatial>
    <spatial name="glut_max_l_tendon">
      <site site="glut_max_l-P1"></site>
      <site site="glut_max_l-P2"></site>
      <site site="glut_max_l-P3"></site>
      <site site="glut_max_l-P4"></site>
    </spatial>
    <spatial name="iliopsoas_l_tendon">
      <site site="psoas_l-P1"></site>
      <site site="psoas_l-P2"></site>
      <site site="psoas_l-P3"></site>
      <site site="psoas_l-P4"></site>
      <site site="psoas_l-P5"></site>
    </spatial>
    <spatial name="rect_fem_l_tendon">
      <site site="rect_fem_l-P1"></site>
      <site site="rect_fem_l-P2"></site>
      <site site="rect_fem_l-P3"></site>
    </spatial>
    <spatial name="vasti_l_tendon">
      <site site="vas_int_l-P1"></site>
      <site site="vas_int_l-P2"></site>
      <site site="vas_int_l-P3"></site>
      <site site="vas_int_l-P4"></site>
    </spatial>
    <spatial name="gastroc_l_tendon">
      <site site="med_gas_l-P1"></site>
      <site site="med_gas_l-P2"></site>
      <site site="med_gas_l-P3"></site>
    </spatial>
    <spatial name="soleus_l_tendon">
      <site site="soleus_l-P1"></site>
      <site site="soleus_l-P2"></site>
    </spatial>
    <spatial name="tib_ant_l_tendon">
      <site site="tib_ant_l-P1"></site>
      <site site="tib_ant_l-P2"></site>
      <site site="tib_ant_l-P3"></site>
    </spatial>
  </tendon>
  <actuator>
    <muscle name="hamstrings_r" tendon="hamstrings_r_tendon" class="muscle" timeconst="    0.01     0.04" force="2700" lengthrange="0.431574 0.555205" ctrllimited="true" ctrlrange="       0        1"></muscle>
    <muscle name="bifemsh_r" tendon="bifemsh_r_tendon" class="muscle" timeconst="    0.01     0.04" force="804" lengthrange="0.186602 0.362828" ctrllimited="true" ctrlrange="       0        1"></muscle>
    <muscle name="glut_max_r" tendon="glut_max_r_tendon" class="muscle" timeconst="    0.01     0.04" force="1944" lengthrange="0.165243 0.336093" ctrllimited="true" ctrlrange="       0        1"></muscle>
    <muscle name="iliopsoas_r" tendon="iliopsoas_r_tendon" class="muscle" timeconst="    0.01     0.04" force="2342" lengthrange=" 0.22035 0.324499" ctrllimited="true" ctrlrange="       0        1"></muscle>
    <muscle name="rect_fem_r" tendon="rect_fem_r_tendon" class="muscle" timeconst="    0.01     0.04" force="1169" lengthrange="0.419749 0.549715" ctrllimited="true" ctrlrange="       0        1"></muscle>
    <muscle name="vasti_r" tendon="vasti_r_tendon" class="muscle" timeconst="    0.01     0.04" force="5000" lengthrange=" 0.19742 0.321927" ctrllimited="true" ctrlrange="       0        1"></muscle>
    <muscle name="gastroc_r" tendon="gastroc_r_tendon" class="muscle" timeconst="    0.01     0.04" force="2500" lengthrange=" 0.40361 0.489801" ctrllimited="true" ctrlrange="       0        1"></muscle>
    <muscle name="soleus_r" tendon="soleus_r_tendon" class="muscle" timeconst="    0.01     0.04" force="5137" lengthrange="0.274233  0.31981" ctrllimited="true" ctrlrange="       0        1"></muscle>
    <muscle name="tib_ant_r" tendon="tib_ant_r_tendon" class="muscle" timeconst="    0.01     0.04" force="3000" lengthrange="0.271571 0.369111" ctrllimited="true" ctrlrange="       0        1"></muscle>
    <muscle name="hamstrings_l" tendon="hamstrings_l_tendon" class="muscle" timeconst="    0.01     0.04" force="2700" lengthrange="0.431574 0.555205" ctrllimited="true" ctrlrange="       0        1"></muscle>
    <muscle name="bifemsh_l" tendon="bifemsh_l_tendon" class="muscle" timeconst="    0.01     0.04" force="804" lengthrange="0.186602 0.362828" ctrllimited="true" ctrlrange="       0        1"></muscle>
    <muscle name="glut_max_l" tendon="glut_max_l_tendon" class="muscle" timeconst="    0.01     0.04" force="1944" lengthrange="0.165243 0.336093" ctrllimited="true" ctrlrange="       0        1"></muscle>
    <muscle name="iliopsoas_l" tendon="iliopsoas_l_tendon" class="muscle" timeconst="    0.01     0.04" force="2342" lengthrange=" 0.22035 0.324499" ctrllimited="true" ctrlrange="       0        1"></muscle>
    <muscle name="rect_fem_l" tendon="rect_fem_l_tendon" class="muscle" timeconst="    0.01     0.04" force="1169" lengthrange="0.419749 0.549715" ctrllimited="true" ctrlrange="       0        1"></muscle>
    <muscle name="vasti_l" tendon="vasti_l_tendon" class="muscle" timeconst="    0.01     0.04" force="5000" lengthrange=" 0.19742 0.321927" ctrllimited="true" ctrlrange="       0        1"></muscle>
    <muscle name="gastroc_l" tendon="gastroc_l_tendon" class="muscle" timeconst="    0.01     0.04" force="2500" lengthrange=" 0.40361 0.489801" ctrllimited="true" ctrlrange="       0        1"></muscle>
    <muscle name="soleus_l" tendon="soleus_l_tendon" class="muscle" timeconst="    0.01     0.04" force="5137" lengthrange="0.274233  0.31981" ctrllimited="true" ctrlrange="       0        1"></muscle>
    <muscle name="tib_ant_l" tendon="tib_ant_l_tendon" class="muscle" timeconst="    0.01     0.04" force="3000" lengthrange="0.271571 0.369111" ctrllimited="true" ctrlrange="       0        1"></muscle>
  </actuator>
  <equality>
    <joint name="knee_angle_r_translation2_constraint" active="true" joint1="knee_angle_r_translation2" joint2="knee_angle_r" polycoef="-0.395713 0.00341345 -0.00558653 0.000669664 0.000567409" solimp="0.9999 0.9999 0.001 0.5 2"></joint>
    <joint name="knee_angle_r_translation1_constraint" active="true" joint1="knee_angle_r_translation1" joint2="knee_angle_r" polycoef="-0.00363925 -0.00626677 0.00280689 0.00134038 -0.000677624" solimp="0.9999 0.9999 0.001 0.5 2"></joint>
    <joint name="knee_angle_l_translation2_constraint" active="true" joint1="knee_angle_l_translation2" joint2="knee_angle_l" polycoef="-0.395713 0.00341345 -0.00558653 0.000669664 0.000567409" solimp="0.9999 0.9999 0.001 0.5 2"></joint>
    <joint name="knee_angle_l_translation1_constraint" active="true" joint1="knee_angle_l_translation1" joint2="knee_angle_l" polycoef="-0.00363925 -0.00626677 0.00280689 0.00134038 -0.000677624" solimp="0.9999 0.9999 0.001 0.5 2"></joint>
    <weld name="origin_to_worldbody" body1="pelvis" active="false"></weld>
  </equality>
</mujoco>