<?xml version="1.0" encoding="utf-8"?>
<mujoco model="arm26_converted">
	<compiler inertiafromgeom="auto" angle="radian"></compiler>
	<default>
		<joint limited="true" damping="1" armature="0.01" stiffness="5"></joint>
		<geom contype="1" conaffinity="1" condim="3" rgba="0.8 0.6 .4 1" margin="0.001" solref=".02 1" solimp=".8 .8 .01" material="geom"></geom>
		<site size="0.01"></site>
	</default>
	<option timestep="0.002" iterations="50" solver="PGS">
		<flag energy="enable"></flag>
	</option>
	<size nconmax="400"></size>
	<visual>
		<map fogstart="3" fogend="5" force="0.1"></map>
		<quality shadowsize="2048"></quality>
	</visual>
	<worldbody>
		<geom name="floor" pos="0 0 0" size="10 10 0.125" type="plane" material="MatPlane" condim="3"></geom>
		<body name="base" pos="0. 0. 1.5" quat="0.7071067811865476 0.7071067811865475 0.0 0.0">
			<light mode="trackcom" directional="false" diffuse=".8 .8 .8" specular="0.3 0.3 0.3" pos="0 0 4.0" dir="0 0 -1"></light>
			<geom name="ground_ribs" type="mesh" mesh="ground_ribs"></geom>
			<geom name="ground_spine" type="mesh" mesh="ground_spine"></geom>
			<geom name="ground_skull" type="mesh" mesh="ground_skull"></geom>
			<geom name="ground_jaw" type="mesh" mesh="ground_jaw"></geom>
			<geom name="ground_r_clavicle" type="mesh" mesh="ground_r_clavicle"></geom>
			<geom name="ground_r_scapula" type="mesh" mesh="ground_r_scapula"></geom>
			<site name="TRIlong-P1" pos="-0.05365 -0.01373 0.14723"></site>
			<site name="BIClong-P1" pos="-0.039235 0.00347 0.14795"></site>
			<site name="BIClong-P2" pos="-0.028945 0.01391 0.15639"></site>
			<site name="BICshort-P1" pos="0.004675 -0.01231 0.13475"></site>
			<site name="BICshort-P2" pos="-0.007075 -0.04004 0.14507"></site>
			<body name="r_humerus" pos="-0.017545 -0.007     0.17    " quat="1.0 0.0 0.0 0.0">
				<inertial pos=" 0.       -0.180496  0.      " mass="1.864572" fullinertia="0.01481  0.004551 0.013193 0.       0.       0.      "></inertial>
				<geom name="arm_r_humerus" type="mesh" mesh="arm_r_humerus"></geom>
				<site name="TRIlong-P2" pos="-0.02714 -0.11441 -0.00664"></site>
				<site name="TRIlong-P3" pos="-0.03184 -0.22637 -0.01217"></site>
				<site name="TRIlong-P4" pos="-0.01743 -0.26757 -0.01208"></site>
				<site name="TRIlat-P1" pos="-0.00599 -0.12646 0.00428"></site>
				<site name="TRIlat-P2" pos="-0.02344 -0.14528 0.00928"></site>
				<site name="TRIlat-P3" pos="-0.03184 -0.22637 -0.01217"></site>
				<site name="TRIlat-P4" pos="-0.01743 -0.26757 -0.01208"></site>
				<site name="TRImed-P1" pos="-0.00838 -0.13695 -0.00906"></site>
				<site name="TRImed-P2" pos="-0.02601 -0.15139 -0.0108"></site>
				<site name="TRImed-P3" pos="-0.03184 -0.22637 -0.01217"></site>
				<site name="TRImed-P4" pos="-0.01743 -0.26757 -0.01208"></site>
				<site name="BIClong-P3" pos="0.02131 0.01793 0.01028"></site>
				<site name="BIClong-P4" pos="0.02378 -0.00511 0.01201"></site>
				<site name="BIClong-P5" pos="0.01345 -0.02827 0.00136"></site>
				<site name="BIClong-P6" pos="0.01068 -0.07736 -0.00165"></site>
				<site name="BIClong-P7" pos="0.01703 -0.12125 0.00024"></site>
				<site name="BIClong-P8" pos="0.0228 -0.1754 -0.0063"></site>
				<site name="BICshort-P3" pos="0.01117 -0.07576 -0.01101"></site>
				<site name="BICshort-P4" pos="0.01703 -0.12125 -0.01079"></site>
				<site name="BICshort-P5" pos="0.0228 -0.1754 -0.0063"></site>
				<site name="BRA-P1" pos="0.0068 -0.1739 -0.0036"></site>
				<joint name="r_shoulder_rotation1" type="hinge" pos="0 0 0" limited="false" axis="-0.05889802  0.0023      0.99826136" range="-1.57079633  3.14159265"></joint>
				<body name="r_ulna_radius_hand" pos=" 0.0061 -0.2904 -0.0123" quat="1.0 0.0 0.0 0.0">
					<inertial pos=" 0.       -0.181479  0.      " mass="1.534315" fullinertia="0.019281 0.001571 0.020062 0.       0.       0.      "></inertial>
					<geom name="arm_r_ulna" type="mesh" mesh="arm_r_ulna"></geom>
					<geom name="arm_r_radius" type="mesh" mesh="arm_r_radius"></geom>
					<geom name="arm_r_lunate" type="mesh" mesh="arm_r_lunate"></geom>
					<geom name="arm_r_scaphoid" type="mesh" mesh="arm_r_scaphoid"></geom>
					<geom name="arm_r_pisiform" type="mesh" mesh="arm_r_pisiform"></geom>
					<geom name="arm_r_triquetrum" type="mesh" mesh="arm_r_triquetrum"></geom>
					<geom name="arm_r_capitate" type="mesh" mesh="arm_r_capitate"></geom>
					<geom name="arm_r_trapezium" type="mesh" mesh="arm_r_trapezium"></geom>
					<geom name="arm_r_trapezoid" type="mesh" mesh="arm_r_trapezoid"></geom>
					<geom name="arm_r_hamate" type="mesh" mesh="arm_r_hamate"></geom>
					<geom name="arm_r_1mc" type="mesh" mesh="arm_r_1mc"></geom>
					<geom name="arm_r_2mc" type="mesh" mesh="arm_r_2mc"></geom>
					<geom name="arm_r_3mc" type="mesh" mesh="arm_r_3mc"></geom>
					<geom name="arm_r_4mc" type="mesh" mesh="arm_r_4mc"></geom>
					<geom name="arm_r_5mc" type="mesh" mesh="arm_r_5mc"></geom>
					<geom name="arm_r_thumbprox" type="mesh" mesh="arm_r_thumbprox"></geom>
					<geom name="arm_r_thumbdist" type="mesh" mesh="arm_r_thumbdist"></geom>
					<geom name="arm_r_2proxph" type="mesh" mesh="arm_r_2proxph"></geom>
					<geom name="arm_r_2midph" type="mesh" mesh="arm_r_2midph"></geom>
					<geom name="arm_r_2distph" type="mesh" mesh="arm_r_2distph"></geom>
					<geom name="arm_r_3proxph" type="mesh" mesh="arm_r_3proxph"></geom>
					<geom name="arm_r_3midph" type="mesh" mesh="arm_r_3midph"></geom>
					<geom name="arm_r_3distph" type="mesh" mesh="arm_r_3distph"></geom>
					<geom name="arm_r_4proxph" type="mesh" mesh="arm_r_4proxph"></geom>
					<geom name="arm_r_4midph" type="mesh" mesh="arm_r_4midph"></geom>
					<geom name="arm_r_4distph" type="mesh" mesh="arm_r_4distph"></geom>
					<geom name="arm_r_5proxph" type="mesh" mesh="arm_r_5proxph"></geom>
					<geom name="arm_r_5midph" type="mesh" mesh="arm_r_5midph"></geom>
					<geom name="arm_r_5distph" type="mesh" mesh="arm_r_5distph"></geom>
					<site name="TRIlong-P5" pos="-0.0219 0.01046 -0.00078"></site>
					<site name="TRIlat-P5" pos="-0.0219 0.01046 -0.00078"></site>
					<site name="TRImed-P5" pos="-0.0219 0.01046 -0.00078"></site>
					<site name="BIClong-P9" pos="0.00751 -0.04839 0.02179"></site>
					<site name="BICshort-P6" pos="0.00751 -0.04839 0.02179"></site>
					<site name="BRA-P2" pos="-0.0032 -0.0239 0.0009"></site>
					<joint name="r_elbow_rotation1" type="hinge" pos="0 0 0" limited="false" axis="0.04940001 0.03660001 0.99810825" range="0.         2.26892803"></joint>
				</body>
			</body>
		</body>
	</worldbody>
	<asset>
		<mesh name="ground_ribs" file="Geometry/ground_ribs.stl" scale="1. 1. 1."></mesh>
		<mesh name="ground_spine" file="Geometry/ground_spine.stl" scale="1. 1. 1."></mesh>
		<mesh name="ground_skull" file="Geometry/ground_skull.stl" scale="1. 1. 1."></mesh>
		<mesh name="ground_jaw" file="Geometry/ground_jaw.stl" scale="1. 1. 1."></mesh>
		<mesh name="ground_r_clavicle" file="Geometry/ground_r_clavicle.stl" scale="1. 1. 1."></mesh>
		<mesh name="ground_r_scapula" file="Geometry/ground_r_scapula.stl" scale="1. 1. 1."></mesh>
		<mesh name="arm_r_humerus" file="Geometry/arm_r_humerus.stl" scale="1. 1. 1."></mesh>
		<mesh name="arm_r_ulna" file="Geometry/arm_r_ulna.stl" scale="1. 1. 1."></mesh>
		<mesh name="arm_r_radius" file="Geometry/arm_r_radius.stl" scale="1. 1. 1."></mesh>
		<mesh name="arm_r_lunate" file="Geometry/arm_r_lunate.stl" scale="1. 1. 1."></mesh>
		<mesh name="arm_r_scaphoid" file="Geometry/arm_r_scaphoid.stl" scale="1. 1. 1."></mesh>
		<mesh name="arm_r_pisiform" file="Geometry/arm_r_pisiform.stl" scale="1. 1. 1."></mesh>
		<mesh name="arm_r_triquetrum" file="Geometry/arm_r_triquetrum.stl" scale="1. 1. 1."></mesh>
		<mesh name="arm_r_capitate" file="Geometry/arm_r_capitate.stl" scale="1. 1. 1."></mesh>
		<mesh name="arm_r_trapezium" file="Geometry/arm_r_trapezium.stl" scale="1. 1. 1."></mesh>
		<mesh name="arm_r_trapezoid" file="Geometry/arm_r_trapezoid.stl" scale="1. 1. 1."></mesh>
		<mesh name="arm_r_hamate" file="Geometry/arm_r_hamate.stl" scale="1. 1. 1."></mesh>
		<mesh name="arm_r_1mc" file="Geometry/arm_r_1mc.stl" scale="1. 1. 1."></mesh>
		<mesh name="arm_r_2mc" file="Geometry/arm_r_2mc.stl" scale="1. 1. 1."></mesh>
		<mesh name="arm_r_3mc" file="Geometry/arm_r_3mc.stl" scale="1. 1. 1."></mesh>
		<mesh name="arm_r_4mc" file="Geometry/arm_r_4mc.stl" scale="1. 1. 1."></mesh>
		<mesh name="arm_r_5mc" file="Geometry/arm_r_5mc.stl" scale="1. 1. 1."></mesh>
		<mesh name="arm_r_thumbprox" file="Geometry/arm_r_thumbprox.stl" scale="1. 1. 1."></mesh>
		<mesh name="arm_r_thumbdist" file="Geometry/arm_r_thumbdist.stl" scale="1. 1. 1."></mesh>
		<mesh name="arm_r_2proxph" file="Geometry/arm_r_2proxph.stl" scale="1. 1. 1."></mesh>
		<mesh name="arm_r_2midph" file="Geometry/arm_r_2midph.stl" scale="1. 1. 1."></mesh>
		<mesh name="arm_r_2distph" file="Geometry/arm_r_2distph.stl" scale="1. 1. 1."></mesh>
		<mesh name="arm_r_3proxph" file="Geometry/arm_r_3proxph.stl" scale="1. 1. 1."></mesh>
		<mesh name="arm_r_3midph" file="Geometry/arm_r_3midph.stl" scale="1. 1. 1."></mesh>
		<mesh name="arm_r_3distph" file="Geometry/arm_r_3distph.stl" scale="1. 1. 1."></mesh>
		<mesh name="arm_r_4proxph" file="Geometry/arm_r_4proxph.stl" scale="1. 1. 1."></mesh>
		<mesh name="arm_r_4midph" file="Geometry/arm_r_4midph.stl" scale="1. 1. 1."></mesh>
		<mesh name="arm_r_4distph" file="Geometry/arm_r_4distph.stl" scale="1. 1. 1."></mesh>
		<mesh name="arm_r_5proxph" file="Geometry/arm_r_5proxph.stl" scale="1. 1. 1."></mesh>
		<mesh name="arm_r_5midph" file="Geometry/arm_r_5midph.stl" scale="1. 1. 1."></mesh>
		<mesh name="arm_r_5distph" file="Geometry/arm_r_5distph.stl" scale="1. 1. 1."></mesh>
		<texture name="texplane" type="2d" builtin="checker" rgb1=".2 .3 .4" rgb2=".1 0.15 0.2" width="100" height="100"></texture>
		<texture name="texgeom" type="cube" builtin="flat" mark="cross" width="127" height="1278" rgb1="0.8 0.6 0.4" rgb2="0.8 0.6 0.4" markrgb="1 1 1" random="0.01"></texture>
		<material name="MatPlane" reflectance="0.5" texture="texplane" texrepeat="1 1" texuniform="true"></material>
		<material name="geom" texture="texgeom" texuniform="true"></material>
	</asset>
	<tendon>
		<spatial name="TRIlong_tendon" width="0.004" rgba=".95 .3 .3 1" limited="false">
			<site site="TRIlong-P1"></site>
			<site site="TRIlong-P2"></site>
			<site site="TRIlong-P3"></site>
			<site site="TRIlong-P4"></site>
			<site site="TRIlong-P5"></site>
		</spatial>
		<spatial name="TRIlat_tendon" width="0.004" rgba=".95 .3 .3 1" limited="false">
			<site site="TRIlat-P1"></site>
			<site site="TRIlat-P2"></site>
			<site site="TRIlat-P3"></site>
			<site site="TRIlat-P4"></site>
			<site site="TRIlat-P5"></site>
		</spatial>
		<spatial name="TRImed_tendon" width="0.004" rgba=".95 .3 .3 1" limited="false">
			<site site="TRImed-P1"></site>
			<site site="TRImed-P2"></site>
			<site site="TRImed-P3"></site>
			<site site="TRImed-P4"></site>
			<site site="TRImed-P5"></site>
		</spatial>
		<spatial name="BIClong_tendon" width="0.004" rgba=".95 .3 .3 1" limited="false">
			<site site="BIClong-P1"></site>
			<site site="BIClong-P2"></site>
			<site site="BIClong-P3"></site>
			<site site="BIClong-P4"></site>
			<site site="BIClong-P5"></site>
			<site site="BIClong-P6"></site>
			<site site="BIClong-P7"></site>
			<site site="BIClong-P8"></site>
			<site site="BIClong-P9"></site>
		</spatial>
		<spatial name="BICshort_tendon" width="0.004" rgba=".95 .3 .3 1" limited="false">
			<site site="BICshort-P1"></site>
			<site site="BICshort-P2"></site>
			<site site="BICshort-P3"></site>
			<site site="BICshort-P4"></site>
			<site site="BICshort-P5"></site>
			<site site="BICshort-P6"></site>
		</spatial>
		<spatial name="BRA_tendon" width="0.004" rgba=".95 .3 .3 1" limited="false">
			<site site="BRA-P1"></site>
			<site site="BRA-P2"></site>
		</spatial>
	</tendon>
	<actuator>
		<muscle name="TRIlong_muscle" tendon="TRIlong_tendon" timeconst="0.01 0.04"></muscle>
		<muscle name="TRIlat_muscle" tendon="TRIlat_tendon" timeconst="0.01 0.04"></muscle>
		<muscle name="TRImed_muscle" tendon="TRImed_tendon" timeconst="0.01 0.04"></muscle>
		<muscle name="BIClong_muscle" tendon="BIClong_tendon" timeconst="0.01 0.04"></muscle>
		<muscle name="BICshort_muscle" tendon="BICshort_tendon" timeconst="0.01 0.04"></muscle>
		<muscle name="BRA_muscle" tendon="BRA_tendon" timeconst="0.01 0.04"></muscle>
	</actuator>
</mujoco>
