<?xml version="1.0" encoding="utf-8"?>
<mujoco model="subject_scale_run">
  <compiler inertiafromgeom="auto" angle="radian" balanceinertia="true" boundmass="0.001" boundinertia="0.001">
    <lengthrange inttotal="50" useexisting="true"></lengthrange>
  </compiler>
  <default>
    <joint limited="true" damping="0.5" armature="0.1" stiffness="2"></joint>
    <geom rgba="0.8 0.6 .4 1" margin="0.001"></geom>
    <site size="0.001"></site>
    <tendon width="0.001" rgba=".95 .3 .3 1" limited="false"></tendon>
    <default class="muscle">
      <muscle ctrllimited="true" ctrlrange="0 1" scale="200"></muscle>
    </default>
    <default class="motor">
      <general gainprm="5 0 0 0 0 0 0 0 0 0"></general>
    </default>
  </default>
  <option timestep="0.002"></option>
  <size njmax="1000" nconmax="400" nuser_jnt="1"></size>
  <worldbody>
    <geom name="floor" pos="0 0 0" size="10 10 0.125" type="plane" material="MatPlane" condim="3"></geom>
    <body name="pelvis" pos="       0 6.73556e-17      1.1" quat="0.7071067811865475 0.7071067811865475 0.0 0.0">
      <light mode="trackcom" directional="false" pos="0 0 4.0" dir="0 0 -1"></light>
      <geom name="r_pelvis" type="mesh" mesh="r_pelvis"></geom>
      <geom name="l_pelvis" type="mesh" mesh="l_pelvis"></geom>
      <geom name="sacrum" type="mesh" mesh="sacrum"></geom>
      <inertial pos="-0.0699009        0        0" mass="11.3866583484875" fullinertia="0.118815 0.118815 0.0564256        0        0        0"></inertial>
      <site name="addbrev_r-P1" pos="-0.0188841 -0.0958299 0.0173473"></site>
      <site name="addlong_r-P1" pos="-0.00749432 -0.0906306 0.0212674"></site>
      <site name="addmagDist_r-P1" pos="-0.0732031 -0.130155 0.0448553"></site>
      <site name="addmagIsch_r-P1" pos="-0.088607 -0.132286 0.0469843"></site>
      <site name="addmagMid_r-P1" pos="-0.0520648 -0.123101 0.0321489"></site>
      <site name="addmagProx_r-P1" pos="-0.0306298 -0.109644 0.0153761"></site>
      <site name="bflh_r-P1" pos="-0.102824 -0.121419 0.06601"></site>
      <site name="glmax1_r-P1" pos="-0.121709 0.0351716 0.0634192"></site>
      <site name="glmax1_r-P2" pos="-0.124279 -0.0246711 0.0877505"></site>
      <site name="glmax2_r-P1" pos="-0.130211 0.00886936 0.052042"></site>
      <site name="glmax2_r-P2" pos="-0.132881 -0.0620856 0.0915804"></site>
      <site name="glmax3_r-P1" pos="-0.128531 -0.053522 0.0101381"></site>
      <site name="glmax3_r-P2" pos="-0.125861 -0.128759 0.0490006"></site>
      <site name="glmed1_r-P1" pos="-0.043997 0.0249769 0.13202"></site>
      <site name="glmed2_r-P1" pos="-0.0840392 0.0322152 0.0760354"></site>
      <site name="glmed3_r-P1" pos="-0.113898 -0.00744211 0.0592513"></site>
      <site name="glmin1_r-P1" pos="-0.0458755 -0.0151901 0.117376"></site>
      <site name="glmin2_r-P1" pos="-0.0609037 -0.0144764 0.109378"></site>
      <site name="glmin3_r-P1" pos="-0.0780082 -0.0158017 0.0898908"></site>
      <site name="grac_r-P1" pos="-0.0468247 -0.131837 0.0276656"></site>
      <site name="iliacus_r-P1" pos="-0.0598162 0.0315015 0.0949598"></site>
      <site name="iliacus_r-P2" pos="-0.0133474 -0.0567843 0.0851597"></site>
      <site name="piri_r-P1" pos="-0.100659 -0.00665712 0.0152183"></site>
      <site name="piri_r-P2" pos="-0.100867 -0.0312569 0.0686234"></site>
      <site name="psoas_r-P1" pos="-0.059915 0.063207 0.0439316"></site>
      <site name="psoas_r-P2" pos="-0.0202683 -0.0666732 0.0738952"></site>
      <site name="recfem_r-P1" pos="-0.0237287 -0.0395553 0.105098"></site>
      <site name="sart_r-P1" pos="-0.0192796 -0.0159037 0.118953"></site>
      <site name="semimem_r-P1" pos="-0.0975844 -0.116219 0.0691641"></site>
      <site name="semiten_r-P1" pos="-0.102627 -0.127739 0.0580122"></site>
      <site name="tfl_r-P1" pos="-0.0307485 0.0218166 0.139793"></site>
      <site name="addbrev_l-P1" pos="-0.0188841 -0.0958299 -0.0173473"></site>
      <site name="addlong_l-P1" pos="-0.00749432 -0.0906306 -0.0212674"></site>
      <site name="addmagDist_l-P1" pos="-0.0732031 -0.130155 -0.0448553"></site>
      <site name="addmagIsch_l-P1" pos="-0.088607 -0.132286 -0.0469843"></site>
      <site name="addmagMid_l-P1" pos="-0.0520648 -0.123101 -0.0321489"></site>
      <site name="addmagProx_l-P1" pos="-0.0306298 -0.109644 -0.0153761"></site>
      <site name="bflh_l-P1" pos="-0.102824 -0.121419 -0.06601"></site>
      <site name="glmax1_l-P1" pos="-0.121709 0.0351716 -0.0634192"></site>
      <site name="glmax1_l-P2" pos="-0.124279 -0.0246711 -0.0877505"></site>
      <site name="glmax2_l-P1" pos="-0.130211 0.00886936 -0.052042"></site>
      <site name="glmax2_l-P2" pos="-0.132881 -0.0620856 -0.0915804"></site>
      <site name="glmax3_l-P1" pos="-0.128531 -0.053522 -0.0101381"></site>
      <site name="glmax3_l-P2" pos="-0.125861 -0.128759 -0.0490006"></site>
      <site name="glmed1_l-P1" pos="-0.043997 0.0249769 -0.13202"></site>
      <site name="glmed2_l-P1" pos="-0.0840392 0.0322152 -0.0760354"></site>
      <site name="glmed3_l-P1" pos="-0.113898 -0.00744211 -0.0592513"></site>
      <site name="glmin1_l-P1" pos="-0.0458755 -0.0151901 -0.117376"></site>
      <site name="glmin2_l-P1" pos="-0.0609037 -0.0144764 -0.109378"></site>
      <site name="glmin3_l-P1" pos="-0.0780082 -0.0158017 -0.0898908"></site>
      <site name="grac_l-P1" pos="-0.0468247 -0.131837 -0.0276656"></site>
      <site name="iliacus_l-P1" pos="-0.0598162 0.0315015 -0.0949598"></site>
      <site name="iliacus_l-P2" pos="-0.0133474 -0.0567843 -0.0851597"></site>
      <site name="piri_l-P1" pos="-0.100659 -0.00665712 -0.0152183"></site>
      <site name="piri_l-P2" pos="-0.100867 -0.0312569 -0.0686234"></site>
      <site name="psoas_l-P1" pos="-0.059915 0.063207 -0.0439316"></site>
      <site name="psoas_l-P2" pos="-0.0202683 -0.0666732 -0.0738952"></site>
      <site name="recfem_l-P1" pos="-0.0237287 -0.0395553 -0.105098"></site>
      <site name="sart_l-P1" pos="-0.0192796 -0.0159037 -0.118953"></site>
      <site name="semimem_l-P1" pos="-0.0975844 -0.116219 -0.0691641"></site>
      <site name="semiten_l-P1" pos="-0.102627 -0.127739 -0.0580122"></site>
      <site name="tfl_l-P1" pos="-0.0307485 0.0218166 -0.139793"></site>
      <joint name="pelvis_tz" type="slide" pos="0 0 0" axis="       0        0        1" limited="true" range="      -3        3" ref="0" armature="0" damping="0" stiffness="0"></joint>
      <joint name="pelvis_ty" type="slide" pos="0 0 0" axis="       0        1        0" limited="true" range="      -1        2" ref="0" armature="0" damping="0" stiffness="0"></joint>
      <joint name="pelvis_tx" type="slide" pos="0 0 0" axis="       1        0        0" limited="true" range="      -5        5" ref="0" armature="0" damping="0" stiffness="0"></joint>
      <joint name="pelvis_tilt" type="hinge" pos="0 0 0" axis="       0        0        1" limited="true" range=" -1.5708   1.5708" ref="0" armature="0" damping="0" stiffness="0"></joint>
      <joint name="pelvis_list" type="hinge" pos="0 0 0" axis="       1        0        0" limited="true" range=" -1.5708   1.5708" ref="0" armature="0" damping="0" stiffness="0"></joint>
      <joint name="pelvis_rotation" type="hinge" pos="0 0 0" axis="       0        1        0" limited="true" range=" -1.5708   1.5708" ref="0" armature="0" damping="0" stiffness="0"></joint>
      <body name="femur_r" pos="-0.0556399 -0.080018 0.0870296" quat="1.0 0.0 0.0 0.0">
        <geom name="r_femur" type="mesh" mesh="r_femur"></geom>
        <inertial pos="       0 -0.188514        0" mass="8.99311063620797" fullinertia="0.159195 0.0417308 0.167874        0        0        0"></inertial>
        <site name="addbrev_r-P2" pos="-0.00221781 -0.130851 0.0276117"></site>
        <site name="addlong_r-P2" pos="0.0124863 -0.265438 0.017554"></site>
        <site name="addmagDist_r-P2" pos="0.0124752 -0.291087 0.0214019"></site>
        <site name="addmagIsch_r-P2" pos="0.00533383 -0.430222 -0.0362944"></site>
        <site name="addmagMid_r-P2" pos="0.00268355 -0.180086 0.0324022"></site>
        <site name="addmagProx_r-P2" pos="-0.016933 -0.0874482 0.0355071"></site>
        <site name="bfsh_r-P1" pos="0.00554452 -0.23409 0.0259484"></site>
        <site name="gaslat_r-P1" pos="-0.00332671 -0.422936 0.0307167"></site>
        <site name="gasmed_r-P1" pos="0.00887124 -0.420053 -0.0230652"></site>
        <site name="glmax1_r-P3" pos="-0.0492354 -0.0361503 0.0334889"></site>
        <site name="glmax1_r-P4" pos="-0.0307167 -0.062764 0.0521185"></site>
        <site name="glmax2_r-P3" pos="-0.0499007 -0.06476 0.0279444"></site>
        <site name="glmax2_r-P4" pos="-0.0172989 -0.112665 0.0464631"></site>
        <site name="glmax3_r-P3" pos="-0.0311602 -0.124752 0.0104237"></site>
        <site name="glmax3_r-P4" pos="-0.00665343 -0.157354 0.045576"></site>
        <site name="glmed1_r-P2" pos="-0.0241741 -0.0129742 0.0615442"></site>
        <site name="glmed2_r-P2" pos="-0.0286097 -0.00643165 0.0584393"></site>
        <site name="glmed3_r-P2" pos="-0.0342651 -0.00521185 0.0574413"></site>
        <site name="glmin1_r-P2" pos="-0.00798411 -0.0115326 0.0620987"></site>
        <site name="glmin2_r-P2" pos="-0.0106455 -0.0115326 0.0620987"></site>
        <site name="glmin3_r-P2" pos="-0.0149702 -0.00920391 0.0609897"></site>
        <site name="iliacus_r-P3" pos="-0.00255048 -0.0626531 0.0154138"></site>
        <site name="iliacus_r-P4" pos="-0.0135286 -0.0706372 0.0217345"></site>
        <site name="piri_r-P3" pos="-0.0164118 -0.00399206 0.0484591"></site>
        <site name="psoas_r-P3" pos="-0.0146375 -0.0517858 0.00510096"></site>
        <site name="psoas_r-P4" pos="-0.0260593 -0.0581066 0.00975836"></site>
        <site name="sart_r-P2" pos="-0.00332671 -0.395657 -0.0466849"></site>
        <site name="tfl_r-P2" pos="0.0326018 -0.110336 0.0662016"></site>
        <site name="tfl_r-P3" pos="0.0118653 -0.449106 0.0359285"></site>
        <site name="vasint_r-P1" pos="0.0321582 -0.213353 0.034376"></site>
        <site name="vasint_r-P2" pos="0.0371483 -0.231096 0.0316038"></site>
        <site name="vaslat_r-P1" pos="0.00532274 -0.205591 0.0387008"></site>
        <site name="vaslat_r-P2" pos="0.0298295 -0.287317 0.0453542"></site>
        <site name="vasmed_r-P1" pos="0.0155247 -0.232759 0.0208474"></site>
        <site name="vasmed_r-P2" pos="0.039477 -0.307056 0.000998014"></site>
        <joint name="hip_flexion_r" type="hinge" pos="0 0 0" axis="       0        0        1" limited="true" range="-0.523599   2.0944" ref="0"></joint>
        <joint name="hip_adduction_r" type="hinge" pos="0 0 0" axis="       1        0        0" limited="true" range="-0.872665 0.523599" ref="0"></joint>
        <joint name="hip_rotation_r" type="hinge" pos="0 0 0" axis="       0        1        0" limited="true" range="-0.698132 0.698132" ref="0"></joint>
        <body name="tibia_r" pos="-0.000255263 -0.44858 -0.00144981" quat="1.0 7.240636975890137e-18 -9.456205735995121e-17 -2.960068750797159e-20">
          <geom name="r_tibia" type="mesh" mesh="r_tibia"></geom>
          <geom name="r_fibula" type="mesh" mesh="r_fibula"></geom>
          <inertial pos="       0 -0.201153        0" mass="3.58461712040564" fullinertia="0.0565661 0.00572395 0.0573518        0        0        0"></inertial>
          <site name="bflh_r-P2" pos="-0.0363088 -0.0377095 0.0272585"></site>
          <site name="bflh_r-P3" pos="-0.0309217 -0.0490223 0.0326456"></site>
          <site name="bfsh_r-P2" pos="-0.0324301 -0.0451436 0.0342617"></site>
          <site name="edl_r-P1" pos="-0.0172386 -0.124657 0.022087"></site>
          <site name="edl_r-P2" pos="0.0176696 -0.405107 0.012067"></site>
          <site name="ehl_r-P1" pos="-0.0150838 -0.166999 0.0203631"></site>
          <site name="ehl_r-P2" pos="0.00764963 -0.313419 0.0176696"></site>
          <site name="ehl_r-P3" pos="0.0215483 -0.397889 -0.00301676"></site>
          <site name="fdl_r-P1" pos="-0.00247805 -0.197382 -0.00193934"></site>
          <site name="fdl_r-P2" pos="-0.0189625 -0.392717 -0.0133599"></site>
          <site name="fhl_r-P1" pos="-0.0333998 -0.233044 0.0215483"></site>
          <site name="fhl_r-P2" pos="-0.0260734 -0.395518 -0.00818834"></site>
          <site name="grac_r-P2" pos="-0.0198459 -0.051231 -0.0319022"></site>
          <site name="grac_r-P3" pos="0.00191779 -0.0750095 -0.0169477"></site>
          <site name="perbrev_r-P1" pos="-0.0261811 -0.272801 0.0270431"></site>
          <site name="perbrev_r-P2" pos="-0.0365243 -0.419437 0.0268276"></site>
          <site name="perbrev_r-P3" pos="-0.0307063 -0.431396 0.027474"></site>
          <site name="perlong_r-P1" pos="-0.0215483 -0.147929 0.030383"></site>
          <site name="perlong_r-P2" pos="-0.034154 -0.420191 0.0255347"></site>
          <site name="perlong_r-P3" pos="-0.0293056 -0.432474 0.0258579"></site>
          <site name="recfem_r-P5" pos="0.0351237 -0.0680063 -0.000506384"></site>
          <site name="sart_r-P3" pos="-0.0270431 -0.0432043 -0.0393256"></site>
          <site name="sart_r-P4" pos="-0.0171309 -0.064537 -0.0284437"></site>
          <site name="sart_r-P5" pos="0.0146528 -0.0872704 -0.00280127"></site>
          <site name="semimem_r-P2" pos="-0.031245 -0.0449281 -0.0211173"></site>
          <site name="semiten_r-P2" pos="-0.0336153 -0.0547326 -0.0246728"></site>
          <site name="semiten_r-P3" pos="0.00204708 -0.083284 -0.0126057"></site>
          <site name="soleus_r-P1" pos="-0.00818834 -0.098691 0.0105586"></site>
          <site name="tfl_r-P4" pos="0.0116361 -0.0441739 0.0372785"></site>
          <site name="tibant_r-P1" pos="0.0165922 -0.141357 0.0174541"></site>
          <site name="tibant_r-P2" pos="0.0270431 -0.205355 0.0137909"></site>
          <site name="tibant_r-P3" pos="0.0251037 -0.394225 -0.0142219"></site>
          <site name="tibpost_r-P1" pos="-0.00441739 -0.140495 0.0110974"></site>
          <site name="tibpost_r-P2" pos="-0.0176696 -0.393794 -0.0188547"></site>
          <site name="vasint_r-P5" pos="0.0350913 -0.0680925 0.000463288"></site>
          <site name="vaslat_r-P5" pos="0.035059 -0.0682864 0.00550558"></site>
          <site name="vasmed_r-P5" pos="0.0343695 -0.0684911 -0.00730486"></site>
          <joint name="knee_angle_r_translation2" type="slide" pos="0 0 0" axis="0.992246 0.123982 -0.00878916" limited="true" range="7.69254e-11 0.006792" ref="0"></joint>
          <joint name="knee_angle_r_translation1" type="slide" pos="0 0 0" axis="-0.124293 0.989762 -0.0701648" limited="true" range="9.53733e-08 0.00159883" ref="0"></joint>
          <joint name="knee_angle_r" type="hinge" pos="0 0 0" axis="-3.98373e-10 -0.0707131 -0.997497" limited="true" range="       0   2.0944" ref="0"></joint>
          <joint name="knee_angle_r_rotation2" type="hinge" pos="0 0 0" axis="0.992246 0.123982 -0.00878916" limited="true" range="-0.00167821 0.0335354" ref="0"></joint>
          <joint name="knee_angle_r_rotation3" type="hinge" pos="0 0 0" axis="-0.124293 0.989762 -0.0701648" limited="true" range="1.08939e-08 0.262788" ref="0"></joint>
          <body name="talus_r" pos="-0.0107741 -0.430965        0" quat="1.0 -6.036754011562992e-18 1.5193252867388614e-18 -2.498419531737724e-19">
            <geom name="r_talus" type="mesh" mesh="r_talus"></geom>
            <inertial pos="       0        0        0" mass="0.0966855595524112" fullinertia="0.00120867 0.00120867 0.00120867        0        0        0"></inertial>
            <joint name="ankle_angle_r" type="hinge" pos="0 0 0" axis="-0.105014 -0.174022 0.979126" limited="true" range="-0.698132 0.523599" ref="0"></joint>
            <body name="calcn_r" pos="-0.0545288 -0.0469035 0.0088552" quat="1.0 -5.320429553087796e-19 1.609289071159989e-17 -2.1848634538867752e-17">
              <geom name="r_foot" type="mesh" mesh="r_foot"></geom>
              <inertial pos="0.111808 0.0335424        0" mass="1.20856949440514" fullinertia="0.00169214 0.00471381 0.00495555        0        0        0"></inertial>
              <site name="edl_r-P3" pos="0.102752 0.0402509 0.000894464"></site>
              <site name="edl_r-P4" pos="0.180682 0.00614944 0.014535"></site>
              <site name="ehl_r-P4" pos="0.108454 0.0434933 -0.0235915"></site>
              <site name="ehl_r-P5" pos="0.144568 0.0345487 -0.0287347"></site>
              <site name="ehl_r-P6" pos="0.193875 0.0155413 -0.0313063"></site>
              <site name="fdl_r-P3" pos="0.0487483 0.0352195 -0.0313063"></site>
              <site name="fdl_r-P4" pos="0.0791601 0.0196782 -0.0294055"></site>
              <site name="fdl_r-P5" pos="0.185378 -0.00905645 0.0129697"></site>
              <site name="fhl_r-P3" pos="0.0418162 0.030859 -0.0269457"></site>
              <site name="fhl_r-P4" pos="0.116057 0.00760295 -0.0286229"></site>
              <site name="fhl_r-P5" pos="0.192981 -0.00592583 -0.0300764"></site>
              <site name="gaslat_r-P2" pos="0.00491955 0.0346605 -0.00592583"></site>
              <site name="gasmed_r-P2" pos="0.00491955 0.0346605 -0.00592583"></site>
              <site name="perbrev_r-P4" pos="0.0526616 0.0301882 0.0260513"></site>
              <site name="perbrev_r-P5" pos="0.075694 0.024486 0.0383502"></site>
              <site name="perlong_r-P4" pos="0.0489719 0.0257158 0.0247096"></site>
              <site name="perlong_r-P5" pos="0.0761413 0.0118517 0.0317535"></site>
              <site name="perlong_r-P6" pos="0.0952605 0.00771475 0.0131933"></site>
              <site name="perlong_r-P7" pos="0.134505 0.00950368 -0.0205727"></site>
              <site name="soleus_r-P2" pos="0.00491955 0.0346605 -0.00592583"></site>
              <site name="tibant_r-P4" pos="0.130368 0.0199018 -0.0341015"></site>
              <site name="tibpost_r-P3" pos="0.046624 0.0373439 -0.0319771"></site>
              <site name="tibpost_r-P4" pos="0.0863158 0.0177775 -0.0314181"></site>
              <joint name="subtalar_angle_r" type="hinge" pos="0 0 0" axis=" 0.78718 0.604747 -0.120949" limited="true" range="-0.349066 0.349066" ref="0"></joint>
              <body name="toes_r" pos="0.199913 -0.00223616 0.00120753" quat="1.0 1.314867274624753e-31 -2.6810890689525335e-17 -3.939849802505862e-32">
                <geom name="r_bofoot" type="mesh" mesh="r_bofoot"></geom>
                <inertial pos="0.0386856 0.00670848 -0.0195664" mass="0.209420921990523" fullinertia="0.000120867 0.000241734 0.00120867        0        0        0"></inertial>
                <site name="edl_r-P5" pos="0.000335424 0.00525498 0.0171066"></site>
                <site name="edl_r-P6" pos="0.049531 -0.000447232 0.027952"></site>
                <site name="ehl_r-P7" pos="0.0333188 0.00458413 -0.027393"></site>
                <site name="ehl_r-P8" pos="0.0629479 0.00380147 -0.0207963"></site>
                <site name="fdl_r-P6" pos="-0.00212435 -0.00872103 0.0164358"></site>
                <site name="fdl_r-P7" pos="0.0318653 -0.00793837 0.0240387"></site>
                <site name="fdl_r-P8" pos="0.0493073 -0.00670848 0.0270575"></site>
                <site name="fhl_r-P6" pos="0.0173302 -0.00715571 -0.0296291"></site>
                <site name="fhl_r-P7" pos="0.0628361 -0.0114044 -0.0202373"></site>
                <joint name="mtp_angle_r" type="hinge" pos="0 0 0" axis="0.580954 2.6299e-15 -0.813936" limited="true" range="-0.523599 0.523599" ref="0"></joint>
              </body>
            </body>
          </body>
        </body>
        <body name="patella_r" pos="-0.00897104 -0.452389 -0.000299487" quat="1.0 0.0 0.0 0.0">
          <geom name="r_patella" type="mesh" mesh="r_patella"></geom>
          <inertial pos="  0.0018   0.0264        0" mass="0.0833429523341784" fullinertia="2.77488e-06 1.26755e-05 1.26755e-05        0        0        0"></inertial>
          <site name="recfem_r-P2" pos="0.01 0.049 0.0007"></site>
          <site name="recfem_r-P3" pos="0.0121 0.0437 -0.001"></site>
          <site name="recfem_r-P4" pos="0.005 0.00247 3e-005"></site>
          <site name="vasint_r-P3" pos="0.0058 0.048 -0.0006"></site>
          <site name="vasint_r-P4" pos="0.005 0.00247 -0.00039"></site>
          <site name="vaslat_r-P3" pos="0.0103 0.0423 0.0141"></site>
          <site name="vaslat_r-P4" pos="0.005 0.00247 0.00733"></site>
          <site name="vasmed_r-P3" pos="0.0063 0.0445 -0.017"></site>
          <site name="vasmed_r-P4" pos="0.005 0.00247 -0.0085"></site>
          <joint name="knee_angle_r_beta_translation2" type="slide" pos="0 0 0" axis="       0        1        0" limited="true" range="-0.0408267 -0.0108281" ref="0"></joint>
          <joint name="knee_angle_r_beta_translation1" type="slide" pos="0 0 0" axis="       1        0        0" limited="true" range="-0.0227731 0.0524192" ref="0"></joint>
          <joint name="knee_angle_r_beta_rotation1" type="hinge" pos="0 0 0" axis="       0        0        1" limited="true" range="-1.79241 0.010506" ref="0"></joint>
        </body>
      </body>
      <body name="femur_l" pos="-0.0556399 -0.080018 -0.0870296" quat="1.0 0.0 0.0 0.0">
        <geom name="l_femur" type="mesh" mesh="l_femur"></geom>
        <inertial pos="       0 -0.188514        0" mass="8.99311063620797" fullinertia="0.159195 0.0417308 0.167874        0        0        0"></inertial>
        <site name="addbrev_l-P2" pos="-0.00221781 -0.130851 -0.0276117"></site>
        <site name="addlong_l-P2" pos="0.0124863 -0.265438 -0.017554"></site>
        <site name="addmagDist_l-P2" pos="0.0124752 -0.291087 -0.0214019"></site>
        <site name="addmagIsch_l-P2" pos="0.00533383 -0.430222 0.0362944"></site>
        <site name="addmagMid_l-P2" pos="0.00268355 -0.180086 -0.0324022"></site>
        <site name="addmagProx_l-P2" pos="-0.016933 -0.0874482 -0.0355071"></site>
        <site name="bfsh_l-P1" pos="0.00554452 -0.23409 -0.0259484"></site>
        <site name="gaslat_l-P1" pos="-0.00332671 -0.422936 -0.0307167"></site>
        <site name="gasmed_l-P1" pos="0.00887124 -0.420053 0.0230652"></site>
        <site name="glmax1_l-P3" pos="-0.0492354 -0.0361503 -0.0334889"></site>
        <site name="glmax1_l-P4" pos="-0.0307167 -0.062764 -0.0521185"></site>
        <site name="glmax2_l-P3" pos="-0.0499007 -0.06476 -0.0279444"></site>
        <site name="glmax2_l-P4" pos="-0.0172989 -0.112665 -0.0464631"></site>
        <site name="glmax3_l-P3" pos="-0.0311602 -0.124752 -0.0104237"></site>
        <site name="glmax3_l-P4" pos="-0.00665343 -0.157354 -0.045576"></site>
        <site name="glmed1_l-P2" pos="-0.0241741 -0.0129742 -0.0615442"></site>
        <site name="glmed2_l-P2" pos="-0.0286097 -0.00643165 -0.0584393"></site>
        <site name="glmed3_l-P2" pos="-0.0342651 -0.00521185 -0.0574413"></site>
        <site name="glmin1_l-P2" pos="-0.00798411 -0.0115326 -0.0620987"></site>
        <site name="glmin2_l-P2" pos="-0.0106455 -0.0115326 -0.0620987"></site>
        <site name="glmin3_l-P2" pos="-0.0149702 -0.00920391 -0.0609897"></site>
        <site name="iliacus_l-P3" pos="-0.00255048 -0.0626531 -0.0154138"></site>
        <site name="iliacus_l-P4" pos="-0.0135286 -0.0706372 -0.0217345"></site>
        <site name="piri_l-P3" pos="-0.0164118 -0.00399206 -0.0484591"></site>
        <site name="psoas_l-P3" pos="-0.0146375 -0.0517858 -0.00510096"></site>
        <site name="psoas_l-P4" pos="-0.0260593 -0.0581066 -0.00975836"></site>
        <site name="sart_l-P2" pos="-0.00332671 -0.395657 0.0466849"></site>
        <site name="tfl_l-P2" pos="0.0326018 -0.110336 -0.0662016"></site>
        <site name="tfl_l-P3" pos="0.0118653 -0.449106 -0.0359285"></site>
        <site name="vasint_l-P1" pos="0.0321582 -0.213353 -0.034376"></site>
        <site name="vasint_l-P2" pos="0.0371483 -0.231096 -0.0316038"></site>
        <site name="vaslat_l-P1" pos="0.00532274 -0.205591 -0.0387008"></site>
        <site name="vaslat_l-P2" pos="0.0298295 -0.287317 -0.0453542"></site>
        <site name="vasmed_l-P1" pos="0.0155247 -0.232759 -0.0208474"></site>
        <site name="vasmed_l-P2" pos="0.039477 -0.307056 -0.000998014"></site>
        <joint name="hip_flexion_l" type="hinge" pos="0 0 0" axis="       0        0        1" limited="true" range="-0.523599   2.0944" ref="0"></joint>
        <joint name="hip_adduction_l" type="hinge" pos="0 0 0" axis="      -1       -0       -0" limited="true" range="-0.872665 0.523599" ref="0"></joint>
        <joint name="hip_rotation_l" type="hinge" pos="0 0 0" axis="      -0       -1       -0" limited="true" range="-0.698132 0.698132" ref="0"></joint>
        <body name="tibia_l" pos="-0.000255263 -0.44858 0.00144981" quat="1.0 -7.240636975890137e-18 9.456205735995121e-17 -2.960068750797159e-20">
          <geom name="l_tibia" type="mesh" mesh="l_tibia"></geom>
          <geom name="l_fibula" type="mesh" mesh="l_fibula"></geom>
          <inertial pos="       0 -0.201153        0" mass="3.58461712040564" fullinertia="0.0565661 0.00572395 0.0573518        0        0        0"></inertial>
          <site name="bflh_l-P2" pos="-0.0363088 -0.0377095 -0.0272585"></site>
          <site name="bflh_l-P3" pos="-0.0309217 -0.0490223 -0.0326456"></site>
          <site name="bfsh_l-P2" pos="-0.0324301 -0.0451436 -0.0342617"></site>
          <site name="edl_l-P1" pos="-0.0172386 -0.124657 -0.022087"></site>
          <site name="edl_l-P2" pos="0.0176696 -0.405107 -0.012067"></site>
          <site name="ehl_l-P1" pos="-0.0150838 -0.166999 -0.0203631"></site>
          <site name="ehl_l-P2" pos="0.00764963 -0.313419 -0.0176696"></site>
          <site name="ehl_l-P3" pos="0.0215483 -0.397889 0.00301676"></site>
          <site name="fdl_l-P1" pos="-0.00247805 -0.197382 0.00193934"></site>
          <site name="fdl_l-P2" pos="-0.0189625 -0.392717 0.0133599"></site>
          <site name="fhl_l-P1" pos="-0.0333998 -0.233044 -0.0215483"></site>
          <site name="fhl_l-P2" pos="-0.0260734 -0.395518 0.00818834"></site>
          <site name="grac_l-P2" pos="-0.0198459 -0.051231 0.0319022"></site>
          <site name="grac_l-P3" pos="0.00191779 -0.0750095 0.0169477"></site>
          <site name="perbrev_l-P1" pos="-0.0261811 -0.272801 -0.0270431"></site>
          <site name="perbrev_l-P2" pos="-0.0365243 -0.419437 -0.0268276"></site>
          <site name="perbrev_l-P3" pos="-0.0307063 -0.431396 -0.027474"></site>
          <site name="perlong_l-P1" pos="-0.0215483 -0.147929 -0.030383"></site>
          <site name="perlong_l-P2" pos="-0.034154 -0.420191 -0.0255347"></site>
          <site name="perlong_l-P3" pos="-0.0293056 -0.432474 -0.0258579"></site>
          <site name="recfem_l-P5" pos="0.0351237 -0.0680063 0.000506384"></site>
          <site name="sart_l-P3" pos="-0.0270431 -0.0432043 0.0393256"></site>
          <site name="sart_l-P4" pos="-0.0171309 -0.064537 0.0284437"></site>
          <site name="sart_l-P5" pos="0.0146528 -0.0872704 0.00280127"></site>
          <site name="semimem_l-P2" pos="-0.031245 -0.0449281 0.0211173"></site>
          <site name="semiten_l-P2" pos="-0.0336153 -0.0547326 0.0246728"></site>
          <site name="semiten_l-P3" pos="0.00204708 -0.083284 0.0126057"></site>
          <site name="soleus_l-P1" pos="-0.00818834 -0.098691 -0.0105586"></site>
          <site name="tfl_l-P4" pos="0.0116361 -0.0441739 -0.0372785"></site>
          <site name="tibant_l-P1" pos="0.0165922 -0.141357 -0.0174541"></site>
          <site name="tibant_l-P2" pos="0.0270431 -0.205355 -0.0137909"></site>
          <site name="tibant_l-P3" pos="0.0251037 -0.394225 0.0142219"></site>
          <site name="tibpost_l-P1" pos="-0.00441739 -0.140495 -0.0110974"></site>
          <site name="tibpost_l-P2" pos="-0.0176696 -0.393794 0.0188547"></site>
          <site name="vasint_l-P5" pos="0.0350913 -0.0680925 -0.000463288"></site>
          <site name="vaslat_l-P5" pos="0.035059 -0.0682864 -0.00550558"></site>
          <site name="vasmed_l-P5" pos="0.0343695 -0.0684911 0.00730486"></site>
          <joint name="knee_angle_l_translation2" type="slide" pos="0 0 0" axis="-0.992246 -0.123982 -0.00878916" limited="true" range="-0.006792 -7.69254e-11" ref="0"></joint>
          <joint name="knee_angle_l_translation1" type="slide" pos="0 0 0" axis="-0.124293 0.989762 0.0701648" limited="true" range="9.53733e-08 0.00159883" ref="0"></joint>
          <joint name="knee_angle_l" type="hinge" pos="0 0 0" axis="3.98373e-10 0.0707131 -0.997497" limited="true" range="       0   2.0944" ref="0"></joint>
          <joint name="knee_angle_l_rotation2" type="hinge" pos="0 0 0" axis="-0.992246 -0.123982 -0.00878916" limited="true" range="-0.00167821 0.0335354" ref="0"></joint>
          <joint name="knee_angle_l_rotation3" type="hinge" pos="0 0 0" axis="-0.124293 0.989762 0.0701648" limited="true" range="-0.262788 -1.08939e-08" ref="0"></joint>
          <body name="talus_l" pos="-0.0107741 -0.430965        0" quat="1.0 6.036754011562992e-18 -1.5193252867388614e-18 -2.498419531737724e-19">
            <geom name="l_talus" type="mesh" mesh="l_talus"></geom>
            <inertial pos="       0        0        0" mass="0.0966855595524112" fullinertia="0.00120867 0.00120867 0.00120867        0        0        0"></inertial>
            <joint name="ankle_angle_l" type="hinge" pos="0 0 0" axis="0.105014 0.174022 0.979126" limited="true" range="-0.698132 0.523599" ref="0"></joint>
            <body name="calcn_l" pos="-0.0545288 -0.0469035 -0.0088552" quat="1.0 5.320429553087796e-19 -1.609289071159989e-17 -2.1848634538867752e-17">
              <geom name="l_foot" type="mesh" mesh="l_foot"></geom>
              <inertial pos="0.111808 0.0335424        0" mass="1.20856949440514" fullinertia="0.00169214 0.00471381 0.00495555        0        0        0"></inertial>
              <site name="edl_l-P3" pos="0.102752 0.0402509 -0.000894464"></site>
              <site name="edl_l-P4" pos="0.180682 0.00614944 -0.014535"></site>
              <site name="ehl_l-P4" pos="0.108454 0.0434933 0.0235915"></site>
              <site name="ehl_l-P5" pos="0.144568 0.0345487 0.0287347"></site>
              <site name="ehl_l-P6" pos="0.193875 0.0155413 0.0313063"></site>
              <site name="fdl_l-P3" pos="0.0487483 0.0352195 0.0313063"></site>
              <site name="fdl_l-P4" pos="0.0791601 0.0196782 0.0294055"></site>
              <site name="fdl_l-P5" pos="0.185378 -0.00905645 -0.0129697"></site>
              <site name="fhl_l-P3" pos="0.0418162 0.030859 0.0269457"></site>
              <site name="fhl_l-P4" pos="0.116057 0.00760295 0.0286229"></site>
              <site name="fhl_l-P5" pos="0.192981 -0.00592583 0.0300764"></site>
              <site name="gaslat_l-P2" pos="0.00491955 0.0346605 0.00592583"></site>
              <site name="gasmed_l-P2" pos="0.00491955 0.0346605 0.00592583"></site>
              <site name="perbrev_l-P4" pos="0.0526616 0.0301882 -0.0260513"></site>
              <site name="perbrev_l-P5" pos="0.075694 0.024486 -0.0383502"></site>
              <site name="perlong_l-P4" pos="0.0489719 0.0257158 -0.0247096"></site>
              <site name="perlong_l-P5" pos="0.0761413 0.0118517 -0.0317535"></site>
              <site name="perlong_l-P6" pos="0.0952605 0.00771475 -0.0131933"></site>
              <site name="perlong_l-P7" pos="0.134505 0.00950368 0.0205727"></site>
              <site name="soleus_l-P2" pos="0.00491955 0.0346605 0.00592583"></site>
              <site name="tibant_l-P4" pos="0.130368 0.0199018 0.0341015"></site>
              <site name="tibpost_l-P3" pos="0.046624 0.0373439 0.0319771"></site>
              <site name="tibpost_l-P4" pos="0.0863158 0.0177775 0.0314181"></site>
              <joint name="subtalar_angle_l" type="hinge" pos="0 0 0" axis="-0.78718 -0.604747 -0.120949" limited="true" range="-0.349066 0.349066" ref="0"></joint>
              <body name="toes_l" pos="0.199913 -0.00223616 -0.00120753" quat="1.0 1.314867274624753e-31 2.6810890689525335e-17 3.939849802505862e-32">
                <geom name="l_bofoot" type="mesh" mesh="l_bofoot"></geom>
                <inertial pos="0.0386856 0.00670848 0.0195664" mass="0.209420921990523" fullinertia="0.000120867 0.000241734 0.00120867        0        0        0"></inertial>
                <site name="edl_l-P5" pos="0.000335424 0.00525498 -0.0171066"></site>
                <site name="edl_l-P6" pos="0.049531 -0.000447232 -0.027952"></site>
                <site name="ehl_l-P7" pos="0.0333188 0.00458413 0.027393"></site>
                <site name="ehl_l-P8" pos="0.0629479 0.00380147 0.0207963"></site>
                <site name="fdl_l-P6" pos="-0.00212435 -0.00872103 -0.0164358"></site>
                <site name="fdl_l-P7" pos="0.0318653 -0.00793837 -0.0240387"></site>
                <site name="fdl_l-P8" pos="0.0493073 -0.00670848 -0.0270575"></site>
                <site name="fhl_l-P6" pos="0.0173302 -0.00715571 0.0296291"></site>
                <site name="fhl_l-P7" pos="0.0628361 -0.0114044 0.0202373"></site>
                <joint name="mtp_angle_l" type="hinge" pos="0 0 0" axis="-0.580954 2.6299e-15 -0.813936" limited="true" range="-0.523599 0.523599" ref="0"></joint>
              </body>
            </body>
          </body>
        </body>
        <body name="patella_l" pos="-0.00897104 -0.452389 0.000299487" quat="1.0 0.0 0.0 0.0">
          <geom name="l_patella" type="mesh" mesh="l_patella"></geom>
          <inertial pos="  0.0018   0.0264        0" mass="0.0833429523341784" fullinertia="2.77488e-06 1.26755e-05 1.26755e-05        0        0        0"></inertial>
          <site name="recfem_l-P2" pos="0.01 0.049 -0.0007"></site>
          <site name="recfem_l-P3" pos="0.0121 0.0437 0.001"></site>
          <site name="recfem_l-P4" pos="0.005 0.00247 -3e-005"></site>
          <site name="vasint_l-P3" pos="0.0058 0.048 0.0006"></site>
          <site name="vasint_l-P4" pos="0.005 0.00247 0.00039"></site>
          <site name="vaslat_l-P3" pos="0.0103 0.0423 -0.0141"></site>
          <site name="vaslat_l-P4" pos="0.005 0.00247 -0.00733"></site>
          <site name="vasmed_l-P3" pos="0.0063 0.0445 0.017"></site>
          <site name="vasmed_l-P4" pos="0.005 0.00247 0.0085"></site>
          <joint name="knee_angle_l_beta_translation2" type="slide" pos="0 0 0" axis="       0        1        0" limited="true" range="-0.0408267 -0.0108281" ref="0"></joint>
          <joint name="knee_angle_l_beta_translation1" type="slide" pos="0 0 0" axis="       1        0        0" limited="true" range="-0.0227731 0.0524192" ref="0"></joint>
          <joint name="knee_angle_l_beta_rotation1" type="hinge" pos="0 0 0" axis="       0        0        1" limited="true" range="-1.79241 0.010506" ref="0"></joint>
        </body>
      </body>
      <body name="torso" pos="-0.0995618 0.0830866        0" quat="1.0 0.0 0.0 0.0">
        <geom name="hat_spine" type="mesh" mesh="hat_spine"></geom>
        <geom name="hat_jaw" type="mesh" mesh="hat_jaw"></geom>
        <geom name="hat_skull" type="mesh" mesh="hat_skull"></geom>
        <geom name="hat_ribs_scap" type="mesh" mesh="hat_ribs_scap"></geom>
        <inertial pos="-0.0297446 0.317275        0" mass="25.9374483188871" fullinertia=" 1.40145 0.718073  1.36049        0        0        0"></inertial>
        <joint name="lumbar_extension" type="hinge" pos="0 0 0" axis="       0        0        1" limited="true" range=" -1.5708   1.5708" ref="0"></joint>
        <joint name="lumbar_bending" type="hinge" pos="0 0 0" axis="       1        0        0" limited="true" range=" -1.5708   1.5708" ref="0"></joint>
        <joint name="lumbar_rotation" type="hinge" pos="0 0 0" axis="       0        1        0" limited="true" range=" -1.5708   1.5708" ref="0"></joint>
        <body name="humerus_r" pos="0.00312814 0.368337 0.168553" quat="1.0 0.0 0.0 0.0">
          <geom name="humerus_rv" type="mesh" mesh="humerus_rv"></geom>
          <inertial pos="       0 -0.18191        0" mass="1.96513399790276" fullinertia="0.0141238 0.00487229 0.0158536        0        0        0"></inertial>
          <joint name="arm_flex_r" type="hinge" pos="0 0 0" axis="       0        0        1" limited="true" range=" -1.5708   1.5708" ref="0"></joint>
          <joint name="arm_add_r" type="hinge" pos="0 0 0" axis="       1        0        0" limited="true" range=" -2.0944   1.5708" ref="0"></joint>
          <joint name="arm_rot_r" type="hinge" pos="0 0 0" axis="       0        1        0" limited="true" range=" -1.5708   1.5708" ref="0"></joint>
          <body name="ulna_r" pos="0.0145349 -0.316566 -0.0106103" quat="1.0 1.6893809785063376e-18 -6.938893903907228e-18 4.155190089080778e-20">
            <geom name="ulna_rv" type="mesh" mesh="ulna_rv"></geom>
            <inertial pos="       0 -0.134201        0" mass="0.587364774280898" fullinertia="0.00355063 0.000740813 0.00385151        0        0        0"></inertial>
            <joint name="elbow_flex_r" type="hinge" pos="0 0 0" axis="0.226047 0.022269 0.973862" limited="true" range="       0    2.618" ref="0"></joint>
            <body name="radius_r" pos="-0.00749032 -0.0144829 0.0290427" quat="1.0 2.301201592641875e-21 -6.933378131686372e-19 1.7489241099837954e-19">
              <geom name="radius_rv" type="mesh" mesh="radius_rv"></geom>
              <inertial pos="       0 -0.134201        0" mass="0.587364774280898" fullinertia="0.00355063 0.000740813 0.00385151        0        0        0"></inertial>
              <joint name="pro_sup_r" type="hinge" pos="0 0 0" axis="0.056398 0.998406 0.001952" limited="true" range="       0   1.5708" ref="0"></joint>
              <body name="hand_r" pos="-0.00979521 -0.262602 0.0151543" quat="1.0 0.0 8.407790785948892e-45 0.0">
                <geom name="pisiform_rvs" type="mesh" mesh="pisiform_rvs"></geom>
                <geom name="lunate_rvs" type="mesh" mesh="lunate_rvs"></geom>
                <geom name="scaphoid_rvs" type="mesh" mesh="scaphoid_rvs"></geom>
                <geom name="triquetrum_rvs" type="mesh" mesh="triquetrum_rvs"></geom>
                <geom name="hamate_rvs" type="mesh" mesh="hamate_rvs"></geom>
                <geom name="capitate_rvs" type="mesh" mesh="capitate_rvs"></geom>
                <geom name="trapezoid_rvs" type="mesh" mesh="trapezoid_rvs"></geom>
                <geom name="trapezium_rvs" type="mesh" mesh="trapezium_rvs"></geom>
                <geom name="metacarpal2_rvs" type="mesh" mesh="metacarpal2_rvs"></geom>
                <geom name="index_proximal_rvs" type="mesh" mesh="index_proximal_rvs"></geom>
                <geom name="index_medial_rvs" type="mesh" mesh="index_medial_rvs"></geom>
                <geom name="index_distal_rvs" type="mesh" mesh="index_distal_rvs"></geom>
                <geom name="metacarpal3_rvs" type="mesh" mesh="metacarpal3_rvs"></geom>
                <geom name="middle_proximal_rvs" type="mesh" mesh="middle_proximal_rvs"></geom>
                <geom name="middle_medial_rvs" type="mesh" mesh="middle_medial_rvs"></geom>
                <geom name="middle_distal_rvs" type="mesh" mesh="middle_distal_rvs"></geom>
                <geom name="metacarpal4_rvs" type="mesh" mesh="metacarpal4_rvs"></geom>
                <geom name="ring_proximal_rvs" type="mesh" mesh="ring_proximal_rvs"></geom>
                <geom name="ring_medial_rvs" type="mesh" mesh="ring_medial_rvs"></geom>
                <geom name="ring_distal_rvs" type="mesh" mesh="ring_distal_rvs"></geom>
                <geom name="metacarpal5_rvs" type="mesh" mesh="metacarpal5_rvs"></geom>
                <geom name="little_proximal_rvs" type="mesh" mesh="little_proximal_rvs"></geom>
                <geom name="little_medial_rvs" type="mesh" mesh="little_medial_rvs"></geom>
                <geom name="little_distal_rvs" type="mesh" mesh="little_distal_rvs"></geom>
                <geom name="metacarpal1_rvs" type="mesh" mesh="metacarpal1_rvs"></geom>
                <geom name="thumb_proximal_rvs" type="mesh" mesh="thumb_proximal_rvs"></geom>
                <geom name="thumb_distal_rvs" type="mesh" mesh="thumb_distal_rvs"></geom>
                <inertial pos="       0 -0.0758218        0" mass="0.442336434952281" fullinertia="0.00106926 0.000655703 0.00160629        0        0        0"></inertial>
                <joint name="wrist_flex_r" type="hinge" pos="0 0 0" axis="-3.55271e-15 3.55271e-15        1" limited="true" range="-1.22173  1.22173" ref="0"></joint>
                <joint name="wrist_dev_r" type="hinge" pos="0 0 0" axis="       1        0 3.55271e-15" limited="true" range="-0.436332 0.610865" ref="0"></joint>
              </body>
            </body>
          </body>
        </body>
        <body name="humerus_l" pos="0.00312814 0.368337 -0.168553" quat="1.0 0.0 0.0 0.0">
          <geom name="humerus_lv" type="mesh" mesh="humerus_lv"></geom>
          <inertial pos="       0 -0.18191        0" mass="1.96513399790276" fullinertia="0.0141238 0.00487229 0.0158536        0        0        0"></inertial>
          <joint name="arm_flex_l" type="hinge" pos="0 0 0" axis="       0        0        1" limited="true" range=" -1.5708   1.5708" ref="0"></joint>
          <joint name="arm_add_l" type="hinge" pos="0 0 0" axis="      -1        0        0" limited="true" range=" -2.0944   1.5708" ref="0"></joint>
          <joint name="arm_rot_l" type="hinge" pos="0 0 0" axis="       0       -1        0" limited="true" range=" -1.5708   1.5708" ref="0"></joint>
          <body name="ulna_l" pos="0.0145349 -0.316566 0.0106103" quat="1.0 -1.6893809785063376e-18 6.938893903907228e-18 4.155190089080778e-20">
            <geom name="ulna_lv" type="mesh" mesh="ulna_lv"></geom>
            <inertial pos="       0 -0.134201        0" mass="0.587364774280898" fullinertia="0.00355063 0.000740813 0.00385151        0        0        0"></inertial>
            <joint name="elbow_flex_l" type="hinge" pos="0 0 0" axis="-0.226047 -0.022269 0.973862" limited="true" range="       0    2.618" ref="0"></joint>
            <body name="radius_l" pos="-0.00749032 -0.0144829 -0.0290427" quat="1.0 -2.301201592641875e-21 6.933378131686372e-19 1.7489241099837954e-19">
              <geom name="radius_lv" type="mesh" mesh="radius_lv"></geom>
              <inertial pos="       0 -0.134201        0" mass="0.587364774280898" fullinertia="0.00355063 0.000740813 0.00385151        0        0        0"></inertial>
              <joint name="pro_sup_l" type="hinge" pos="0 0 0" axis="-0.056398 -0.998406 0.001952" limited="true" range="       0   1.5708" ref="0"></joint>
              <body name="hand_l" pos="-0.00979521 -0.262602 -0.0151543" quat="1.0 0.0 8.407790785948892e-45 0.0">
                <geom name="pisiform_lvs" type="mesh" mesh="pisiform_lvs"></geom>
                <geom name="lunate_lvs" type="mesh" mesh="lunate_lvs"></geom>
                <geom name="scaphoid_lvs" type="mesh" mesh="scaphoid_lvs"></geom>
                <geom name="triquetrum_lvs" type="mesh" mesh="triquetrum_lvs"></geom>
                <geom name="hamate_lvs" type="mesh" mesh="hamate_lvs"></geom>
                <geom name="capitate_lvs" type="mesh" mesh="capitate_lvs"></geom>
                <geom name="trapezoid_lvs" type="mesh" mesh="trapezoid_lvs"></geom>
                <geom name="trapezium_lvs" type="mesh" mesh="trapezium_lvs"></geom>
                <geom name="metacarpal2_lvs" type="mesh" mesh="metacarpal2_lvs"></geom>
                <geom name="index_proximal_lvs" type="mesh" mesh="index_proximal_lvs"></geom>
                <geom name="index_medial_lvs" type="mesh" mesh="index_medial_lvs"></geom>
                <geom name="index_distal_lvs" type="mesh" mesh="index_distal_lvs"></geom>
                <geom name="metacarpal3_lvs" type="mesh" mesh="metacarpal3_lvs"></geom>
                <geom name="middle_proximal_lvs" type="mesh" mesh="middle_proximal_lvs"></geom>
                <geom name="middle_medial_lvs" type="mesh" mesh="middle_medial_lvs"></geom>
                <geom name="middle_distal_lvs" type="mesh" mesh="middle_distal_lvs"></geom>
                <geom name="metacarpal4_lvs" type="mesh" mesh="metacarpal4_lvs"></geom>
                <geom name="ring_proximal_lvs" type="mesh" mesh="ring_proximal_lvs"></geom>
                <geom name="ring_medial_lvs" type="mesh" mesh="ring_medial_lvs"></geom>
                <geom name="ring_distal_lvs" type="mesh" mesh="ring_distal_lvs"></geom>
                <geom name="metacarpal5_lvs" type="mesh" mesh="metacarpal5_lvs"></geom>
                <geom name="little_proximal_lvs" type="mesh" mesh="little_proximal_lvs"></geom>
                <geom name="little_medial_lvs" type="mesh" mesh="little_medial_lvs"></geom>
                <geom name="little_distal_lvs" type="mesh" mesh="little_distal_lvs"></geom>
                <geom name="metacarpal1_lvs" type="mesh" mesh="metacarpal1_lvs"></geom>
                <geom name="thumb_proximal_lvs" type="mesh" mesh="thumb_proximal_lvs"></geom>
                <geom name="thumb_distal_lvs" type="mesh" mesh="thumb_distal_lvs"></geom>
                <inertial pos="       0 -0.0758218        0" mass="0.442336434952281" fullinertia="0.00106926 0.000655703 0.00160629        0        0        0"></inertial>
                <joint name="wrist_flex_l" type="hinge" pos="0 0 0" axis="-3.55271e-15 -3.55271e-15        1" limited="true" range="-1.22173  1.22173" ref="0"></joint>
                <joint name="wrist_dev_l" type="hinge" pos="0 0 0" axis="      -1        0 -3.55271e-15" limited="true" range="-0.436332 0.610865" ref="0"></joint>
              </body>
            </body>
          </body>
        </body>
      </body>
    </body>
    <camera name="for_testing" pos="0 0 0" euler="0 0 0"></camera>
  </worldbody>
  <asset>
    <mesh name="r_pelvis" file="Geometry/r_pelvis.stl" scale="0.988697  1.01947  1.12645"></mesh>
    <mesh name="l_pelvis" file="Geometry/l_pelvis.stl" scale="0.988697  1.01947  1.12645"></mesh>
    <mesh name="sacrum" file="Geometry/sacrum.stl" scale="0.988697  1.01947  1.12645"></mesh>
    <mesh name="r_femur" file="Geometry/r_femur.stl" scale="  1.1089   1.1089   1.1089"></mesh>
    <mesh name="r_tibia" file="Geometry/r_tibia.stl" scale=" 1.07741  1.07741  1.07741"></mesh>
    <mesh name="r_fibula" file="Geometry/r_fibula.stl" scale=" 1.07741  1.07741  1.07741"></mesh>
    <mesh name="r_talus" file="Geometry/r_talus.stl" scale=" 1.11808  1.11808  1.11808"></mesh>
    <mesh name="r_foot" file="Geometry/r_foot.stl" scale=" 1.11808  1.11808  1.11808"></mesh>
    <mesh name="r_bofoot" file="Geometry/r_bofoot.stl" scale=" 1.11808  1.11808  1.11808"></mesh>
    <mesh name="r_patella" file="Geometry/r_patella.stl" scale="       1        1        1"></mesh>
    <mesh name="l_femur" file="Geometry/l_femur.stl" scale="  1.1089   1.1089   1.1089"></mesh>
    <mesh name="l_tibia" file="Geometry/l_tibia.stl" scale=" 1.07741  1.07741  1.07741"></mesh>
    <mesh name="l_fibula" file="Geometry/l_fibula.stl" scale=" 1.07741  1.07741  1.07741"></mesh>
    <mesh name="l_talus" file="Geometry/l_talus.stl" scale=" 1.11808  1.11808  1.11808"></mesh>
    <mesh name="l_foot" file="Geometry/l_foot.stl" scale=" 1.11808  1.11808  1.11808"></mesh>
    <mesh name="l_bofoot" file="Geometry/l_bofoot.stl" scale=" 1.11808  1.11808  1.11808"></mesh>
    <mesh name="l_patella" file="Geometry/l_patella.stl" scale="       1        1        1"></mesh>
    <mesh name="hat_spine" file="Geometry/hat_spine.stl" scale="0.991485 0.991485 0.991485"></mesh>
    <mesh name="hat_jaw" file="Geometry/hat_jaw.stl" scale="0.991485 0.991485 0.991485"></mesh>
    <mesh name="hat_skull" file="Geometry/hat_skull.stl" scale="0.991485 0.991485 0.991485"></mesh>
    <mesh name="hat_ribs_scap" file="Geometry/hat_ribs_scap.stl" scale="0.991485 0.991485 0.991485"></mesh>
    <mesh name="humerus_rv" file="Geometry/humerus_rv.stl" scale=" 1.10582  1.10582  1.10582"></mesh>
    <mesh name="ulna_rv" file="Geometry/ulna_rv.stl" scale=" 1.11347  1.11347  1.11347"></mesh>
    <mesh name="radius_rv" file="Geometry/radius_rv.stl" scale=" 1.11347  1.11347  1.11347"></mesh>
    <mesh name="pisiform_rvs" file="Geometry/pisiform_rvs.stl" scale="0.946451 0.946451 0.946451"></mesh>
    <mesh name="lunate_rvs" file="Geometry/lunate_rvs.stl" scale="0.946451 0.946451 0.946451"></mesh>
    <mesh name="scaphoid_rvs" file="Geometry/scaphoid_rvs.stl" scale="0.946451 0.946451 0.946451"></mesh>
    <mesh name="triquetrum_rvs" file="Geometry/triquetrum_rvs.stl" scale="0.946451 0.946451 0.946451"></mesh>
    <mesh name="hamate_rvs" file="Geometry/hamate_rvs.stl" scale="0.946451 0.946451 0.946451"></mesh>
    <mesh name="capitate_rvs" file="Geometry/capitate_rvs.stl" scale="0.946451 0.946451 0.946451"></mesh>
    <mesh name="trapezoid_rvs" file="Geometry/trapezoid_rvs.stl" scale="0.946451 0.946451 0.946451"></mesh>
    <mesh name="trapezium_rvs" file="Geometry/trapezium_rvs.stl" scale="0.946451 0.946451 0.946451"></mesh>
    <mesh name="metacarpal2_rvs" file="Geometry/metacarpal2_rvs.stl" scale="0.946451 0.946451 0.946451"></mesh>
    <mesh name="index_proximal_rvs" file="Geometry/index_proximal_rvs.stl" scale="0.946451 0.946451 0.946451"></mesh>
    <mesh name="index_medial_rvs" file="Geometry/index_medial_rvs.stl" scale="0.946451 0.946451 0.946451"></mesh>
    <mesh name="index_distal_rvs" file="Geometry/index_distal_rvs.stl" scale="0.946451 0.946451 0.946451"></mesh>
    <mesh name="metacarpal3_rvs" file="Geometry/metacarpal3_rvs.stl" scale="0.946451 0.946451 0.946451"></mesh>
    <mesh name="middle_proximal_rvs" file="Geometry/middle_proximal_rvs.stl" scale="0.946451 0.946451 0.946451"></mesh>
    <mesh name="middle_medial_rvs" file="Geometry/middle_medial_rvs.stl" scale="0.946451 0.946451 0.946451"></mesh>
    <mesh name="middle_distal_rvs" file="Geometry/middle_distal_rvs.stl" scale="0.946451 0.946451 0.946451"></mesh>
    <mesh name="metacarpal4_rvs" file="Geometry/metacarpal4_rvs.stl" scale="0.946451 0.946451 0.946451"></mesh>
    <mesh name="ring_proximal_rvs" file="Geometry/ring_proximal_rvs.stl" scale="0.946451 0.946451 0.946451"></mesh>
    <mesh name="ring_medial_rvs" file="Geometry/ring_medial_rvs.stl" scale="0.946451 0.946451 0.946451"></mesh>
    <mesh name="ring_distal_rvs" file="Geometry/ring_distal_rvs.stl" scale="0.946451 0.946451 0.946451"></mesh>
    <mesh name="metacarpal5_rvs" file="Geometry/metacarpal5_rvs.stl" scale="0.946451 0.946451 0.946451"></mesh>
    <mesh name="little_proximal_rvs" file="Geometry/little_proximal_rvs.stl" scale="0.946451 0.946451 0.946451"></mesh>
    <mesh name="little_medial_rvs" file="Geometry/little_medial_rvs.stl" scale="0.946451 0.946451 0.946451"></mesh>
    <mesh name="little_distal_rvs" file="Geometry/little_distal_rvs.stl" scale="0.946451 0.946451 0.946451"></mesh>
    <mesh name="metacarpal1_rvs" file="Geometry/metacarpal1_rvs.stl" scale="0.946451 0.946451 0.946451"></mesh>
    <mesh name="thumb_proximal_rvs" file="Geometry/thumb_proximal_rvs.stl" scale="0.946451 0.946451 0.946451"></mesh>
    <mesh name="thumb_distal_rvs" file="Geometry/thumb_distal_rvs.stl" scale="0.946451 0.946451 0.946451"></mesh>
    <mesh name="humerus_lv" file="Geometry/humerus_lv.stl" scale=" 1.10582  1.10582  1.10582"></mesh>
    <mesh name="ulna_lv" file="Geometry/ulna_lv.stl" scale=" 1.11347  1.11347  1.11347"></mesh>
    <mesh name="radius_lv" file="Geometry/radius_lv.stl" scale=" 1.11347  1.11347  1.11347"></mesh>
    <mesh name="pisiform_lvs" file="Geometry/pisiform_lvs.stl" scale="0.946451 0.946451 0.946451"></mesh>
    <mesh name="lunate_lvs" file="Geometry/lunate_lvs.stl" scale="0.946451 0.946451 0.946451"></mesh>
    <mesh name="scaphoid_lvs" file="Geometry/scaphoid_lvs.stl" scale="0.946451 0.946451 0.946451"></mesh>
    <mesh name="triquetrum_lvs" file="Geometry/triquetrum_lvs.stl" scale="0.946451 0.946451 0.946451"></mesh>
    <mesh name="hamate_lvs" file="Geometry/hamate_lvs.stl" scale="0.946451 0.946451 0.946451"></mesh>
    <mesh name="capitate_lvs" file="Geometry/capitate_lvs.stl" scale="0.946451 0.946451 0.946451"></mesh>
    <mesh name="trapezoid_lvs" file="Geometry/trapezoid_lvs.stl" scale="0.946451 0.946451 0.946451"></mesh>
    <mesh name="trapezium_lvs" file="Geometry/trapezium_lvs.stl" scale="0.946451 0.946451 0.946451"></mesh>
    <mesh name="metacarpal2_lvs" file="Geometry/metacarpal2_lvs.stl" scale="0.946451 0.946451 0.946451"></mesh>
    <mesh name="index_proximal_lvs" file="Geometry/index_proximal_lvs.stl" scale="0.946451 0.946451 0.946451"></mesh>
    <mesh name="index_medial_lvs" file="Geometry/index_medial_lvs.stl" scale="0.946451 0.946451 0.946451"></mesh>
    <mesh name="index_distal_lvs" file="Geometry/index_distal_lvs.stl" scale="0.946451 0.946451 0.946451"></mesh>
    <mesh name="metacarpal3_lvs" file="Geometry/metacarpal3_lvs.stl" scale="0.946451 0.946451 0.946451"></mesh>
    <mesh name="middle_proximal_lvs" file="Geometry/middle_proximal_lvs.stl" scale="0.946451 0.946451 0.946451"></mesh>
    <mesh name="middle_medial_lvs" file="Geometry/middle_medial_lvs.stl" scale="0.946451 0.946451 0.946451"></mesh>
    <mesh name="middle_distal_lvs" file="Geometry/middle_distal_lvs.stl" scale="0.946451 0.946451 0.946451"></mesh>
    <mesh name="metacarpal4_lvs" file="Geometry/metacarpal4_lvs.stl" scale="0.946451 0.946451 0.946451"></mesh>
    <mesh name="ring_proximal_lvs" file="Geometry/ring_proximal_lvs.stl" scale="0.946451 0.946451 0.946451"></mesh>
    <mesh name="ring_medial_lvs" file="Geometry/ring_medial_lvs.stl" scale="0.946451 0.946451 0.946451"></mesh>
    <mesh name="ring_distal_lvs" file="Geometry/ring_distal_lvs.stl" scale="0.946451 0.946451 0.946451"></mesh>
    <mesh name="metacarpal5_lvs" file="Geometry/metacarpal5_lvs.stl" scale="0.946451 0.946451 0.946451"></mesh>
    <mesh name="little_proximal_lvs" file="Geometry/little_proximal_lvs.stl" scale="0.946451 0.946451 0.946451"></mesh>
    <mesh name="little_medial_lvs" file="Geometry/little_medial_lvs.stl" scale="0.946451 0.946451 0.946451"></mesh>
    <mesh name="little_distal_lvs" file="Geometry/little_distal_lvs.stl" scale="0.946451 0.946451 0.946451"></mesh>
    <mesh name="metacarpal1_lvs" file="Geometry/metacarpal1_lvs.stl" scale="0.946451 0.946451 0.946451"></mesh>
    <mesh name="thumb_proximal_lvs" file="Geometry/thumb_proximal_lvs.stl" scale="0.946451 0.946451 0.946451"></mesh>
    <mesh name="thumb_distal_lvs" file="Geometry/thumb_distal_lvs.stl" scale="0.946451 0.946451 0.946451"></mesh>
    <texture name="texplane" type="2d" builtin="checker" rgb1=".2 .3 .4" rgb2=".1 0.15 0.2" width="100" height="100"></texture>
    <material name="MatPlane" reflectance="0.0" texture="texplane" texrepeat="1 1" texuniform="true"></material>
  </asset>
  <tendon>
    <spatial name="addbrev_r_tendon">
      <site site="addbrev_r-P1"></site>
      <site site="addbrev_r-P2"></site>
    </spatial>
    <spatial name="addlong_r_tendon">
      <site site="addlong_r-P1"></site>
      <site site="addlong_r-P2"></site>
    </spatial>
    <spatial name="addmagDist_r_tendon">
      <site site="addmagDist_r-P1"></site>
      <site site="addmagDist_r-P2"></site>
    </spatial>
    <spatial name="addmagIsch_r_tendon">
      <site site="addmagIsch_r-P1"></site>
      <site site="addmagIsch_r-P2"></site>
    </spatial>
    <spatial name="addmagMid_r_tendon">
      <site site="addmagMid_r-P1"></site>
      <site site="addmagMid_r-P2"></site>
    </spatial>
    <spatial name="addmagProx_r_tendon">
      <site site="addmagProx_r-P1"></site>
      <site site="addmagProx_r-P2"></site>
    </spatial>
    <spatial name="bflh_r_tendon">
      <site site="bflh_r-P1"></site>
      <site site="bflh_r-P2"></site>
      <site site="bflh_r-P3"></site>
    </spatial>
    <spatial name="bfsh_r_tendon">
      <site site="bfsh_r-P1"></site>
      <site site="bfsh_r-P2"></site>
    </spatial>
    <spatial name="edl_r_tendon">
      <site site="edl_r-P1"></site>
      <site site="edl_r-P2"></site>
      <site site="edl_r-P3"></site>
      <site site="edl_r-P4"></site>
      <site site="edl_r-P5"></site>
      <site site="edl_r-P6"></site>
    </spatial>
    <spatial name="ehl_r_tendon">
      <site site="ehl_r-P1"></site>
      <site site="ehl_r-P2"></site>
      <site site="ehl_r-P3"></site>
      <site site="ehl_r-P4"></site>
      <site site="ehl_r-P5"></site>
      <site site="ehl_r-P6"></site>
      <site site="ehl_r-P7"></site>
      <site site="ehl_r-P8"></site>
    </spatial>
    <spatial name="fdl_r_tendon">
      <site site="fdl_r-P1"></site>
      <site site="fdl_r-P2"></site>
      <site site="fdl_r-P3"></site>
      <site site="fdl_r-P4"></site>
      <site site="fdl_r-P5"></site>
      <site site="fdl_r-P6"></site>
      <site site="fdl_r-P7"></site>
      <site site="fdl_r-P8"></site>
    </spatial>
    <spatial name="fhl_r_tendon">
      <site site="fhl_r-P1"></site>
      <site site="fhl_r-P2"></site>
      <site site="fhl_r-P3"></site>
      <site site="fhl_r-P4"></site>
      <site site="fhl_r-P5"></site>
      <site site="fhl_r-P6"></site>
      <site site="fhl_r-P7"></site>
    </spatial>
    <spatial name="gaslat_r_tendon">
      <site site="gaslat_r-P1"></site>
      <site site="gaslat_r-P2"></site>
    </spatial>
    <spatial name="gasmed_r_tendon">
      <site site="gasmed_r-P1"></site>
      <site site="gasmed_r-P2"></site>
    </spatial>
    <spatial name="glmax1_r_tendon">
      <site site="glmax1_r-P1"></site>
      <site site="glmax1_r-P2"></site>
      <site site="glmax1_r-P3"></site>
      <site site="glmax1_r-P4"></site>
    </spatial>
    <spatial name="glmax2_r_tendon">
      <site site="glmax2_r-P1"></site>
      <site site="glmax2_r-P2"></site>
      <site site="glmax2_r-P3"></site>
      <site site="glmax2_r-P4"></site>
    </spatial>
    <spatial name="glmax3_r_tendon">
      <site site="glmax3_r-P1"></site>
      <site site="glmax3_r-P2"></site>
      <site site="glmax3_r-P3"></site>
      <site site="glmax3_r-P4"></site>
    </spatial>
    <spatial name="glmed1_r_tendon">
      <site site="glmed1_r-P1"></site>
      <site site="glmed1_r-P2"></site>
    </spatial>
    <spatial name="glmed2_r_tendon">
      <site site="glmed2_r-P1"></site>
      <site site="glmed2_r-P2"></site>
    </spatial>
    <spatial name="glmed3_r_tendon">
      <site site="glmed3_r-P1"></site>
      <site site="glmed3_r-P2"></site>
    </spatial>
    <spatial name="glmin1_r_tendon">
      <site site="glmin1_r-P1"></site>
      <site site="glmin1_r-P2"></site>
    </spatial>
    <spatial name="glmin2_r_tendon">
      <site site="glmin2_r-P1"></site>
      <site site="glmin2_r-P2"></site>
    </spatial>
    <spatial name="glmin3_r_tendon">
      <site site="glmin3_r-P1"></site>
      <site site="glmin3_r-P2"></site>
    </spatial>
    <spatial name="grac_r_tendon">
      <site site="grac_r-P1"></site>
      <site site="grac_r-P2"></site>
      <site site="grac_r-P3"></site>
    </spatial>
    <spatial name="iliacus_r_tendon">
      <site site="iliacus_r-P1"></site>
      <site site="iliacus_r-P2"></site>
      <site site="iliacus_r-P3"></site>
      <site site="iliacus_r-P4"></site>
    </spatial>
    <spatial name="perbrev_r_tendon">
      <site site="perbrev_r-P1"></site>
      <site site="perbrev_r-P2"></site>
      <site site="perbrev_r-P3"></site>
      <site site="perbrev_r-P4"></site>
      <site site="perbrev_r-P5"></site>
    </spatial>
    <spatial name="perlong_r_tendon">
      <site site="perlong_r-P1"></site>
      <site site="perlong_r-P2"></site>
      <site site="perlong_r-P3"></site>
      <site site="perlong_r-P4"></site>
      <site site="perlong_r-P5"></site>
      <site site="perlong_r-P6"></site>
      <site site="perlong_r-P7"></site>
    </spatial>
    <spatial name="piri_r_tendon">
      <site site="piri_r-P1"></site>
      <site site="piri_r-P2"></site>
      <site site="piri_r-P3"></site>
    </spatial>
    <spatial name="psoas_r_tendon">
      <site site="psoas_r-P1"></site>
      <site site="psoas_r-P2"></site>
      <site site="psoas_r-P3"></site>
      <site site="psoas_r-P4"></site>
    </spatial>
    <spatial name="recfem_r_tendon">
      <site site="recfem_r-P1"></site>
      <site site="recfem_r-P2"></site>
      <site site="recfem_r-P3"></site>
      <site site="recfem_r-P4"></site>
      <site site="recfem_r-P5"></site>
    </spatial>
    <spatial name="sart_r_tendon">
      <site site="sart_r-P1"></site>
      <site site="sart_r-P2"></site>
      <site site="sart_r-P3"></site>
      <site site="sart_r-P4"></site>
      <site site="sart_r-P5"></site>
    </spatial>
    <spatial name="semimem_r_tendon">
      <site site="semimem_r-P1"></site>
      <site site="semimem_r-P2"></site>
    </spatial>
    <spatial name="semiten_r_tendon">
      <site site="semiten_r-P1"></site>
      <site site="semiten_r-P2"></site>
      <site site="semiten_r-P3"></site>
    </spatial>
    <spatial name="soleus_r_tendon">
      <site site="soleus_r-P1"></site>
      <site site="soleus_r-P2"></site>
    </spatial>
    <spatial name="tfl_r_tendon">
      <site site="tfl_r-P1"></site>
      <site site="tfl_r-P2"></site>
      <site site="tfl_r-P3"></site>
      <site site="tfl_r-P4"></site>
    </spatial>
    <spatial name="tibant_r_tendon">
      <site site="tibant_r-P1"></site>
      <site site="tibant_r-P2"></site>
      <site site="tibant_r-P3"></site>
      <site site="tibant_r-P4"></site>
    </spatial>
    <spatial name="tibpost_r_tendon">
      <site site="tibpost_r-P1"></site>
      <site site="tibpost_r-P2"></site>
      <site site="tibpost_r-P3"></site>
      <site site="tibpost_r-P4"></site>
    </spatial>
    <spatial name="vasint_r_tendon">
      <site site="vasint_r-P1"></site>
      <site site="vasint_r-P2"></site>
      <site site="vasint_r-P3"></site>
      <site site="vasint_r-P4"></site>
      <site site="vasint_r-P5"></site>
    </spatial>
    <spatial name="vaslat_r_tendon">
      <site site="vaslat_r-P1"></site>
      <site site="vaslat_r-P2"></site>
      <site site="vaslat_r-P3"></site>
      <site site="vaslat_r-P4"></site>
      <site site="vaslat_r-P5"></site>
    </spatial>
    <spatial name="vasmed_r_tendon">
      <site site="vasmed_r-P1"></site>
      <site site="vasmed_r-P2"></site>
      <site site="vasmed_r-P3"></site>
      <site site="vasmed_r-P4"></site>
      <site site="vasmed_r-P5"></site>
    </spatial>
    <spatial name="addbrev_l_tendon">
      <site site="addbrev_l-P1"></site>
      <site site="addbrev_l-P2"></site>
    </spatial>
    <spatial name="addlong_l_tendon">
      <site site="addlong_l-P1"></site>
      <site site="addlong_l-P2"></site>
    </spatial>
    <spatial name="addmagDist_l_tendon">
      <site site="addmagDist_l-P1"></site>
      <site site="addmagDist_l-P2"></site>
    </spatial>
    <spatial name="addmagIsch_l_tendon">
      <site site="addmagIsch_l-P1"></site>
      <site site="addmagIsch_l-P2"></site>
    </spatial>
    <spatial name="addmagMid_l_tendon">
      <site site="addmagMid_l-P1"></site>
      <site site="addmagMid_l-P2"></site>
    </spatial>
    <spatial name="addmagProx_l_tendon">
      <site site="addmagProx_l-P1"></site>
      <site site="addmagProx_l-P2"></site>
    </spatial>
    <spatial name="bflh_l_tendon">
      <site site="bflh_l-P1"></site>
      <site site="bflh_l-P2"></site>
      <site site="bflh_l-P3"></site>
    </spatial>
    <spatial name="bfsh_l_tendon">
      <site site="bfsh_l-P1"></site>
      <site site="bfsh_l-P2"></site>
    </spatial>
    <spatial name="edl_l_tendon">
      <site site="edl_l-P1"></site>
      <site site="edl_l-P2"></site>
      <site site="edl_l-P3"></site>
      <site site="edl_l-P4"></site>
      <site site="edl_l-P5"></site>
      <site site="edl_l-P6"></site>
    </spatial>
    <spatial name="ehl_l_tendon">
      <site site="ehl_l-P1"></site>
      <site site="ehl_l-P2"></site>
      <site site="ehl_l-P3"></site>
      <site site="ehl_l-P4"></site>
      <site site="ehl_l-P5"></site>
      <site site="ehl_l-P6"></site>
      <site site="ehl_l-P7"></site>
      <site site="ehl_l-P8"></site>
    </spatial>
    <spatial name="fdl_l_tendon">
      <site site="fdl_l-P1"></site>
      <site site="fdl_l-P2"></site>
      <site site="fdl_l-P3"></site>
      <site site="fdl_l-P4"></site>
      <site site="fdl_l-P5"></site>
      <site site="fdl_l-P6"></site>
      <site site="fdl_l-P7"></site>
      <site site="fdl_l-P8"></site>
    </spatial>
    <spatial name="fhl_l_tendon">
      <site site="fhl_l-P1"></site>
      <site site="fhl_l-P2"></site>
      <site site="fhl_l-P3"></site>
      <site site="fhl_l-P4"></site>
      <site site="fhl_l-P5"></site>
      <site site="fhl_l-P6"></site>
      <site site="fhl_l-P7"></site>
    </spatial>
    <spatial name="gaslat_l_tendon">
      <site site="gaslat_l-P1"></site>
      <site site="gaslat_l-P2"></site>
    </spatial>
    <spatial name="gasmed_l_tendon">
      <site site="gasmed_l-P1"></site>
      <site site="gasmed_l-P2"></site>
    </spatial>
    <spatial name="glmax1_l_tendon">
      <site site="glmax1_l-P1"></site>
      <site site="glmax1_l-P2"></site>
      <site site="glmax1_l-P3"></site>
      <site site="glmax1_l-P4"></site>
    </spatial>
    <spatial name="glmax2_l_tendon">
      <site site="glmax2_l-P1"></site>
      <site site="glmax2_l-P2"></site>
      <site site="glmax2_l-P3"></site>
      <site site="glmax2_l-P4"></site>
    </spatial>
    <spatial name="glmax3_l_tendon">
      <site site="glmax3_l-P1"></site>
      <site site="glmax3_l-P2"></site>
      <site site="glmax3_l-P3"></site>
      <site site="glmax3_l-P4"></site>
    </spatial>
    <spatial name="glmed1_l_tendon">
      <site site="glmed1_l-P1"></site>
      <site site="glmed1_l-P2"></site>
    </spatial>
    <spatial name="glmed2_l_tendon">
      <site site="glmed2_l-P1"></site>
      <site site="glmed2_l-P2"></site>
    </spatial>
    <spatial name="glmed3_l_tendon">
      <site site="glmed3_l-P1"></site>
      <site site="glmed3_l-P2"></site>
    </spatial>
    <spatial name="glmin1_l_tendon">
      <site site="glmin1_l-P1"></site>
      <site site="glmin1_l-P2"></site>
    </spatial>
    <spatial name="glmin2_l_tendon">
      <site site="glmin2_l-P1"></site>
      <site site="glmin2_l-P2"></site>
    </spatial>
    <spatial name="glmin3_l_tendon">
      <site site="glmin3_l-P1"></site>
      <site site="glmin3_l-P2"></site>
    </spatial>
    <spatial name="grac_l_tendon">
      <site site="grac_l-P1"></site>
      <site site="grac_l-P2"></site>
      <site site="grac_l-P3"></site>
    </spatial>
    <spatial name="iliacus_l_tendon">
      <site site="iliacus_l-P1"></site>
      <site site="iliacus_l-P2"></site>
      <site site="iliacus_l-P3"></site>
      <site site="iliacus_l-P4"></site>
    </spatial>
    <spatial name="perbrev_l_tendon">
      <site site="perbrev_l-P1"></site>
      <site site="perbrev_l-P2"></site>
      <site site="perbrev_l-P3"></site>
      <site site="perbrev_l-P4"></site>
      <site site="perbrev_l-P5"></site>
    </spatial>
    <spatial name="perlong_l_tendon">
      <site site="perlong_l-P1"></site>
      <site site="perlong_l-P2"></site>
      <site site="perlong_l-P3"></site>
      <site site="perlong_l-P4"></site>
      <site site="perlong_l-P5"></site>
      <site site="perlong_l-P6"></site>
      <site site="perlong_l-P7"></site>
    </spatial>
    <spatial name="piri_l_tendon">
      <site site="piri_l-P1"></site>
      <site site="piri_l-P2"></site>
      <site site="piri_l-P3"></site>
    </spatial>
    <spatial name="psoas_l_tendon">
      <site site="psoas_l-P1"></site>
      <site site="psoas_l-P2"></site>
      <site site="psoas_l-P3"></site>
      <site site="psoas_l-P4"></site>
    </spatial>
    <spatial name="recfem_l_tendon">
      <site site="recfem_l-P1"></site>
      <site site="recfem_l-P2"></site>
      <site site="recfem_l-P3"></site>
      <site site="recfem_l-P4"></site>
      <site site="recfem_l-P5"></site>
    </spatial>
    <spatial name="sart_l_tendon">
      <site site="sart_l-P1"></site>
      <site site="sart_l-P2"></site>
      <site site="sart_l-P3"></site>
      <site site="sart_l-P4"></site>
      <site site="sart_l-P5"></site>
    </spatial>
    <spatial name="semimem_l_tendon">
      <site site="semimem_l-P1"></site>
      <site site="semimem_l-P2"></site>
    </spatial>
    <spatial name="semiten_l_tendon">
      <site site="semiten_l-P1"></site>
      <site site="semiten_l-P2"></site>
      <site site="semiten_l-P3"></site>
    </spatial>
    <spatial name="soleus_l_tendon">
      <site site="soleus_l-P1"></site>
      <site site="soleus_l-P2"></site>
    </spatial>
    <spatial name="tfl_l_tendon">
      <site site="tfl_l-P1"></site>
      <site site="tfl_l-P2"></site>
      <site site="tfl_l-P3"></site>
      <site site="tfl_l-P4"></site>
    </spatial>
    <spatial name="tibant_l_tendon">
      <site site="tibant_l-P1"></site>
      <site site="tibant_l-P2"></site>
      <site site="tibant_l-P3"></site>
      <site site="tibant_l-P4"></site>
    </spatial>
    <spatial name="tibpost_l_tendon">
      <site site="tibpost_l-P1"></site>
      <site site="tibpost_l-P2"></site>
      <site site="tibpost_l-P3"></site>
      <site site="tibpost_l-P4"></site>
    </spatial>
    <spatial name="vasint_l_tendon">
      <site site="vasint_l-P1"></site>
      <site site="vasint_l-P2"></site>
      <site site="vasint_l-P3"></site>
      <site site="vasint_l-P4"></site>
      <site site="vasint_l-P5"></site>
    </spatial>
    <spatial name="vaslat_l_tendon">
      <site site="vaslat_l-P1"></site>
      <site site="vaslat_l-P2"></site>
      <site site="vaslat_l-P3"></site>
      <site site="vaslat_l-P4"></site>
      <site site="vaslat_l-P5"></site>
    </spatial>
    <spatial name="vasmed_l_tendon">
      <site site="vasmed_l-P1"></site>
      <site site="vasmed_l-P2"></site>
      <site site="vasmed_l-P3"></site>
      <site site="vasmed_l-P4"></site>
      <site site="vasmed_l-P5"></site>
    </spatial>
  </tendon>
  <actuator>
    <general name="lumbar_ext" joint="lumbar_extension" class="motor"></general>
    <general name="lumbar_bend" joint="lumbar_bending" class="motor"></general>
    <general name="lumbar_rot" joint="lumbar_rotation" class="motor"></general>
    <general name="shoulder_flex_r" joint="arm_flex_r" class="motor"></general>
    <general name="shoulder_add_r" joint="arm_add_r" class="motor"></general>
    <general name="shoulder_rot_r" joint="arm_rot_r" class="motor"></general>
    <general name="elbow_flex_r" joint="elbow_flex_r" class="motor"></general>
    <general name="pro_sup_r" joint="pro_sup_r" class="motor"></general>
    <general name="wrist_flex_r" joint="wrist_flex_r" class="motor"></general>
    <general name="wrist_dev_r" joint="wrist_dev_r" class="motor"></general>
    <general name="shoulder_flex_l" joint="arm_flex_l" class="motor"></general>
    <general name="shoulder_add_l" joint="arm_add_l" class="motor"></general>
    <general name="shoulder_rot_l" joint="arm_rot_l" class="motor"></general>
    <general name="elbow_flex_l" joint="elbow_flex_l" class="motor"></general>
    <general name="pro_sup_l" joint="pro_sup_l" class="motor"></general>
    <general name="wrist_flex_l" joint="wrist_flex_l" class="motor"></general>
    <general name="wrist_dev_l" joint="wrist_dev_l" class="motor"></general>
    <muscle name="addbrev_r" tendon="addbrev_r_tendon" class="muscle" force="625.819672131148" lengthrange="0.096364 0.210253"></muscle>
    <muscle name="addlong_r" tendon="addlong_r_tendon" class="muscle" force="916.8" lengthrange="0.205781 0.324746"></muscle>
    <muscle name="addmagDist_r" tendon="addmagDist_r_tendon" class="muscle" force="597.295081967214" lengthrange="0.196545 0.392577"></muscle>
    <muscle name="addmagIsch_r" tendon="addmagIsch_r_tendon" class="muscle" force="597.295081967214" lengthrange="0.328837 0.501471"></muscle>
    <muscle name="addmagMid_r" tendon="addmagMid_r_tendon" class="muscle" force="597.295081967214" lengthrange="0.129304  0.28214"></muscle>
    <muscle name="addmagProx_r" tendon="addmagProx_r_tendon" class="muscle" force="597.295081967214" lengthrange="0.101143 0.213378"></muscle>
    <muscle name="bflh_r" tendon="bflh_r_tendon" class="muscle" force="1313.18360655738" lengthrange="0.415753 0.522782"></muscle>
    <muscle name="bfsh_r" tendon="bfsh_r_tendon" class="muscle" force="557.11475409836" lengthrange="0.175489 0.292963"></muscle>
    <muscle name="edl_r" tendon="edl_r_tendon" class="muscle" force="603.4981556" lengthrange="0.440119 0.514061"></muscle>
    <muscle name="ehl_r" tendon="ehl_r_tendon" class="muscle" force="285.8675474" lengthrange="0.397981 0.478295"></muscle>
    <muscle name="fdl_r" tendon="fdl_r_tendon" class="muscle" force="423.177049180328" lengthrange="0.439528 0.487241"></muscle>
    <muscle name="fhl_r" tendon="fhl_r_tendon" class="muscle" force="907.839344262294" lengthrange="0.417601 0.473626"></muscle>
    <muscle name="gaslat_r" tendon="gaslat_r_tendon" class="muscle" force="1575.05901639344" lengthrange="0.437248 0.499359"></muscle>
    <muscle name="gasmed_r" tendon="gasmed_r_tendon" class="muscle" force="3115.51475409836" lengthrange="0.458078 0.512439"></muscle>
    <muscle name="glmax1_r" tendon="glmax1_r_tendon" class="muscle" force="983.783606557378" lengthrange="0.123749 0.268616"></muscle>
    <muscle name="glmax2_r" tendon="glmax2_r_tendon" class="muscle" force="1406.04590163935" lengthrange="0.150117 0.305951"></muscle>
    <muscle name="glmax3_r" tendon="glmax3_r_tendon" class="muscle" force="947.754098360656" lengthrange="0.159231 0.326848"></muscle>
    <muscle name="glmed1_r" tendon="glmed1_r_tendon" class="muscle" force="1093.4667688" lengthrange="0.0934174 0.165024"></muscle>
    <muscle name="glmed2_r" tendon="glmed2_r_tendon" class="muscle" force="765.0916616" lengthrange="0.104339  0.17677"></muscle>
    <muscle name="glmed3_r" tendon="glmed3_r_tendon" class="muscle" force="871.1992642" lengthrange="0.084613  0.15806"></muscle>
    <muscle name="glmin1_r" tendon="glmin1_r_tendon" class="muscle" force="374.045901639344" lengthrange="0.0516209 0.121287"></muscle>
    <muscle name="glmin2_r" tendon="glmin2_r_tendon" class="muscle" force="394.819672131148" lengthrange="0.0565696 0.115127"></muscle>
    <muscle name="glmin3_r" tendon="glmin3_r_tendon" class="muscle" force="446.773770491804" lengthrange="0.0737614 0.113872"></muscle>
    <muscle name="grac_r" tendon="grac_r_tendon" class="muscle" force="281.311475409836" lengthrange="0.316456 0.566338"></muscle>
    <muscle name="iliacus_r" tendon="iliacus_r_tendon" class="muscle" force="1021.14098360656" lengthrange=" 0.15359 0.260383"></muscle>
    <muscle name="perbrev_r" tendon="perbrev_r_tendon" class="muscle" force="521.2015988" lengthrange="0.184327 0.232591"></muscle>
    <muscle name="perlong_r" tendon="perlong_r_tendon" class="muscle" force="1115.3714214" lengthrange="0.388963 0.442641"></muscle>
    <muscle name="piri_r" tendon="piri_r_tendon" class="muscle" force="1029.7868852459" lengthrange="0.137527   0.1651"></muscle>
    <muscle name="psoas_r" tendon="psoas_r_tendon" class="muscle" force="1426.79016393443" lengthrange="0.163162 0.282111"></muscle>
    <muscle name="recfem_r" tendon="recfem_r_tendon" class="muscle" force="2191.74098360656" lengthrange="0.533649 0.615111"></muscle>
    <muscle name="sart_r" tendon="sart_r_tendon" class="muscle" force="249.413114754098" lengthrange="0.355789 0.796232"></muscle>
    <muscle name="semimem_r" tendon="semimem_r_tendon" class="muscle" force="2200.9868852459" lengthrange="0.424196 0.498549"></muscle>
    <muscle name="semiten_r" tendon="semiten_r_tendon" class="muscle" force="591.295081967214" lengthrange="0.378932 0.587246"></muscle>
    <muscle name="soleus_r" tendon="soleus_r_tendon" class="muscle" force="6194.84262295082" lengthrange="0.320828 0.364916"></muscle>
    <muscle name="tfl_r" tendon="tfl_r_tendon" class="muscle" force="411.20655737705" lengthrange="0.541914 0.645371"></muscle>
    <muscle name="tibant_r" tendon="tibant_r_tendon" class="muscle" force="1227.45245901639" lengthrange="0.297304 0.370016"></muscle>
    <muscle name="tibpost_r" tendon="tibpost_r_tendon" class="muscle" force="1730.15409836065" lengthrange="0.324258 0.364178"></muscle>
    <muscle name="vasint_r" tendon="vasint_r_tendon" class="muscle" force="1697.36065573771" lengthrange="0.277659 0.386955"></muscle>
    <muscle name="vaslat_r" tendon="vaslat_r_tendon" class="muscle" force="5148.76721311476" lengthrange="0.296354 0.402489"></muscle>
    <muscle name="vasmed_r" tendon="vasmed_r_tendon" class="muscle" force="2747.82295081966" lengthrange="0.268684 0.365895"></muscle>
    <muscle name="addbrev_l" tendon="addbrev_l_tendon" class="muscle" force="625.819672131148" lengthrange="0.096364 0.210253"></muscle>
    <muscle name="addlong_l" tendon="addlong_l_tendon" class="muscle" force="916.8" lengthrange="0.205781 0.324746"></muscle>
    <muscle name="addmagDist_l" tendon="addmagDist_l_tendon" class="muscle" force="597.295081967214" lengthrange="0.196545 0.392577"></muscle>
    <muscle name="addmagIsch_l" tendon="addmagIsch_l_tendon" class="muscle" force="597.295081967214" lengthrange="0.328837 0.501471"></muscle>
    <muscle name="addmagMid_l" tendon="addmagMid_l_tendon" class="muscle" force="597.295081967214" lengthrange="0.129304  0.28214"></muscle>
    <muscle name="addmagProx_l" tendon="addmagProx_l_tendon" class="muscle" force="597.295081967214" lengthrange="0.101143 0.213378"></muscle>
    <muscle name="bflh_l" tendon="bflh_l_tendon" class="muscle" force="1313.18360655738" lengthrange="0.415753 0.522782"></muscle>
    <muscle name="bfsh_l" tendon="bfsh_l_tendon" class="muscle" force="557.11475409836" lengthrange="0.175489 0.292963"></muscle>
    <muscle name="edl_l" tendon="edl_l_tendon" class="muscle" force="603.4981556" lengthrange="0.440119 0.514061"></muscle>
    <muscle name="ehl_l" tendon="ehl_l_tendon" class="muscle" force="285.8675474" lengthrange="0.397981 0.478295"></muscle>
    <muscle name="fdl_l" tendon="fdl_l_tendon" class="muscle" force="423.177049180328" lengthrange="0.439528 0.487241"></muscle>
    <muscle name="fhl_l" tendon="fhl_l_tendon" class="muscle" force="907.839344262294" lengthrange="0.417601 0.473626"></muscle>
    <muscle name="gaslat_l" tendon="gaslat_l_tendon" class="muscle" force="1575.05901639344" lengthrange="0.437248 0.499359"></muscle>
    <muscle name="gasmed_l" tendon="gasmed_l_tendon" class="muscle" force="3115.51475409836" lengthrange="0.458078 0.512439"></muscle>
    <muscle name="glmax1_l" tendon="glmax1_l_tendon" class="muscle" force="983.783606557378" lengthrange="0.123749 0.268616"></muscle>
    <muscle name="glmax2_l" tendon="glmax2_l_tendon" class="muscle" force="1406.04590163935" lengthrange="0.150117 0.305951"></muscle>
    <muscle name="glmax3_l" tendon="glmax3_l_tendon" class="muscle" force="947.754098360656" lengthrange="0.159231 0.326848"></muscle>
    <muscle name="glmed1_l" tendon="glmed1_l_tendon" class="muscle" force="1093.4667688" lengthrange="0.0934174 0.165024"></muscle>
    <muscle name="glmed2_l" tendon="glmed2_l_tendon" class="muscle" force="765.0916616" lengthrange="0.104339  0.17677"></muscle>
    <muscle name="glmed3_l" tendon="glmed3_l_tendon" class="muscle" force="871.1992642" lengthrange="0.084613  0.15806"></muscle>
    <muscle name="glmin1_l" tendon="glmin1_l_tendon" class="muscle" force="374.045901639344" lengthrange="0.0516209 0.121287"></muscle>
    <muscle name="glmin2_l" tendon="glmin2_l_tendon" class="muscle" force="394.819672131148" lengthrange="0.0565696 0.115127"></muscle>
    <muscle name="glmin3_l" tendon="glmin3_l_tendon" class="muscle" force="446.773770491804" lengthrange="0.0737614 0.113872"></muscle>
    <muscle name="grac_l" tendon="grac_l_tendon" class="muscle" force="281.311475409836" lengthrange="0.316456 0.566338"></muscle>
    <muscle name="iliacus_l" tendon="iliacus_l_tendon" class="muscle" force="1021.14098360656" lengthrange=" 0.15359 0.260383"></muscle>
    <muscle name="perbrev_l" tendon="perbrev_l_tendon" class="muscle" force="521.2015988" lengthrange="0.184327 0.232591"></muscle>
    <muscle name="perlong_l" tendon="perlong_l_tendon" class="muscle" force="1115.3714214" lengthrange="0.388963 0.442641"></muscle>
    <muscle name="piri_l" tendon="piri_l_tendon" class="muscle" force="1029.7868852459" lengthrange="0.137527   0.1651"></muscle>
    <muscle name="psoas_l" tendon="psoas_l_tendon" class="muscle" force="1426.79016393443" lengthrange="0.163162 0.282111"></muscle>
    <muscle name="recfem_l" tendon="recfem_l_tendon" class="muscle" force="2191.74098360656" lengthrange="0.533649 0.615111"></muscle>
    <muscle name="sart_l" tendon="sart_l_tendon" class="muscle" force="249.413114754098" lengthrange="0.355789 0.796232"></muscle>
    <muscle name="semimem_l" tendon="semimem_l_tendon" class="muscle" force="2200.9868852459" lengthrange="0.424196 0.498549"></muscle>
    <muscle name="semiten_l" tendon="semiten_l_tendon" class="muscle" force="591.295081967214" lengthrange="0.378932 0.587246"></muscle>
    <muscle name="soleus_l" tendon="soleus_l_tendon" class="muscle" force="6194.84262295082" lengthrange="0.320828 0.364916"></muscle>
    <muscle name="tfl_l" tendon="tfl_l_tendon" class="muscle" force="411.20655737705" lengthrange="0.541914 0.645371"></muscle>
    <muscle name="tibant_l" tendon="tibant_l_tendon" class="muscle" force="1227.45245901639" lengthrange="0.297304 0.370016"></muscle>
    <muscle name="tibpost_l" tendon="tibpost_l_tendon" class="muscle" force="1730.15409836065" lengthrange="0.324258 0.364178"></muscle>
    <muscle name="vasint_l" tendon="vasint_l_tendon" class="muscle" force="1697.36065573771" lengthrange="0.277659 0.386955"></muscle>
    <muscle name="vaslat_l" tendon="vaslat_l_tendon" class="muscle" force="5148.76721311476" lengthrange="0.296354 0.402489"></muscle>
    <muscle name="vasmed_l" tendon="vasmed_l_tendon" class="muscle" force="2747.82295081966" lengthrange="0.268684 0.365895"></muscle>
  </actuator>
  <equality>
    <joint name="knee_angle_r_translation2_constraint" active="true" joint1="knee_angle_r_translation2" joint2="knee_angle_r" polycoef="7.69254e-11 0.00587971 -0.00125622 -2.61846e-06 6.24355e-07" solimp="0.9999 0.9999 0.001 0.5 2"></joint>
    <joint name="knee_angle_r_translation1_constraint" active="true" joint1="knee_angle_r_translation1" joint2="knee_angle_r" polycoef="9.53733e-08 0.00312879 -0.00230804 0.000561561 5.68366e-07" solimp="0.9999 0.9999 0.001 0.5 2"></joint>
    <joint name="knee_angle_r_rotation2_constraint" active="true" joint1="knee_angle_r_rotation2" joint2="knee_angle_r" polycoef="-1.47325e-08   0.0791 -0.0328478 -0.0252183 0.0108321" solimp="0.9999 0.9999 0.001 0.5 2"></joint>
    <joint name="knee_angle_r_rotation3_constraint" active="true" joint1="knee_angle_r_rotation3" joint2="knee_angle_r" polycoef="1.08939e-08 0.369499 -0.169478 0.0251643 3.50498e-07" solimp="0.9999 0.9999 0.001 0.5 2"></joint>
    <joint name="knee_angle_r_beta_translation2_constraint" active="true" joint1="knee_angle_r_beta_translation2" joint2="knee_angle_r" polycoef="-0.0108281 -0.0487847 0.00927644 0.0131673 -0.00349673" solimp="0.9999 0.9999 0.001 0.5 2"></joint>
    <joint name="knee_angle_r_beta_translation1_constraint" active="true" joint1="knee_angle_r_beta_translation1" joint2="knee_angle_r" polycoef="0.0524192 -0.0150188 -0.0340522 0.0133393 -0.000879151" solimp="0.9999 0.9999 0.001 0.5 2"></joint>
    <joint name="knee_angle_r_beta_rotation1_constraint" active="true" joint1="knee_angle_r_beta_rotation1" joint2="knee_angle_r" polycoef="0.010506 0.0247615 -1.31647 0.716337 -0.138302" solimp="0.9999 0.9999 0.001 0.5 2"></joint>
    <joint name="subtalar_angle_r_constraint" active="true" joint1="subtalar_angle_r" polycoef="       0        0        0        0        0"></joint>
    <joint name="mtp_angle_r_constraint" active="true" joint1="mtp_angle_r" polycoef="       0        0        0        0        0"></joint>
    <joint name="knee_angle_l_translation2_constraint" active="true" joint1="knee_angle_l_translation2" joint2="knee_angle_l" polycoef="-7.69254e-11 -0.00587971 0.00125622 2.61846e-06 -6.24355e-07" solimp="0.9999 0.9999 0.001 0.5 2"></joint>
    <joint name="knee_angle_l_translation1_constraint" active="true" joint1="knee_angle_l_translation1" joint2="knee_angle_l" polycoef="9.53733e-08 0.00312879 -0.00230804 0.000561561 5.68366e-07" solimp="0.9999 0.9999 0.001 0.5 2"></joint>
    <joint name="knee_angle_l_rotation2_constraint" active="true" joint1="knee_angle_l_rotation2" joint2="knee_angle_l" polycoef="-1.47325e-08   0.0791 -0.0328478 -0.0252183 0.0108321" solimp="0.9999 0.9999 0.001 0.5 2"></joint>
    <joint name="knee_angle_l_rotation3_constraint" active="true" joint1="knee_angle_l_rotation3" joint2="knee_angle_l" polycoef="-1.08939e-08 -0.369499 0.169478 -0.0251643 -3.50498e-07" solimp="0.9999 0.9999 0.001 0.5 2"></joint>
    <joint name="knee_angle_l_beta_translation2_constraint" active="true" joint1="knee_angle_l_beta_translation2" joint2="knee_angle_l" polycoef="-0.0108281 -0.0487847 0.00927644 0.0131673 -0.00349673" solimp="0.9999 0.9999 0.001 0.5 2"></joint>
    <joint name="knee_angle_l_beta_translation1_constraint" active="true" joint1="knee_angle_l_beta_translation1" joint2="knee_angle_l" polycoef="0.0524192 -0.0150188 -0.0340522 0.0133393 -0.000879151" solimp="0.9999 0.9999 0.001 0.5 2"></joint>
    <joint name="knee_angle_l_beta_rotation1_constraint" active="true" joint1="knee_angle_l_beta_rotation1" joint2="knee_angle_l" polycoef="0.010506 0.0247615 -1.31647 0.716337 -0.138302" solimp="0.9999 0.9999 0.001 0.5 2"></joint>
    <joint name="subtalar_angle_l_constraint" active="true" joint1="subtalar_angle_l" polycoef="       0        0        0        0        0"></joint>
    <joint name="mtp_angle_l_constraint" active="true" joint1="mtp_angle_l" polycoef="       0        0        0        0        0"></joint>
    <joint name="wrist_flex_r_constraint" active="true" joint1="wrist_flex_r" polycoef="       0        0        0        0        0"></joint>
    <joint name="wrist_dev_r_constraint" active="true" joint1="wrist_dev_r" polycoef="       0        0        0        0        0"></joint>
    <joint name="wrist_flex_l_constraint" active="true" joint1="wrist_flex_l" polycoef="       0        0        0        0        0"></joint>
    <joint name="wrist_dev_l_constraint" active="true" joint1="wrist_dev_l" polycoef="       0        0        0        0        0"></joint>
    <weld name="origin_to_worldbody" body1="pelvis" active="false"></weld>
  </equality>
</mujoco>