<?xml version="1.0" encoding="utf-8"?>
<mujoco model="leg6dof9musc">
  <compiler inertiafromgeom="auto" angle="radian" balanceinertia="true" boundmass="0.001" boundinertia="0.001">
    <lengthrange inttotal="50" useexisting="true"></lengthrange>
  </compiler>
  <default>
    <joint limited="true" damping="0.5" armature="0.1" stiffness="2"></joint>
    <geom rgba="0.8 0.6 .4 1" margin="0.001"></geom>
    <site size="0.001"></site>
    <tendon width="0.001" rgba=".95 .3 .3 1" limited="false"></tendon>
    <default class="muscle">
      <muscle ctrllimited="true" ctrlrange="0 1" scale="200"></muscle>
    </default>
    <default class="motor">
      <general gainprm="5 0 0 0 0 0 0 0 0 0"></general>
    </default>
  </default>
  <option timestep="0.002"></option>
  <size njmax="1000" nconmax="400" nuser_jnt="1"></size>
  <worldbody>
    <geom name="floor" pos="0 0 0" size="10 10 0.125" type="plane" material="MatPlane" condim="3"></geom>
    <body name="pelvis" pos="0.593075 -0.017089        1" quat="0.7070896702840977 0.7070896702840974 -0.004919164311757895 -0.004919164311757895">
      <light mode="trackcom" directional="false" pos="0 0 4.0" dir="0 0 -1"></light>
      <geom name="sacrum" type="mesh" mesh="sacrum"></geom>
      <geom name="pelvis" type="mesh" mesh="pelvis"></geom>
      <geom name="l_pelvis" type="mesh" mesh="l_pelvis"></geom>
      <inertial pos="-0.0739512        0        0" mass="10.75379227" fullinertia="  0.1027 0.0870155 0.0578439        0        0        0"></inertial>
      <site name="bifemlh_r-P1" pos="-0.131752 -0.107287 0.0726333"></site>
      <site name="glut_max2_r-P1" pos="-0.141103 0.0184094 0.058889"></site>
      <site name="glut_max2_r-P2" pos="-0.143928 -0.0543913 0.0956031"></site>
      <site name="psoas_r-P1" pos="-0.0676753 0.0927789 0.030229"></site>
      <site name="psoas_r-P2" pos="-0.0248945 -0.0596212 0.0793903"></site>
      <site name="psoas_r-P3" pos="-0.0301244 -0.0842019 0.0853524"></site>
      <site name="rect_fem_r-P1" pos="-0.0308566 -0.0325302 0.101251"></site>
      <joint name="pelvis_ty" type="slide" pos="0 0 0" axis="       0        1        0" limited="false" range="      -1        3" ref="0" armature="0" damping="0" stiffness="0"></joint>
      <joint name="pelvis_tx" type="slide" pos="0 0 0" axis="       1        0        0" limited="false" range="      -1        1" ref="0" armature="0" damping="0" stiffness="0"></joint>
      <joint name="pelvis_tilt" type="hinge" pos="0 0 0" axis="       0        0        1" limited="false" range=" -1.5708   1.5708" ref="0" armature="0" damping="0" stiffness="0"></joint>
      <body name="femur_r" pos="-0.0739512 -0.0691397 0.0873398" quat="0.9992742038021659 -0.00777274134338932 -0.037290293290919894 0.0002900583276007693">
        <geom name="femur_r" type="mesh" mesh="femur_r"></geom>
        <inertial pos="       0 -0.199543        0" mass="8.54926632" fullinertia="0.169564 0.0444489 0.178809        0        0        0"></inertial>
        <site name="bifemsh_r-P1" pos="0.0058689 -0.247785 0.0274665"></site>
        <site name="glut_max2_r-P3" pos="-0.050003 -0.0622103 0.0343917"></site>
        <site name="glut_max2_r-P4" pos="-0.018311 -0.119256 0.0491814"></site>
        <site name="psoas_r-P4" pos="0.00187804 -0.0595106 0.00446036"></site>
        <site name="psoas_r-P5" pos="-0.0220671 -0.0700747 0.0122073"></site>
        <site name="rect_fem_r-P2" pos="0.0392043 -0.473033 0.00223019"></site>
        <site name="vas_int_r-P1" pos="0.0340396 -0.225835 0.0363872"></site>
        <site name="vas_int_r-P2" pos="0.0393216 -0.244616 0.0334527"></site>
        <site name="vas_int_r-P3" pos="0.0402607 -0.473033 0.00645579"></site>
        <site name="med_gas_r-P1" pos="-0.0223018 -0.461178 -0.0275838"></site>
        <site name="med_gas_r-P2" pos="-0.0352134 -0.472094 -0.0302835"></site>
        <joint name="hip_flexion_r" type="hinge" pos="0 0 0" axis="       0        0        1" limited="true" range=" -2.0944   2.0944" ref="0"></joint>
        <body name="tibia_r" pos="       0        0        0" quat="1.0 0.0 0.0 0.0">
          <geom name="tibia_r" type="mesh" mesh="tibia_r"></geom>
          <geom name="fibula_r" type="mesh" mesh="fibula_r"></geom>
          <inertial pos="       0  -0.2098        0" mass="4.67404243" fullinertia="0.0802351 0.00811903 0.0813495        0        0        0"></inertial>
          <site name="bifemlh_r-P2" pos="-0.0338242 -0.0404542 0.0330713"></site>
          <site name="bifemlh_r-P3" pos="-0.0262952 -0.0632659 0.0385439"></site>
          <site name="bifemsh_r-P2" pos="-0.0338242 -0.0404542 0.0330713"></site>
          <site name="bifemsh_r-P3" pos="-0.0262952 -0.0632659 0.0385439"></site>
          <site name="rect_fem_r-P3" pos="0.0878426 -0.0139192 0.00157322"></site>
          <site name="vas_int_r-P4" pos="0.0881542 -0.00708265 0.00202271"></site>
          <site name="soleus_r-P1" pos="-0.00269695 -0.172268 0.00797847"></site>
          <site name="tib_ant_r-P1" pos="0.0201147 -0.182493 0.0129229"></site>
          <site name="tib_ant_r-P2" pos="0.0369707 -0.443985 -0.01989"></site>
          <joint name="knee_angle_r_translation2" type="slide" pos="0 0 0" axis="       0        1        0" limited="true" range="-0.496042 -0.464005" ref="0"></joint>
          <joint name="knee_angle_r_translation1" type="slide" pos="0 0 0" axis="       1        0        0" limited="true" range="-0.00694632 0.00511636" ref="0"></joint>
          <joint name="knee_angle_r" type="hinge" pos="0 0 0" axis="       0        0        1" limited="true" range=" -2.0944 0.174533" ref="0"></joint>
          <body name="patella_r" pos="       0        0        0" quat="1.0 0.0 0.0 0.0">
            <geom name="pat" type="mesh" mesh="pat"></geom>
            <inertial pos="       0        0        0" mass="0.09191376" fullinertia="0.00110296 0.00110296 0.00110296        0        0        0"></inertial>
            <joint name="knee_angle_pat_r_translation2" type="slide" pos="0 0 0" axis="       0        1        0" limited="true" range="-0.0256302 -0.0225454" ref="0"></joint>
            <joint name="knee_angle_pat_r_translation1" type="slide" pos="0 0 0" axis="       1        0        0" limited="true" range="0.019463 0.0561568" ref="0"></joint>
            <joint name="knee_angle_pat_r_rotation1" type="hinge" pos="0 0 0" axis="       0        0        1" limited="true" range="-0.275058 0.320216" ref="0"></joint>
          </body>
          <body name="talus_r" pos="       0 -0.483203        0" quat="1.0 0.0 0.0 0.0">
            <geom name="talus" type="mesh" mesh="talus"></geom>
            <inertial pos="       0        0        0" mass="0.12606858" fullinertia="0.00202166 0.00202166 0.00202166        0        0        0"></inertial>
            <joint name="ankle_angle_r" type="hinge" pos="0 0 0" axis="  -0.105   -0.174    0.979" limited="false" range="  -1.571    1.571" ref="0"></joint>
            <body name="calcn_r" pos="-0.0620508 -0.0531864 0.0101307" quat="1.0 0.0 0.0 0.0">
              <geom name="foot" type="mesh" mesh="foot"></geom>
              <inertial pos="0.102693 0.0308079        0" mass="1.07224816" fullinertia="0.00090462 0.00361848 0.00361848        0        0        0"></inertial>
              <site name="med_gas_r-P3" pos="0 0.0318348 -0.00544272"></site>
              <site name="soleus_r-P2" pos="0 0.0318348 -0.00544272"></site>
              <site name="tib_ant_r-P3" pos="0.11974 0.0182793 -0.0313213"></site>
              <body name="toes_r" pos=" 0.18382 -0.00205386 0.00102692" quat="1.0 0.0 0.0 0.0">
                <geom name="bofoot" type="mesh" mesh="bofoot"></geom>
              </body>
            </body>
          </body>
        </body>
      </body>
    </body>
    <camera name="for_testing" pos="0 0 0" euler="0 0 0"></camera>
  </worldbody>
  <asset>
    <mesh name="sacrum" file="Geometry/sacrum.stl" scale=" 1.04599  1.04599  1.04599"></mesh>
    <mesh name="pelvis" file="Geometry/pelvis.stl" scale=" 1.04599  1.04599  1.04599"></mesh>
    <mesh name="l_pelvis" file="Geometry/l_pelvis.stl" scale=" 1.04599  1.04599  1.04599"></mesh>
    <mesh name="femur_r" file="Geometry/femur_r.stl" scale=" 1.17378  1.17378  1.17378"></mesh>
    <mesh name="tibia_r" file="Geometry/tibia_r.stl" scale=" 1.12373  1.12373  1.12373"></mesh>
    <mesh name="fibula_r" file="Geometry/fibula_r.stl" scale=" 1.12373  1.12373  1.12373"></mesh>
    <mesh name="pat" file="Geometry/pat.stl" scale=" 1.09544  1.09544  1.09544"></mesh>
    <mesh name="talus" file="Geometry/talus.stl" scale=" 1.26634  1.26634  1.26634"></mesh>
    <mesh name="foot" file="Geometry/foot.stl" scale=" 1.02693  1.02693  1.02693"></mesh>
    <mesh name="bofoot" file="Geometry/bofoot.stl" scale=" 1.02693  1.02693  1.02693"></mesh>
    <texture name="texplane" type="2d" builtin="checker" rgb1=".2 .3 .4" rgb2=".1 0.15 0.2" width="100" height="100"></texture>
    <material name="MatPlane" reflectance="0.0" texture="texplane" texrepeat="1 1" texuniform="true"></material>
  </asset>
  <tendon>
    <spatial name="bifemlh_r_tendon">
      <site site="bifemlh_r-P1"></site>
      <site site="bifemlh_r-P2"></site>
      <site site="bifemlh_r-P3"></site>
    </spatial>
    <spatial name="bifemsh_r_tendon">
      <site site="bifemsh_r-P1"></site>
      <site site="bifemsh_r-P2"></site>
      <site site="bifemsh_r-P3"></site>
    </spatial>
    <spatial name="glut_max2_r_tendon">
      <site site="glut_max2_r-P1"></site>
      <site site="glut_max2_r-P2"></site>
      <site site="glut_max2_r-P3"></site>
      <site site="glut_max2_r-P4"></site>
    </spatial>
    <spatial name="psoas_r_tendon">
      <site site="psoas_r-P1"></site>
      <site site="psoas_r-P2"></site>
      <site site="psoas_r-P3"></site>
      <site site="psoas_r-P4"></site>
      <site site="psoas_r-P5"></site>
    </spatial>
    <spatial name="rect_fem_r_tendon">
      <site site="rect_fem_r-P1"></site>
      <site site="rect_fem_r-P2"></site>
      <site site="rect_fem_r-P3"></site>
    </spatial>
    <spatial name="vas_int_r_tendon">
      <site site="vas_int_r-P1"></site>
      <site site="vas_int_r-P2"></site>
      <site site="vas_int_r-P3"></site>
      <site site="vas_int_r-P4"></site>
    </spatial>
    <spatial name="med_gas_r_tendon">
      <site site="med_gas_r-P1"></site>
      <site site="med_gas_r-P2"></site>
      <site site="med_gas_r-P3"></site>
    </spatial>
    <spatial name="soleus_r_tendon">
      <site site="soleus_r-P1"></site>
      <site site="soleus_r-P2"></site>
    </spatial>
    <spatial name="tib_ant_r_tendon">
      <site site="tib_ant_r-P1"></site>
      <site site="tib_ant_r-P2"></site>
      <site site="tib_ant_r-P3"></site>
    </spatial>
  </tendon>
  <actuator>
    <muscle name="bifemlh_r" tendon="bifemlh_r_tendon" class="muscle" timeconst="    0.01     0.04" force="2594" lengthrange="0.447658 0.575897" ctrllimited="true" ctrlrange="    0.01        1"></muscle>
    <muscle name="bifemsh_r" tendon="bifemsh_r_tendon" class="muscle" timeconst="    0.01     0.04" force="960" lengthrange="0.195757 0.380628" ctrllimited="true" ctrlrange="    0.01        1"></muscle>
    <muscle name="glut_max2_r" tendon="glut_max2_r_tendon" class="muscle" timeconst="    0.01     0.04" force="1944" lengthrange="0.222206  0.38512" ctrllimited="true" ctrlrange="    0.01        1"></muscle>
    <muscle name="psoas_r" tendon="psoas_r_tendon" class="muscle" timeconst="    0.01     0.04" force="2342" lengthrange="0.225076 0.331459" ctrllimited="true" ctrlrange="    0.01        1"></muscle>
    <muscle name="rect_fem_r" tendon="rect_fem_r_tendon" class="muscle" timeconst="    0.01     0.04" force="1169" lengthrange="0.427508 0.559876" ctrllimited="true" ctrlrange="    0.01        1"></muscle>
    <muscle name="vas_int_r" tendon="vas_int_r_tendon" class="muscle" timeconst="    0.01     0.04" force="4530" lengthrange="0.199786 0.325786" ctrllimited="true" ctrlrange="    0.01        1"></muscle>
    <muscle name="med_gas_r" tendon="med_gas_r_tendon" class="muscle" timeconst="    0.01     0.04" force="2241" lengthrange="0.461755 0.560362" ctrllimited="true" ctrlrange="    0.01        1"></muscle>
    <muscle name="soleus_r" tendon="soleus_r_tendon" class="muscle" timeconst="    0.01     0.04" force="5137" lengthrange="0.296763 0.380729" ctrllimited="true" ctrlrange="    0.01        1"></muscle>
    <muscle name="tib_ant_r" tendon="tib_ant_r_tendon" class="muscle" timeconst="    0.01     0.04" force="1759" lengthrange="0.305243 0.414877" ctrllimited="true" ctrlrange="    0.01        1"></muscle>
  </actuator>
  <equality>
    <joint name="knee_angle_r_translation2_constraint" active="true" joint1="knee_angle_r_translation2" joint2="knee_angle_r" polycoef="-0.46448 0.00400632 -0.00655771 0.000786081 0.000666101" solimp="0.9999 0.9999 0.001 0.5 2"></joint>
    <joint name="knee_angle_r_translation1_constraint" active="true" joint1="knee_angle_r_translation1" joint2="knee_angle_r" polycoef="-0.00427167 -0.00735581 0.00329467 0.00157331 -0.000795381" solimp="0.9999 0.9999 0.001 0.5 2"></joint>
    <joint name="knee_angle_pat_r_translation2_constraint" active="true" joint1="knee_angle_pat_r_translation2" joint2="knee_angle_r" polycoef="-0.0254571 -0.00207559 0.00100824 0.000424741 -0.000209386" solimp="0.9999 0.9999 0.001 0.5 2"></joint>
    <joint name="knee_angle_pat_r_translation1_constraint" active="true" joint1="knee_angle_pat_r_translation1" joint2="knee_angle_r" polycoef="0.0556042 0.00674739 -0.00479468 0.000435864 0.000157309" solimp="0.9999 0.9999 0.001 0.5 2"></joint>
    <joint name="knee_angle_pat_r_rotation1_constraint" active="true" joint1="knee_angle_pat_r_rotation1" joint2="knee_angle_r" polycoef="-0.0102787 -1.18764  -1.7036 -1.01704 -0.210418" solimp="0.9999 0.9999 0.001 0.5 2"></joint>
    <weld name="origin_to_worldbody" body1="pelvis" active="false"></weld>
  </equality>
</mujoco>